{
  "version": 8,
  "blockIdVersion": 11,
  "anchorX": 0,
  "anchorY": 0,
  "anchorZ": 0,
  "blocks": [
    {
      "x": -6,
      "y": 0,
      "z": -5,
      "name": "Rock_Stone_Cobble"
    },
    {
      "x": -6,
      "y": 1,
      "z": -5,
      "name": "Mixology_Crate"
    },
    {
      "x": -6,
      "y": 2,
      "z": -5,
      "name": "Mixology_Crate"
    },
    {
      "x": -6,
      "y": 4,
      "z": -5,
      "name": "Wood_Softwood_Roof_Hollow",
      "rotation": 2
    },
    {
      "x": -6,
      "y": 0,
      "z": -4,
      "name": "Rock_Stone_Cobble"
    },
    {
      "x": -6,
      "y": 1,
      "z": -4,
      "name": "Mixology_Crate"
    },
    {
      "x": -6,
      "y": 4,
      "z": -4,
      "name": "Wood_Beech_Trunk",
      "support": 15,
      "rotation": 5
    },
    {
      "x": -6,
      "y": 5,
      "z": -4,
      "name": "Wood_Softwood_Roof",
      "rotation": 2
    },
    {
      "x": -6,
      "y": 0,
      "z": -3,
      "name": "Rock_Stone_Cobble"
    },
    {
      "x": -6,
      "y": 4,
      "z": -3,
      "name": "Plant_Vine_Wall",
      "support": 15,
      "rotation": 3
    },
    {
      "x": -6,
      "y": 5,
      "z": -3,
      "name": "Wood_Softwood_Stairs",
      "rotation": 10
    },
    {
      "x": -6,
      "y": 6,
      "z": -3,
      "name": "Wood_Softwood_Roof",
      "rotation": 2
    },
    {
      "x": -6,
      "y": 0,
      "z": -2,
      "name": "Rock_Stone_Cobble"
    },
    {
      "x": -6,
      "y": 6,
      "z": -2,
      "name": "Wood_Softwood_Stairs",
      "rotation": 10
    },
    {
      "x": -6,
      "y": 7,
      "z": -2,
      "name": "Wood_Softwood_Roof",
      "rotation": 2
    },
    {
      "x": -6,
      "y": 0,
      "z": -1,
      "name": "Rock_Stone_Cobble"
    },
    {
      "x": -6,
      "y": 4,
      "z": -1,
      "name": "Wood_Beech_Trunk_Half",
      "rotation": 7
    },
    {
      "x": -6,
      "y": 7,
      "z": -1,
      "name": "Wood_Softwood_Stairs",
      "rotation": 10
    },
    {
      "x": -6,
      "y": 8,
      "z": -1,
      "name": "Wood_Softwood_Roof_Shallow",
      "rotation": 2
    },
    {
      "x": -6,
      "y": 0,
      "z": 0,
      "name": "Rock_Stone_Cobble_Mossy"
    },
    {
      "x": -6,
      "y": 7,
      "z": 0,
      "name": "Wood_Softwood_Planks_Half",
      "rotation": 8
    },
    {
      "x": -6,
      "y": 8,
      "z": 0,
      "name": "Wood_Softwood_Roof_Shallow",
      "filler": 32,
      "rotation": 2
    },
    {
      "x": -6,
      "y": 0,
      "z": 1,
      "name": "Rock_Stone_Cobble_Mossy"
    },
    {
      "x": -6,
      "y": 7,
      "z": 1,
      "name": "Wood_Softwood_Planks_Half",
      "rotation": 8
    },
    {
      "x": -6,
      "y": 8,
      "z": 1,
      "name": "Wood_Softwood_Roof_Shallow",
      "filler": 992
    },
    {
      "x": -6,
      "y": 0,
      "z": 2,
      "name": "Rock_Stone_Cobble"
    },
    {
      "x": -6,
      "y": 4,
      "z": 2,
      "name": "Wood_Beech_Trunk_Half",
      "rotation": 7
    },
    {
      "x": -6,
      "y": 7,
      "z": 2,
      "name": "Wood_Softwood_Stairs",
      "rotation": 8
    },
    {
      "x": -6,
      "y": 8,
      "z": 2,
      "name": "Wood_Softwood_Roof_Shallow"
    },
    {
      "x": -6,
      "y": 0,
      "z": 3,
      "name": "Rock_Stone_Cobble"
    },
    {
      "x": -6,
      "y": 5,
      "z": 3,
      "name": "Plant_Vine_Wall",
      "support": 15,
      "rotation": 3
    },
    {
      "x": -6,
      "y": 6,
      "z": 3,
      "name": "Wood_Softwood_Stairs",
      "rotation": 8
    },
    {
      "x": -6,
      "y": 7,
      "z": 3,
      "name": "Wood_Softwood_Roof"
    },
    {
      "x": -6,
      "y": 0,
      "z": 4,
      "name": "Rock_Stone_Cobble_Mossy"
    },
    {
      "x": -6,
      "y": 2,
      "z": 4,
      "name": "Plant_Vine_Wall",
      "support": 15,
      "rotation": 3
    },
    {
      "x": -6,
      "y": 5,
      "z": 4,
      "name": "Wood_Softwood_Stairs",
      "rotation": 8
    },
    {
      "x": -6,
      "y": 6,
      "z": 4,
      "name": "Wood_Softwood_Roof"
    },
    {
      "x": -6,
      "y": 0,
      "z": 5,
      "name": "Rock_Stone_Cobble"
    },
    {
      "x": -6,
      "y": 4,
      "z": 5,
      "name": "Wood_Beech_Trunk",
      "support": 15,
      "rotation": 5
    },
    {
      "x": -6,
      "y": 5,
      "z": 5,
      "name": "Wood_Softwood_Roof"
    },
    {
      "x": -6,
      "y": 0,
      "z": 6,
      "name": "Rock_Stone_Cobble"
    },
    {
      "x": -6,
      "y": 4,
      "z": 6,
      "name": "Wood_Softwood_Roof_Hollow"
    },
    {
      "x": -5,
      "y": 0,
      "z": -5,
      "name": "Rock_Stone_Cobble"
    },
    {
      "x": -5,
      "y": 1,
      "z": -5,
      "name": "Rock_Sandstone_Red_Brick_Smooth"
    },
    {
      "x": -5,
      "y": 3,
      "z": -5,
      "name": "Wood_Beech_Trunk_Half",
      "rotation": 6
    },
    {
      "x": -5,
      "y": 4,
      "z": -5,
      "name": "Wood_Softwood_Roof_Hollow",
      "rotation": 2
    },
    {
      "x": -5,
      "y": 0,
      "z": -4,
      "name": "Rock_Stone_Cobble"
    },
    {
      "x": -5,
      "y": 1,
      "z": -4,
      "name": "Wood_Beech_Trunk",
      "support": 15
    },
    {
      "x": -5,
      "y": 2,
      "z": -4,
      "name": "Wood_Beech_Trunk",
      "support": 15
    },
    {
      "x": -5,
      "y": 3,
      "z": -4,
      "name": "Wood_Beech_Trunk",
      "support": 15
    },
    {
      "x": -5,
      "y": 4,
      "z": -4,
      "name": "Wood_Beech_Trunk",
      "support": 15
    },
    {
      "x": -5,
      "y": 5,
      "z": -4,
      "name": "Wood_Softwood_Roof",
      "rotation": 2
    },
    {
      "x": -5,
      "y": 0,
      "z": -3,
      "name": "Rock_Stone_Cobble"
    },
    {
      "x": -5,
      "y": 1,
      "z": -3,
      "name": "Rock_Stone_Brick"
    },
    {
      "x": -5,
      "y": 2,
      "z": -3,
      "name": "Rock_Stone_Brick"
    },
    {
      "x": -5,
      "y": 3,
      "z": -3,
      "name": "Wood_Hardwood_Ornate"
    },
    {
      "x": -5,
      "y": 4,
      "z": -3,
      "name": "Wood_Beech_Trunk",
      "support": 15,
      "rotation": 4
    },
    {
      "x": -5,
      "y": 5,
      "z": -3,
      "name": "Wood_Village_Wall_Full"
    },
    {
      "x": -5,
      "y": 6,
      "z": -3,
      "name": "Wood_Softwood_Roof",
      "rotation": 2
    },
    {
      "x": -5,
      "y": 0,
      "z": -2,
      "name": "Rock_Stone_Cobble"
    },
    {
      "x": -5,
      "y": 1,
      "z": -2,
      "name": "Rock_Stone_Brick"
    },
    {
      "x": -5,
      "y": 2,
      "z": -2,
      "name": "Rock_Stone_Brick"
    },
    {
      "x": -5,
      "y": 3,
      "z": -2,
      "name": "Furniture_Village_Window",
      "rotation": 1
    },
    {
      "x": -5,
      "y": 4,
      "z": -2,
      "name": "Wood_Beech_Trunk",
      "support": 15,
      "rotation": 4
    },
    {
      "x": -5,
      "y": 5,
      "z": -2,
      "name": "*Wood_Village_Wall_Full_State_Definitions_Bottom"
    },
    {
      "x": -5,
      "y": 6,
      "z": -2,
      "name": "*Wood_Village_Wall_Full_State_Definitions_Top"
    },
    {
      "x": -5,
      "y": 7,
      "z": -2,
      "name": "Wood_Softwood_Roof",
      "rotation": 2
    },
    {
      "x": -5,
      "y": 0,
      "z": -1,
      "name": "Rock_Stone_Cobble"
    },
    {
      "x": -5,
      "y": 1,
      "z": -1,
      "name": "Wood_Beech_Trunk",
      "support": 15
    },
    {
      "x": -5,
      "y": 2,
      "z": -1,
      "name": "Wood_Beech_Trunk",
      "support": 15
    },
    {
      "x": -5,
      "y": 3,
      "z": -1,
      "name": "Wood_Beech_Trunk",
      "support": 15
    },
    {
      "x": -5,
      "y": 4,
      "z": -1,
      "name": "Wood_Beech_Trunk",
      "support": 15
    },
    {
      "x": -5,
      "y": 5,
      "z": -1,
      "name": "Wood_Beech_Trunk",
      "support": 15
    },
    {
      "x": -5,
      "y": 6,
      "z": -1,
      "name": "Wood_Beech_Trunk",
      "support": 15
    },
    {
      "x": -5,
      "y": 7,
      "z": -1,
      "name": "Wood_Beech_Trunk",
      "support": 15
    },
    {
      "x": -5,
      "y": 8,
      "z": -1,
      "name": "Wood_Softwood_Roof_Shallow",
      "rotation": 2
    },
    {
      "x": -5,
      "y": 0,
      "z": 0,
      "name": "Rock_Stone_Cobble"
    },
    {
      "x": -5,
      "y": 1,
      "z": 0,
      "name": "Rock_Stone_Brick"
    },
    {
      "x": -5,
      "y": 2,
      "z": 0,
      "name": "Rock_Stone_Brick"
    },
    {
      "x": -5,
      "y": 3,
      "z": 0,
      "name": "Wood_Hardwood_Ornate"
    },
    {
      "x": -5,
      "y": 4,
      "z": 0,
      "name": "Wood_Beech_Trunk",
      "support": 15,
      "rotation": 4
    },
    {
      "x": -5,
      "y": 5,
      "z": 0,
      "name": "Furniture_Village_Window",
      "rotation": 1
    },
    {
      "x": -5,
      "y": 6,
      "z": 0,
      "name": "Furniture_Village_Window",
      "rotation": 1
    },
    {
      "x": -5,
      "y": 7,
      "z": 0,
      "name": "Wood_Village_Wall_Full"
    },
    {
      "x": -5,
      "y": 8,
      "z": 0,
      "name": "Wood_Softwood_Roof_Shallow",
      "filler": 32,
      "rotation": 2
    },
    {
      "x": -5,
      "y": 0,
      "z": 1,
      "name": "Rock_Stone_Cobble"
    },
    {
      "x": -5,
      "y": 1,
      "z": 1,
      "name": "Rock_Stone_Brick"
    },
    {
      "x": -5,
      "y": 2,
      "z": 1,
      "name": "Rock_Stone_Brick"
    },
    {
      "x": -5,
      "y": 3,
      "z": 1,
      "name": "Wood_Hardwood_Ornate"
    },
    {
      "x": -5,
      "y": 4,
      "z": 1,
      "name": "Wood_Beech_Trunk",
      "support": 15,
      "rotation": 4
    },
    {
      "x": -5,
      "y": 5,
      "z": 1,
      "name": "Furniture_Village_Window",
      "rotation": 1
    },
    {
      "x": -5,
      "y": 6,
      "z": 1,
      "name": "Furniture_Village_Window",
      "rotation": 1
    },
    {
      "x": -5,
      "y": 7,
      "z": 1,
      "name": "Wood_Village_Wall_Full"
    },
    {
      "x": -5,
      "y": 8,
      "z": 1,
      "name": "Wood_Softwood_Roof_Shallow",
      "filler": 992
    },
    {
      "x": -5,
      "y": 0,
      "z": 2,
      "name": "Rock_Stone_Cobble"
    },
    {
      "x": -5,
      "y": 1,
      "z": 2,
      "name": "Wood_Beech_Trunk",
      "support": 15
    },
    {
      "x": -5,
      "y": 2,
      "z": 2,
      "name": "Wood_Beech_Trunk",
      "support": 15
    },
    {
      "x": -5,
      "y": 3,
      "z": 2,
      "name": "Wood_Beech_Trunk",
      "support": 15
    },
    {
      "x": -5,
      "y": 4,
      "z": 2,
      "name": "Wood_Beech_Trunk",
      "support": 15
    },
    {
      "x": -5,
      "y": 5,
      "z": 2,
      "name": "Wood_Beech_Trunk",
      "support": 15
    },
    {
      "x": -5,
      "y": 6,
      "z": 2,
      "name": "Wood_Beech_Trunk",
      "support": 15
    },
    {
      "x": -5,
      "y": 7,
      "z": 2,
      "name": "Wood_Beech_Trunk",
      "support": 15
    },
    {
      "x": -5,
      "y": 8,
      "z": 2,
      "name": "Wood_Softwood_Roof_Shallow"
    },
    {
      "x": -5,
      "y": 0,
      "z": 3,
      "name": "Rock_Stone_Cobble"
    },
    {
      "x": -5,
      "y": 1,
      "z": 3,
      "name": "Rock_Stone_Brick"
    },
    {
      "x": -5,
      "y": 2,
      "z": 3,
      "name": "Rock_Stone_Brick"
    },
    {
      "x": -5,
      "y": 3,
      "z": 3,
      "name": "Furniture_Village_Window",
      "rotation": 1
    },
    {
      "x": -5,
      "y": 4,
      "z": 3,
      "name": "Wood_Beech_Trunk",
      "support": 15,
      "rotation": 4
    },
    {
      "x": -5,
      "y": 5,
      "z": 3,
      "name": "*Wood_Village_Wall_Full_State_Definitions_Bottom"
    },
    {
      "x": -5,
      "y": 6,
      "z": 3,
      "name": "*Wood_Village_Wall_Full_State_Definitions_Top"
    },
    {
      "x": -5,
      "y": 7,
      "z": 3,
      "name": "Wood_Softwood_Roof"
    },
    {
      "x": -5,
      "y": 0,
      "z": 4,
      "name": "Rock_Stone_Cobble"
    },
    {
      "x": -5,
      "y": 1,
      "z": 4,
      "name": "Rock_Stone_Brick"
    },
    {
      "x": -5,
      "y": 2,
      "z": 4,
      "name": "Rock_Stone_Brick"
    },
    {
      "x": -5,
      "y": 3,
      "z": 4,
      "name": "Wood_Hardwood_Ornate"
    },
    {
      "x": -5,
      "y": 4,
      "z": 4,
      "name": "Wood_Beech_Trunk",
      "support": 15,
      "rotation": 4
    },
    {
      "x": -5,
      "y": 5,
      "z": 4,
      "name": "Wood_Village_Wall_Full"
    },
    {
      "x": -5,
      "y": 6,
      "z": 4,
      "name": "Wood_Softwood_Roof"
    },
    {
      "x": -5,
      "y": 0,
      "z": 5,
      "name": "Rock_Stone_Cobble"
    },
    {
      "x": -5,
      "y": 1,
      "z": 5,
      "name": "Wood_Beech_Trunk",
      "support": 15
    },
    {
      "x": -5,
      "y": 2,
      "z": 5,
      "name": "Wood_Beech_Trunk",
      "support": 15
    },
    {
      "x": -5,
      "y": 3,
      "z": 5,
      "name": "Wood_Beech_Trunk",
      "support": 15
    },
    {
      "x": -5,
      "y": 4,
      "z": 5,
      "name": "Wood_Beech_Trunk",
      "support": 15
    },
    {
      "x": -5,
      "y": 5,
      "z": 5,
      "name": "Wood_Softwood_Roof"
    },
    {
      "x": -5,
      "y": 0,
      "z": 6,
      "name": "Rock_Stone_Cobble"
    },
    {
      "x": -5,
      "y": 4,
      "z": 6,
      "name": "Wood_Softwood_Roof_Hollow"
    },
    {
      "x": -5,
      "y": 10,
      "z": 6,
      "name": "Plant_Leaves_Ash",
      "support": 1,
      "rotation": 1
    },
    {
      "x": -4,
      "y": 0,
      "z": -5,
      "name": "Rock_Stone_Cobble"
    },
    {
      "x": -4,
      "y": 4,
      "z": -5,
      "name": "Wood_Softwood_Roof_Hollow",
      "rotation": 2
    },
    {
      "x": -4,
      "y": 0,
      "z": -4,
      "name": "Rock_Stone_Cobble"
    },
    {
      "x": -4,
      "y": 1,
      "z": -4,
      "name": "Rock_Stone_Brick"
    },
    {
      "x": -4,
      "y": 2,
      "z": -4,
      "name": "*Wood_Village_Wall_Full_State_Definitions_Bottom"
    },
    {
      "x": -4,
      "y": 3,
      "z": -4,
      "name": "*Wood_Village_Wall_Full_State_Definitions_Top"
    },
    {
      "x": -4,
      "y": 4,
      "z": -4,
      "name": "Wood_Beech_Trunk",
      "support": 15,
      "rotation": 5
    },
    {
      "x": -4,
      "y": 5,
      "z": -4,
      "name": "Wood_Softwood_Roof",
      "rotation": 2
    },
    {
      "x": -4,
      "y": 0,
      "z": -3,
      "name": "Wood_Hardwood_Planks"
    },
    {
      "x": -4,
      "y": 1,
      "z": -3,
      "name": "Furniture_Tavern_Wardrobe",
      "rotation": 1
    },
    {
      "x": -4,
      "y": 2,
      "z": -3,
      "name": "Furniture_Tavern_Wardrobe",
      "filler": 1024,
      "rotation": 1
    },
    {
      "x": -4,
      "y": 5,
      "z": -3,
      "name": "Wood_Softwood_Stairs",
      "rotation": 10
    },
    {
      "x": -4,
      "y": 6,
      "z": -3,
      "name": "Wood_Softwood_Roof",
      "rotation": 2
    },
    {
      "x": -4,
      "y": 0,
      "z": -2,
      "name": "Wood_Hardwood_Planks"
    },
    {
      "x": -4,
      "y": 1,
      "z": -2,
      "name": "Furniture_Tavern_Wardrobe",
      "filler": 32,
      "rotation": 1
    },
    {
      "x": -4,
      "y": 2,
      "z": -2,
      "name": "Furniture_Tavern_Wardrobe",
      "filler": 1056,
      "rotation": 1
    },
    {
      "x": -4,
      "y": 6,
      "z": -2,
      "name": "Wood_Hardwood_Stairs",
      "rotation": 10
    },
    {
      "x": -4,
      "y": 7,
      "z": -2,
      "name": "Wood_Softwood_Roof",
      "rotation": 2
    },
    {
      "x": -4,
      "y": 0,
      "z": -1,
      "name": "Wood_Hardwood_Planks"
    },
    {
      "x": -4,
      "y": 1,
      "z": -1,
      "name": "Wood_Hardwood_Planks"
    },
    {
      "x": -4,
      "y": 2,
      "z": -1,
      "name": "Apple_Martini"
    },
    {
      "x": -4,
      "y": 7,
      "z": -1,
      "name": "Wood_Hardwood_Stairs",
      "rotation": 10
    },
    {
      "x": -4,
      "y": 8,
      "z": -1,
      "name": "Wood_Softwood_Roof_Shallow",
      "rotation": 2
    },
    {
      "x": -4,
      "y": 0,
      "z": 0,
      "name": "Wood_Hardwood_Planks"
    },
    {
      "x": -4,
      "y": 1,
      "z": 0,
      "name": "Furniture_Village_Shelf_Full",
      "rotation": 1
    },
    {
      "x": -4,
      "y": 2,
      "z": 0,
      "name": "Furniture_Lumberjack_Shelf",
      "rotation": 1
    },
    {
      "x": -4,
      "y": 3,
      "z": 0,
      "name": "Berry_Punch"
    },
    {
      "x": -4,
      "y": 8,
      "z": 0,
      "name": "Wood_Softwood_Roof_Shallow",
      "filler": 32,
      "rotation": 2
    },
    {
      "x": -4,
      "y": 0,
      "z": 1,
      "name": "Wood_Hardwood_Planks"
    },
    {
      "x": -4,
      "y": 2,
      "z": 1,
      "name": "Furniture_Lumberjack_Shelf",
      "rotation": 1
    },
    {
      "x": -4,
      "y": 3,
      "z": 1,
      "name": "Corn_Cooler"
    },
    {
      "x": -4,
      "y": 8,
      "z": 1,
      "name": "Wood_Softwood_Roof_Shallow",
      "filler": 992
    },
    {
      "x": -4,
      "y": 0,
      "z": 2,
      "name": "Wood_Hardwood_Planks"
    },
    {
      "x": -4,
      "y": 7,
      "z": 2,
      "name": "Wood_Softwood_Stairs",
      "rotation": 8
    },
    {
      "x": -4,
      "y": 8,
      "z": 2,
      "name": "Wood_Softwood_Roof_Shallow"
    },
    {
      "x": -4,
      "y": 0,
      "z": 3,
      "name": "Wood_Hardwood_Planks"
    },
    {
      "x": -4,
      "y": 1,
      "z": 3,
      "name": "Aetherhaven_Management_Block",
      "components": {
        "Components": {
          "AetherhavenManagementBlock": {
            "PlotId": "",
            "TownId": ""
          },
          "PlacedByInteraction": {
            "WhoPlacedUuid": {
              "$binary": "7RgS5j+2Q7iGDrSXx3YJoA==",
              "$type": "04"
            }
          }
        }
      },
      "rotation": 1
    },
    {
      "x": -4,
      "y": 2,
      "z": 3,
      "name": "Furniture_Lumberjack_Shelf",
      "rotation": 1
    },
    {
      "x": -4,
      "y": 3,
      "z": 3,
      "name": "Autumn_Sip"
    },
    {
      "x": -4,
      "y": 6,
      "z": 3,
      "name": "Wood_Softwood_Stairs",
      "rotation": 8
    },
    {
      "x": -4,
      "y": 7,
      "z": 3,
      "name": "Wood_Softwood_Roof"
    },
    {
      "x": -4,
      "y": 0,
      "z": 4,
      "name": "Wood_Hardwood_Planks"
    },
    {
      "x": -4,
      "y": 1,
      "z": 4,
      "name": "Furniture_Village_Shelf_Full",
      "rotation": 1
    },
    {
      "x": -4,
      "y": 2,
      "z": 4,
      "name": "Furniture_Lumberjack_Shelf",
      "rotation": 1
    },
    {
      "x": -4,
      "y": 5,
      "z": 4,
      "name": "Wood_Softwood_Stairs",
      "rotation": 8
    },
    {
      "x": -4,
      "y": 6,
      "z": 4,
      "name": "Wood_Softwood_Roof"
    },
    {
      "x": -4,
      "y": 0,
      "z": 5,
      "name": "Rock_Stone_Cobble"
    },
    {
      "x": -4,
      "y": 1,
      "z": 5,
      "name": "Rock_Stone_Brick"
    },
    {
      "x": -4,
      "y": 2,
      "z": 5,
      "name": "*Wood_Village_Wall_Full_State_Definitions_Bottom"
    },
    {
      "x": -4,
      "y": 3,
      "z": 5,
      "name": "*Wood_Village_Wall_Full_State_Definitions_Top"
    },
    {
      "x": -4,
      "y": 4,
      "z": 5,
      "name": "Wood_Beech_Trunk",
      "support": 15,
      "rotation": 5
    },
    {
      "x": -4,
      "y": 5,
      "z": 5,
      "name": "Wood_Softwood_Roof"
    },
    {
      "x": -4,
      "y": 0,
      "z": 6,
      "name": "Rock_Stone_Cobble"
    },
    {
      "x": -4,
      "y": 4,
      "z": 6,
      "name": "Wood_Softwood_Roof_Hollow"
    },
    {
      "x": -3,
      "y": 0,
      "z": -5,
      "name": "Rock_Stone_Cobble"
    },
    {
      "x": -3,
      "y": 4,
      "z": -5,
      "name": "Wood_Softwood_Roof_Hollow",
      "rotation": 2
    },
    {
      "x": -3,
      "y": 0,
      "z": -4,
      "name": "Rock_Stone_Cobble"
    },
    {
      "x": -3,
      "y": 1,
      "z": -4,
      "name": "Rock_Stone_Brick"
    },
    {
      "x": -3,
      "y": 2,
      "z": -4,
      "name": "Furniture_Village_Window"
    },
    {
      "x": -3,
      "y": 3,
      "z": -4,
      "name": "Furniture_Village_Window"
    },
    {
      "x": -3,
      "y": 4,
      "z": -4,
      "name": "Wood_Beech_Trunk",
      "support": 15,
      "rotation": 5
    },
    {
      "x": -3,
      "y": 5,
      "z": -4,
      "name": "Wood_Softwood_Roof",
      "rotation": 2
    },
    {
      "x": -3,
      "y": 0,
      "z": -3,
      "name": "Wood_Hardwood_Decorative"
    },
    {
      "x": -3,
      "y": 5,
      "z": -3,
      "name": "Wood_Softwood_Stairs",
      "rotation": 10
    },
    {
      "x": -3,
      "y": 6,
      "z": -3,
      "name": "Wood_Softwood_Roof",
      "rotation": 2
    },
    {
      "x": -3,
      "y": 0,
      "z": -2,
      "name": "Wood_Hardwood_Decorative"
    },
    {
      "x": -3,
      "y": 1,
      "z": -2,
      "name": "*Wood_Hardwood_Fence_Gate_State_Definitions_OpenDoorIn",
      "filler": 992,
      "rotation": 2
    },
    {
      "x": -3,
      "y": 6,
      "z": -2,
      "name": "Wood_Hardwood_Stairs",
      "rotation": 10
    },
    {
      "x": -3,
      "y": 7,
      "z": -2,
      "name": "Wood_Softwood_Roof",
      "rotation": 2
    },
    {
      "x": -3,
      "y": 0,
      "z": -1,
      "name": "Wood_Hardwood_Decorative"
    },
    {
      "x": -3,
      "y": 1,
      "z": -1,
      "name": "*Wood_Hardwood_Fence_Gate_State_Definitions_OpenDoorIn",
      "rotation": 2
    },
    {
      "x": -3,
      "y": 7,
      "z": -1,
      "name": "Wood_Hardwood_Stairs",
      "rotation": 10
    },
    {
      "x": -3,
      "y": 8,
      "z": -1,
      "name": "Wood_Softwood_Roof_Shallow",
      "rotation": 2
    },
    {
      "x": -3,
      "y": 0,
      "z": 0,
      "name": "Wood_Hardwood_Decorative"
    },
    {
      "x": -3,
      "y": 8,
      "z": 0,
      "name": "Wood_Softwood_Roof_Shallow",
      "filler": 32,
      "rotation": 2
    },
    {
      "x": -3,
      "y": 0,
      "z": 1,
      "name": "Wood_Hardwood_Decorative"
    },
    {
      "x": -3,
      "y": 8,
      "z": 1,
      "name": "Wood_Softwood_Roof_Shallow",
      "filler": 992
    },
    {
      "x": -3,
      "y": 0,
      "z": 2,
      "name": "Wood_Hardwood_Decorative"
    },
    {
      "x": -3,
      "y": 7,
      "z": 2,
      "name": "Wood_Softwood_Stairs",
      "rotation": 8
    },
    {
      "x": -3,
      "y": 8,
      "z": 2,
      "name": "Wood_Softwood_Roof_Shallow"
    },
    {
      "x": -3,
      "y": 0,
      "z": 3,
      "name": "Wood_Hardwood_Decorative"
    },
    {
      "x": -3,
      "y": 6,
      "z": 3,
      "name": "Wood_Softwood_Stairs",
      "rotation": 8
    },
    {
      "x": -3,
      "y": 7,
      "z": 3,
      "name": "Wood_Softwood_Roof"
    },
    {
      "x": -3,
      "y": 0,
      "z": 4,
      "name": "Wood_Hardwood_Decorative"
    },
    {
      "x": -3,
      "y": 5,
      "z": 4,
      "name": "Wood_Softwood_Stairs",
      "rotation": 8
    },
    {
      "x": -3,
      "y": 6,
      "z": 4,
      "name": "Wood_Softwood_Roof"
    },
    {
      "x": -3,
      "y": 0,
      "z": 5,
      "name": "Rock_Stone_Cobble"
    },
    {
      "x": -3,
      "y": 1,
      "z": 5,
      "name": "Rock_Stone_Brick"
    },
    {
      "x": -3,
      "y": 2,
      "z": 5,
      "name": "Furniture_Village_Window"
    },
    {
      "x": -3,
      "y": 3,
      "z": 5,
      "name": "Furniture_Village_Window"
    },
    {
      "x": -3,
      "y": 4,
      "z": 5,
      "name": "Wood_Beech_Trunk",
      "support": 15,
      "rotation": 5
    },
    {
      "x": -3,
      "y": 5,
      "z": 5,
      "name": "Wood_Softwood_Roof"
    },
    {
      "x": -3,
      "y": 0,
      "z": 6,
      "name": "Rock_Stone_Cobble"
    },
    {
      "x": -3,
      "y": 4,
      "z": 6,
      "name": "Wood_Softwood_Roof_Hollow"
    },
    {
      "x": -2,
      "y": 0,
      "z": -5,
      "name": "Rock_Stone_Cobble"
    },
    {
      "x": -2,
      "y": 4,
      "z": -5,
      "name": "Wood_Softwood_Roof_Hollow",
      "rotation": 2
    },
    {
      "x": -2,
      "y": 0,
      "z": -4,
      "name": "Rock_Stone_Cobble"
    },
    {
      "x": -2,
      "y": 1,
      "z": -4,
      "name": "Rock_Stone_Brick"
    },
    {
      "x": -2,
      "y": 2,
      "z": -4,
      "name": "Furniture_Village_Window"
    },
    {
      "x": -2,
      "y": 3,
      "z": -4,
      "name": "Furniture_Village_Window"
    },
    {
      "x": -2,
      "y": 4,
      "z": -4,
      "name": "Wood_Beech_Trunk",
      "support": 15,
      "rotation": 5
    },
    {
      "x": -2,
      "y": 5,
      "z": -4,
      "name": "Wood_Softwood_Roof",
      "rotation": 2
    },
    {
      "x": -2,
      "y": 0,
      "z": -3,
      "name": "Wood_Hardwood_Decorative"
    },
    {
      "x": -2,
      "y": 5,
      "z": -3,
      "name": "Wood_Softwood_Stairs",
      "rotation": 10
    },
    {
      "x": -2,
      "y": 6,
      "z": -3,
      "name": "Wood_Softwood_Roof",
      "rotation": 2
    },
    {
      "x": -2,
      "y": 0,
      "z": -2,
      "name": "Wood_Hardwood_Decorative"
    },
    {
      "x": -2,
      "y": 6,
      "z": -2,
      "name": "Wood_Hardwood_Stairs",
      "rotation": 10
    },
    {
      "x": -2,
      "y": 7,
      "z": -2,
      "name": "Wood_Softwood_Roof",
      "rotation": 2
    },
    {
      "x": -2,
      "y": 0,
      "z": -1,
      "name": "Wood_Hardwood_Decorative"
    },
    {
      "x": -2,
      "y": 1,
      "z": -1,
      "name": "Wood_Hardwood_Ornate"
    },
    {
      "x": -2,
      "y": 7,
      "z": -1,
      "name": "Wood_Hardwood_Stairs",
      "rotation": 10
    },
    {
      "x": -2,
      "y": 8,
      "z": -1,
      "name": "Wood_Softwood_Roof_Shallow",
      "rotation": 2
    },
    {
      "x": -2,
      "y": 0,
      "z": 0,
      "name": "Wood_Hardwood_Decorative"
    },
    {
      "x": -2,
      "y": 1,
      "z": 0,
      "name": "Bench_Mixology_Bar",
      "filler": 992,
      "rotation": 3
    },
    {
      "x": -2,
      "y": 2,
      "z": 0,
      "name": "Bench_Mixology_Bar",
      "filler": 2016,
      "rotation": 3
    },
    {
      "x": -2,
      "y": 5,
      "z": 0,
      "name": "Deco_Lantern_Ceiling"
    },
    {
      "x": -2,
      "y": 6,
      "z": 0,
      "name": "Deco_Rope"
    },
    {
      "x": -2,
      "y": 7,
      "z": 0,
      "name": "Deco_Rope"
    },
    {
      "x": -2,
      "y": 8,
      "z": 0,
      "name": "Wood_Softwood_Roof_Shallow",
      "filler": 32,
      "rotation": 2
    },
    {
      "x": -2,
      "y": 0,
      "z": 1,
      "name": "Wood_Hardwood_Decorative"
    },
    {
      "x": -2,
      "y": 1,
      "z": 1,
      "name": "Bench_Mixology_Bar",
      "rotation": 3
    },
    {
      "x": -2,
      "y": 2,
      "z": 1,
      "name": "Bench_Mixology_Bar",
      "filler": 1024,
      "rotation": 3
    },
    {
      "x": -2,
      "y": 8,
      "z": 1,
      "name": "Wood_Softwood_Roof_Shallow",
      "filler": 992
    },
    {
      "x": -2,
      "y": 0,
      "z": 2,
      "name": "Wood_Hardwood_Decorative"
    },
    {
      "x": -2,
      "y": 1,
      "z": 2,
      "name": "Wood_Hardwood_Ornate"
    },
    {
      "x": -2,
      "y": 2,
      "z": 2,
      "name": "Aetherhaven_Shop_Spot",
      "components": {
        "Components": {
          "AetherhavenShopSpotBlock": {
            "SpotId": "c58bf11d-54f2-4f28-bab0-e771288b77c6",
            "TownId": "e335ef40-1a18-428e-ba5c-e599439c494e",
            "PlotId": "00000000-0000-0000-0000-000000000000",
            "PlayerControlled": false,
            "LootTableId": "mixologist_drinks",
            "Configured": true
          },
          "PlacedByInteraction": {
            "WhoPlacedUuid": {
              "$binary": "7RgS5j+2Q7iGDrSXx3YJoA==",
              "$type": "04"
            }
          }
        }
      },
      "rotation": 1
    },
    {
      "x": -2,
      "y": 7,
      "z": 2,
      "name": "Wood_Softwood_Stairs",
      "rotation": 8
    },
    {
      "x": -2,
      "y": 8,
      "z": 2,
      "name": "Wood_Softwood_Roof_Shallow"
    },
    {
      "x": -2,
      "y": 0,
      "z": 3,
      "name": "Wood_Hardwood_Decorative"
    },
    {
      "x": -2,
      "y": 1,
      "z": 3,
      "name": "Wood_Hardwood_Ornate"
    },
    {
      "x": -2,
      "y": 2,
      "z": 3,
      "name": "Aetherhaven_Shop_Spot",
      "components": {
        "Components": {
          "AetherhavenShopSpotBlock": {
            "SpotId": "32c6ab65-ba0a-48e4-872d-8824510f50ac",
            "TownId": "e335ef40-1a18-428e-ba5c-e599439c494e",
            "PlotId": "00000000-0000-0000-0000-000000000000",
            "PlayerControlled": false,
            "LootTableId": "mixologist_drinks",
            "Configured": true
          },
          "PlacedByInteraction": {
            "WhoPlacedUuid": {
              "$binary": "7RgS5j+2Q7iGDrSXx3YJoA==",
              "$type": "04"
            }
          }
        }
      },
      "rotation": 1
    },
    {
      "x": -2,
      "y": 6,
      "z": 3,
      "name": "Wood_Softwood_Stairs",
      "rotation": 8
    },
    {
      "x": -2,
      "y": 7,
      "z": 3,
      "name": "Wood_Softwood_Roof"
    },
    {
      "x": -2,
      "y": 0,
      "z": 4,
      "name": "Wood_Hardwood_Decorative"
    },
    {
      "x": -2,
      "y": 1,
      "z": 4,
      "name": "Wood_Hardwood_Ornate"
    },
    {
      "x": -2,
      "y": 2,
      "z": 4,
      "name": "Aetherhaven_Shop_Spot",
      "components": {
        "Components": {
          "AetherhavenShopSpotBlock": {
            "SpotId": "1a76c940-d398-4bee-9b24-5378dc7a0605",
            "TownId": "e335ef40-1a18-428e-ba5c-e599439c494e",
            "PlotId": "00000000-0000-0000-0000-000000000000",
            "PlayerControlled": false,
            "LootTableId": "mixologist_drinks",
            "Configured": true
          },
          "PlacedByInteraction": {
            "WhoPlacedUuid": {
              "$binary": "7RgS5j+2Q7iGDrSXx3YJoA==",
              "$type": "04"
            }
          }
        }
      },
      "rotation": 1
    },
    {
      "x": -2,
      "y": 5,
      "z": 4,
      "name": "Wood_Softwood_Stairs",
      "rotation": 8
    },
    {
      "x": -2,
      "y": 6,
      "z": 4,
      "name": "Wood_Softwood_Roof"
    },
    {
      "x": -2,
      "y": 0,
      "z": 5,
      "name": "Rock_Stone_Cobble"
    },
    {
      "x": -2,
      "y": 1,
      "z": 5,
      "name": "Rock_Stone_Brick"
    },
    {
      "x": -2,
      "y": 2,
      "z": 5,
      "name": "Furniture_Village_Window"
    },
    {
      "x": -2,
      "y": 3,
      "z": 5,
      "name": "Furniture_Village_Window"
    },
    {
      "x": -2,
      "y": 4,
      "z": 5,
      "name": "Wood_Beech_Trunk",
      "support": 15,
      "rotation": 5
    },
    {
      "x": -2,
      "y": 5,
      "z": 5,
      "name": "Wood_Softwood_Roof"
    },
    {
      "x": -2,
      "y": 0,
      "z": 6,
      "name": "Rock_Stone_Cobble"
    },
    {
      "x": -2,
      "y": 4,
      "z": 6,
      "name": "Wood_Softwood_Roof_Hollow"
    },
    {
      "x": -1,
      "y": 0,
      "z": -5,
      "name": "Rock_Stone_Cobble_Mossy"
    },
    {
      "x": -1,
      "y": 3,
      "z": -5,
      "name": "Plant_Vine_Wall",
      "support": 15,
      "rotation": 2
    },
    {
      "x": -1,
      "y": 4,
      "z": -5,
      "name": "Wood_Softwood_Roof_Hollow",
      "rotation": 2
    },
    {
      "x": -1,
      "y": 0,
      "z": -4,
      "name": "Rock_Stone_Cobble"
    },
    {
      "x": -1,
      "y": 1,
      "z": -4,
      "name": "Rock_Stone_Brick"
    },
    {
      "x": -1,
      "y": 2,
      "z": -4,
      "name": "*Wood_Village_Wall_Full_State_Definitions_Bottom"
    },
    {
      "x": -1,
      "y": 3,
      "z": -4,
      "name": "*Wood_Village_Wall_Full_State_Definitions_Top"
    },
    {
      "x": -1,
      "y": 4,
      "z": -4,
      "name": "Wood_Beech_Trunk",
      "support": 15,
      "rotation": 5
    },
    {
      "x": -1,
      "y": 5,
      "z": -4,
      "name": "Wood_Softwood_Roof",
      "rotation": 2
    },
    {
      "x": -1,
      "y": 0,
      "z": -3,
      "name": "Wood_Hardwood_Decorative"
    },
    {
      "x": -1,
      "y": 5,
      "z": -3,
      "name": "Wood_Softwood_Stairs",
      "rotation": 10
    },
    {
      "x": -1,
      "y": 6,
      "z": -3,
      "name": "Wood_Softwood_Roof",
      "rotation": 2
    },
    {
      "x": -1,
      "y": 0,
      "z": -2,
      "name": "Wood_Hardwood_Decorative"
    },
    {
      "x": -1,
      "y": 6,
      "z": -2,
      "name": "Wood_Hardwood_Stairs",
      "rotation": 10
    },
    {
      "x": -1,
      "y": 7,
      "z": -2,
      "name": "Wood_Softwood_Roof",
      "rotation": 2
    },
    {
      "x": -1,
      "y": 0,
      "z": -1,
      "name": "Wood_Hardwood_Decorative"
    },
    {
      "x": -1,
      "y": 7,
      "z": -1,
      "name": "Wood_Hardwood_Stairs",
      "rotation": 10
    },
    {
      "x": -1,
      "y": 8,
      "z": -1,
      "name": "Wood_Softwood_Roof_Shallow",
      "rotation": 2
    },
    {
      "x": -1,
      "y": 0,
      "z": 0,
      "name": "Wood_Hardwood_Decorative"
    },
    {
      "x": -1,
      "y": 8,
      "z": 0,
      "name": "Wood_Softwood_Roof_Shallow",
      "filler": 32,
      "rotation": 2
    },
    {
      "x": -1,
      "y": 0,
      "z": 1,
      "name": "Wood_Hardwood_Decorative"
    },
    {
      "x": -1,
      "y": 8,
      "z": 1,
      "name": "Wood_Softwood_Roof_Shallow",
      "filler": 992
    },
    {
      "x": -1,
      "y": 0,
      "z": 2,
      "name": "Wood_Hardwood_Decorative"
    },
    {
      "x": -1,
      "y": 7,
      "z": 2,
      "name": "Wood_Softwood_Stairs",
      "rotation": 8
    },
    {
      "x": -1,
      "y": 8,
      "z": 2,
      "name": "Wood_Softwood_Roof_Shallow"
    },
    {
      "x": -1,
      "y": 0,
      "z": 3,
      "name": "Wood_Hardwood_Decorative"
    },
    {
      "x": -1,
      "y": 6,
      "z": 3,
      "name": "Wood_Softwood_Stairs",
      "rotation": 8
    },
    {
      "x": -1,
      "y": 7,
      "z": 3,
      "name": "Wood_Softwood_Roof"
    },
    {
      "x": -1,
      "y": 0,
      "z": 4,
      "name": "Wood_Hardwood_Decorative"
    },
    {
      "x": -1,
      "y": 5,
      "z": 4,
      "name": "Wood_Softwood_Stairs",
      "rotation": 8
    },
    {
      "x": -1,
      "y": 6,
      "z": 4,
      "name": "Wood_Softwood_Roof"
    },
    {
      "x": -1,
      "y": 0,
      "z": 5,
      "name": "Rock_Stone_Cobble"
    },
    {
      "x": -1,
      "y": 1,
      "z": 5,
      "name": "Rock_Stone_Brick"
    },
    {
      "x": -1,
      "y": 2,
      "z": 5,
      "name": "*Wood_Village_Wall_Full_State_Definitions_Bottom"
    },
    {
      "x": -1,
      "y": 3,
      "z": 5,
      "name": "*Wood_Village_Wall_Full_State_Definitions_Top"
    },
    {
      "x": -1,
      "y": 4,
      "z": 5,
      "name": "Wood_Beech_Trunk",
      "support": 15,
      "rotation": 5
    },
    {
      "x": -1,
      "y": 5,
      "z": 5,
      "name": "Wood_Softwood_Roof"
    },
    {
      "x": -1,
      "y": 0,
      "z": 6,
      "name": "Rock_Stone_Cobble_Mossy"
    },
    {
      "x": -1,
      "y": 4,
      "z": 6,
      "name": "Wood_Softwood_Roof_Hollow"
    },
    {
      "x": 0,
      "y": 0,
      "z": -5,
      "name": "Rock_Stone_Cobble_Mossy"
    },
    {
      "x": 0,
      "y": 4,
      "z": -5,
      "name": "Wood_Softwood_Roof_Hollow",
      "rotation": 2
    },
    {
      "x": 0,
      "y": 0,
      "z": -4,
      "name": "Rock_Stone_Cobble"
    },
    {
      "x": 0,
      "y": 1,
      "z": -4,
      "name": "Wood_Beech_Trunk",
      "support": 15
    },
    {
      "x": 0,
      "y": 2,
      "z": -4,
      "name": "Wood_Beech_Trunk",
      "support": 15
    },
    {
      "x": 0,
      "y": 3,
      "z": -4,
      "name": "Wood_Beech_Trunk",
      "support": 15
    },
    {
      "x": 0,
      "y": 4,
      "z": -4,
      "name": "Wood_Beech_Trunk",
      "support": 15
    },
    {
      "x": 0,
      "y": 5,
      "z": -4,
      "name": "Wood_Softwood_Roof",
      "rotation": 2
    },
    {
      "x": 0,
      "y": 0,
      "z": -3,
      "name": "Wood_Hardwood_Decorative"
    },
    {
      "x": 0,
      "y": 1,
      "z": -3,
      "name": "Furniture_Village_Stool"
    },
    {
      "x": 0,
      "y": 5,
      "z": -3,
      "name": "Wood_Softwood_Stairs",
      "rotation": 10
    },
    {
      "x": 0,
      "y": 6,
      "z": -3,
      "name": "Wood_Softwood_Roof",
      "rotation": 2
    },
    {
      "x": 0,
      "y": 0,
      "z": -2,
      "name": "Wood_Hardwood_Decorative"
    },
    {
      "x": 0,
      "y": 1,
      "z": -2,
      "name": "Furniture_Village_Stool"
    },
    {
      "x": 0,
      "y": 6,
      "z": -2,
      "name": "Wood_Hardwood_Stairs",
      "rotation": 10
    },
    {
      "x": 0,
      "y": 7,
      "z": -2,
      "name": "Wood_Softwood_Roof",
      "rotation": 2
    },
    {
      "x": 0,
      "y": 0,
      "z": -1,
      "name": "Wood_Hardwood_Decorative"
    },
    {
      "x": 0,
      "y": 7,
      "z": -1,
      "name": "Wood_Hardwood_Stairs",
      "rotation": 10
    },
    {
      "x": 0,
      "y": 8,
      "z": -1,
      "name": "Wood_Softwood_Roof_Shallow",
      "rotation": 2
    },
    {
      "x": 0,
      "y": 0,
      "z": 0,
      "name": "Wood_Hardwood_Decorative"
    },
    {
      "x": 0,
      "y": 8,
      "z": 0,
      "name": "Wood_Softwood_Roof_Shallow",
      "filler": 32,
      "rotation": 2
    },
    {
      "x": 0,
      "y": 0,
      "z": 1,
      "name": "Wood_Hardwood_Decorative"
    },
    {
      "x": 0,
      "y": 5,
      "z": 1,
      "name": "Deco_Lantern_Ceiling"
    },
    {
      "x": 0,
      "y": 6,
      "z": 1,
      "name": "Deco_Rope"
    },
    {
      "x": 0,
      "y": 7,
      "z": 1,
      "name": "Deco_Rope"
    },
    {
      "x": 0,
      "y": 8,
      "z": 1,
      "name": "Wood_Softwood_Roof_Shallow",
      "filler": 992
    },
    {
      "x": 0,
      "y": 0,
      "z": 2,
      "name": "Wood_Hardwood_Decorative"
    },
    {
      "x": 0,
      "y": 7,
      "z": 2,
      "name": "Wood_Softwood_Stairs",
      "rotation": 8
    },
    {
      "x": 0,
      "y": 8,
      "z": 2,
      "name": "Wood_Softwood_Roof_Shallow"
    },
    {
      "x": 0,
      "y": 0,
      "z": 3,
      "name": "Wood_Hardwood_Decorative"
    },
    {
      "x": 0,
      "y": 6,
      "z": 3,
      "name": "Wood_Softwood_Stairs",
      "rotation": 8
    },
    {
      "x": 0,
      "y": 7,
      "z": 3,
      "name": "Wood_Softwood_Roof"
    },
    {
      "x": 0,
      "y": 0,
      "z": 4,
      "name": "Wood_Hardwood_Decorative"
    },
    {
      "x": 0,
      "y": 5,
      "z": 4,
      "name": "Wood_Softwood_Stairs",
      "rotation": 8
    },
    {
      "x": 0,
      "y": 6,
      "z": 4,
      "name": "Wood_Softwood_Roof"
    },
    {
      "x": 0,
      "y": 0,
      "z": 5,
      "name": "Rock_Stone_Cobble"
    },
    {
      "x": 0,
      "y": 1,
      "z": 5,
      "name": "Wood_Beech_Trunk",
      "support": 15
    },
    {
      "x": 0,
      "y": 2,
      "z": 5,
      "name": "Wood_Beech_Trunk",
      "support": 15
    },
    {
      "x": 0,
      "y": 3,
      "z": 5,
      "name": "Wood_Beech_Trunk",
      "support": 15
    },
    {
      "x": 0,
      "y": 4,
      "z": 5,
      "name": "Wood_Beech_Trunk",
      "support": 15
    },
    {
      "x": 0,
      "y": 5,
      "z": 5,
      "name": "Wood_Softwood_Roof"
    },
    {
      "x": 0,
      "y": 0,
      "z": 6,
      "name": "Rock_Stone_Cobble"
    },
    {
      "x": 0,
      "y": 4,
      "z": 6,
      "name": "Wood_Softwood_Roof_Hollow"
    },
    {
      "x": 1,
      "y": 0,
      "z": -5,
      "name": "Rock_Stone_Cobble"
    },
    {
      "x": 1,
      "y": 4,
      "z": -5,
      "name": "Wood_Softwood_Roof_Hollow",
      "rotation": 2
    },
    {
      "x": 1,
      "y": 0,
      "z": -4,
      "name": "Rock_Stone_Cobble"
    },
    {
      "x": 1,
      "y": 1,
      "z": -4,
      "name": "Rock_Stone_Brick"
    },
    {
      "x": 1,
      "y": 2,
      "z": -4,
      "name": "*Wood_Village_Wall_Full_State_Definitions_Bottom"
    },
    {
      "x": 1,
      "y": 3,
      "z": -4,
      "name": "*Wood_Village_Wall_Full_State_Definitions_Top"
    },
    {
      "x": 1,
      "y": 4,
      "z": -4,
      "name": "Wood_Beech_Trunk",
      "support": 15,
      "rotation": 5
    },
    {
      "x": 1,
      "y": 5,
      "z": -4,
      "name": "Wood_Softwood_Roof",
      "rotation": 2
    },
    {
      "x": 1,
      "y": 0,
      "z": -3,
      "name": "Wood_Hardwood_Decorative"
    },
    {
      "x": 1,
      "y": 1,
      "z": -3,
      "name": "Furniture_Village_Table"
    },
    {
      "x": 1,
      "y": 2,
      "z": -3,
      "name": "Apple_Martini"
    },
    {
      "x": 1,
      "y": 5,
      "z": -3,
      "name": "Wood_Softwood_Stairs",
      "rotation": 10
    },
    {
      "x": 1,
      "y": 6,
      "z": -3,
      "name": "Wood_Softwood_Roof",
      "rotation": 2
    },
    {
      "x": 1,
      "y": 0,
      "z": -2,
      "name": "Wood_Hardwood_Decorative"
    },
    {
      "x": 1,
      "y": 1,
      "z": -2,
      "name": "Furniture_Village_Table",
      "filler": 32
    },
    {
      "x": 1,
      "y": 6,
      "z": -2,
      "name": "Wood_Hardwood_Stairs",
      "rotation": 10
    },
    {
      "x": 1,
      "y": 7,
      "z": -2,
      "name": "Wood_Softwood_Roof",
      "rotation": 2
    },
    {
      "x": 1,
      "y": 0,
      "z": -1,
      "name": "Wood_Hardwood_Decorative"
    },
    {
      "x": 1,
      "y": 7,
      "z": -1,
      "name": "Wood_Softwood_Stairs",
      "rotation": 10
    },
    {
      "x": 1,
      "y": 8,
      "z": -1,
      "name": "Wood_Softwood_Roof_Shallow",
      "rotation": 2
    },
    {
      "x": 1,
      "y": 0,
      "z": 0,
      "name": "Wood_Hardwood_Decorative"
    },
    {
      "x": 1,
      "y": 8,
      "z": 0,
      "name": "Wood_Softwood_Roof_Shallow",
      "filler": 32,
      "rotation": 2
    },
    {
      "x": 1,
      "y": 0,
      "z": 1,
      "name": "Wood_Hardwood_Decorative"
    },
    {
      "x": 1,
      "y": 8,
      "z": 1,
      "name": "Wood_Softwood_Roof_Shallow",
      "filler": 992
    },
    {
      "x": 1,
      "y": 0,
      "z": 2,
      "name": "Wood_Hardwood_Decorative"
    },
    {
      "x": 1,
      "y": 7,
      "z": 2,
      "name": "Wood_Softwood_Stairs",
      "rotation": 8
    },
    {
      "x": 1,
      "y": 8,
      "z": 2,
      "name": "Wood_Softwood_Roof_Shallow"
    },
    {
      "x": 1,
      "y": 0,
      "z": 3,
      "name": "Wood_Hardwood_Decorative"
    },
    {
      "x": 1,
      "y": 1,
      "z": 3,
      "name": "Furniture_Village_Chair",
      "rotation": 1
    },
    {
      "x": 1,
      "y": 2,
      "z": 3,
      "name": "Furniture_Village_Chair",
      "filler": 1024,
      "rotation": 1
    },
    {
      "x": 1,
      "y": 6,
      "z": 3,
      "name": "Wood_Softwood_Stairs",
      "rotation": 8
    },
    {
      "x": 1,
      "y": 7,
      "z": 3,
      "name": "Wood_Softwood_Roof"
    },
    {
      "x": 1,
      "y": 0,
      "z": 4,
      "name": "Wood_Hardwood_Decorative"
    },
    {
      "x": 1,
      "y": 1,
      "z": 4,
      "name": "Furniture_Village_Chair",
      "rotation": 1
    },
    {
      "x": 1,
      "y": 2,
      "z": 4,
      "name": "Furniture_Village_Chair",
      "filler": 1024,
      "rotation": 1
    },
    {
      "x": 1,
      "y": 5,
      "z": 4,
      "name": "Wood_Softwood_Stairs",
      "rotation": 8
    },
    {
      "x": 1,
      "y": 6,
      "z": 4,
      "name": "Wood_Softwood_Roof"
    },
    {
      "x": 1,
      "y": 0,
      "z": 5,
      "name": "Rock_Stone_Cobble"
    },
    {
      "x": 1,
      "y": 1,
      "z": 5,
      "name": "Rock_Stone_Brick"
    },
    {
      "x": 1,
      "y": 2,
      "z": 5,
      "name": "*Wood_Village_Wall_Full_State_Definitions_Bottom"
    },
    {
      "x": 1,
      "y": 3,
      "z": 5,
      "name": "*Wood_Village_Wall_Full_State_Definitions_Top"
    },
    {
      "x": 1,
      "y": 4,
      "z": 5,
      "name": "Wood_Beech_Trunk",
      "support": 15,
      "rotation": 5
    },
    {
      "x": 1,
      "y": 5,
      "z": 5,
      "name": "Wood_Softwood_Roof"
    },
    {
      "x": 1,
      "y": 0,
      "z": 6,
      "name": "Rock_Stone_Cobble"
    },
    {
      "x": 1,
      "y": 2,
      "z": 6,
      "name": "Plant_Vine_Wall",
      "support": 15
    },
    {
      "x": 1,
      "y": 4,
      "z": 6,
      "name": "Wood_Softwood_Roof_Hollow"
    },
    {
      "x": 2,
      "y": 0,
      "z": -5,
      "name": "Rock_Stone_Cobble"
    },
    {
      "x": 2,
      "y": 4,
      "z": -5,
      "name": "Wood_Softwood_Roof_Hollow",
      "rotation": 2
    },
    {
      "x": 2,
      "y": 0,
      "z": -4,
      "name": "Rock_Stone_Cobble"
    },
    {
      "x": 2,
      "y": 1,
      "z": -4,
      "name": "Rock_Stone_Brick"
    },
    {
      "x": 2,
      "y": 2,
      "z": -4,
      "name": "Furniture_Village_Window"
    },
    {
      "x": 2,
      "y": 3,
      "z": -4,
      "name": "Furniture_Village_Window"
    },
    {
      "x": 2,
      "y": 4,
      "z": -4,
      "name": "Wood_Beech_Trunk",
      "support": 15,
      "rotation": 5
    },
    {
      "x": 2,
      "y": 5,
      "z": -4,
      "name": "Wood_Softwood_Roof",
      "rotation": 2
    },
    {
      "x": 2,
      "y": 0,
      "z": -3,
      "name": "Wood_Hardwood_Decorative"
    },
    {
      "x": 2,
      "y": 1,
      "z": -3,
      "name": "Furniture_Village_Table",
      "filler": 1
    },
    {
      "x": 2,
      "y": 5,
      "z": -3,
      "name": "Wood_Softwood_Stairs",
      "rotation": 10
    },
    {
      "x": 2,
      "y": 6,
      "z": -3,
      "name": "Wood_Softwood_Roof",
      "rotation": 2
    },
    {
      "x": 2,
      "y": 0,
      "z": -2,
      "name": "Wood_Hardwood_Decorative"
    },
    {
      "x": 2,
      "y": 1,
      "z": -2,
      "name": "Furniture_Village_Table",
      "filler": 33
    },
    {
      "x": 2,
      "y": 2,
      "z": -2,
      "name": "Deco_Mug"
    },
    {
      "x": 2,
      "y": 6,
      "z": -2,
      "name": "Wood_Hardwood_Stairs",
      "rotation": 10
    },
    {
      "x": 2,
      "y": 7,
      "z": -2,
      "name": "Wood_Softwood_Roof",
      "rotation": 2
    },
    {
      "x": 2,
      "y": 0,
      "z": -1,
      "name": "Wood_Hardwood_Decorative"
    },
    {
      "x": 2,
      "y": 7,
      "z": -1,
      "name": "Wood_Softwood_Stairs",
      "rotation": 10
    },
    {
      "x": 2,
      "y": 8,
      "z": -1,
      "name": "Wood_Softwood_Roof_Shallow",
      "rotation": 2
    },
    {
      "x": 2,
      "y": 0,
      "z": 0,
      "name": "Wood_Hardwood_Decorative"
    },
    {
      "x": 2,
      "y": 4,
      "z": 0,
      "name": "Deco_Lantern_Ceiling"
    },
    {
      "x": 2,
      "y": 5,
      "z": 0,
      "name": "Deco_Rope"
    },
    {
      "x": 2,
      "y": 6,
      "z": 0,
      "name": "Deco_Rope"
    },
    {
      "x": 2,
      "y": 7,
      "z": 0,
      "name": "Deco_Rope"
    },
    {
      "x": 2,
      "y": 8,
      "z": 0,
      "name": "Wood_Softwood_Roof_Shallow",
      "filler": 32,
      "rotation": 2
    },
    {
      "x": 2,
      "y": 0,
      "z": 1,
      "name": "Wood_Hardwood_Decorative"
    },
    {
      "x": 2,
      "y": 8,
      "z": 1,
      "name": "Wood_Softwood_Roof_Shallow",
      "filler": 992
    },
    {
      "x": 2,
      "y": 0,
      "z": 2,
      "name": "Wood_Hardwood_Decorative"
    },
    {
      "x": 2,
      "y": 1,
      "z": 2,
      "name": "Furniture_Village_Bookcase",
      "rotation": 2
    },
    {
      "x": 2,
      "y": 7,
      "z": 2,
      "name": "Wood_Softwood_Stairs",
      "rotation": 8
    },
    {
      "x": 2,
      "y": 8,
      "z": 2,
      "name": "Wood_Softwood_Roof_Shallow"
    },
    {
      "x": 2,
      "y": 0,
      "z": 3,
      "name": "Wood_Hardwood_Decorative"
    },
    {
      "x": 2,
      "y": 1,
      "z": 3,
      "name": "Furniture_Village_Platform"
    },
    {
      "x": 2,
      "y": 6,
      "z": 3,
      "name": "Wood_Softwood_Stairs",
      "rotation": 8
    },
    {
      "x": 2,
      "y": 7,
      "z": 3,
      "name": "Wood_Softwood_Roof"
    },
    {
      "x": 2,
      "y": 0,
      "z": 4,
      "name": "Wood_Hardwood_Decorative"
    },
    {
      "x": 2,
      "y": 1,
      "z": 4,
      "name": "Furniture_Village_Platform"
    },
    {
      "x": 2,
      "y": 2,
      "z": 4,
      "name": "Autumn_Sip"
    },
    {
      "x": 2,
      "y": 5,
      "z": 4,
      "name": "Wood_Softwood_Stairs",
      "rotation": 8
    },
    {
      "x": 2,
      "y": 6,
      "z": 4,
      "name": "Wood_Softwood_Roof"
    },
    {
      "x": 2,
      "y": 0,
      "z": 5,
      "name": "Rock_Stone_Cobble"
    },
    {
      "x": 2,
      "y": 1,
      "z": 5,
      "name": "Rock_Stone_Brick"
    },
    {
      "x": 2,
      "y": 2,
      "z": 5,
      "name": "Furniture_Village_Window"
    },
    {
      "x": 2,
      "y": 3,
      "z": 5,
      "name": "Furniture_Village_Window"
    },
    {
      "x": 2,
      "y": 4,
      "z": 5,
      "name": "Wood_Beech_Trunk",
      "support": 15,
      "rotation": 5
    },
    {
      "x": 2,
      "y": 5,
      "z": 5,
      "name": "Wood_Softwood_Roof"
    },
    {
      "x": 2,
      "y": 0,
      "z": 6,
      "name": "Rock_Stone_Cobble"
    },
    {
      "x": 2,
      "y": 4,
      "z": 6,
      "name": "Wood_Softwood_Roof_Hollow"
    },
    {
      "x": 3,
      "y": 0,
      "z": -5,
      "name": "Rock_Stone_Cobble"
    },
    {
      "x": 3,
      "y": 4,
      "z": -5,
      "name": "Wood_Softwood_Roof_Hollow",
      "rotation": 2
    },
    {
      "x": 3,
      "y": 0,
      "z": -4,
      "name": "Rock_Stone_Cobble"
    },
    {
      "x": 3,
      "y": 1,
      "z": -4,
      "name": "Rock_Stone_Brick"
    },
    {
      "x": 3,
      "y": 2,
      "z": -4,
      "name": "Furniture_Village_Window"
    },
    {
      "x": 3,
      "y": 3,
      "z": -4,
      "name": "Furniture_Village_Window"
    },
    {
      "x": 3,
      "y": 4,
      "z": -4,
      "name": "Wood_Beech_Trunk",
      "support": 15,
      "rotation": 5
    },
    {
      "x": 3,
      "y": 5,
      "z": -4,
      "name": "Wood_Softwood_Roof",
      "rotation": 2
    },
    {
      "x": 3,
      "y": 0,
      "z": -3,
      "name": "Wood_Hardwood_Decorative"
    },
    {
      "x": 3,
      "y": 1,
      "z": -3,
      "name": "Furniture_Village_Stool"
    },
    {
      "x": 3,
      "y": 5,
      "z": -3,
      "name": "Wood_Softwood_Stairs",
      "rotation": 10
    },
    {
      "x": 3,
      "y": 6,
      "z": -3,
      "name": "Wood_Softwood_Roof",
      "rotation": 2
    },
    {
      "x": 3,
      "y": 0,
      "z": -2,
      "name": "Wood_Hardwood_Decorative"
    },
    {
      "x": 3,
      "y": 1,
      "z": -2,
      "name": "Furniture_Village_Stool"
    },
    {
      "x": 3,
      "y": 6,
      "z": -2,
      "name": "Wood_Hardwood_Stairs",
      "rotation": 10
    },
    {
      "x": 3,
      "y": 7,
      "z": -2,
      "name": "Wood_Softwood_Roof",
      "rotation": 2
    },
    {
      "x": 3,
      "y": 0,
      "z": -1,
      "name": "Wood_Hardwood_Decorative"
    },
    {
      "x": 3,
      "y": 7,
      "z": -1,
      "name": "Wood_Softwood_Stairs",
      "rotation": 10
    },
    {
      "x": 3,
      "y": 8,
      "z": -1,
      "name": "Wood_Softwood_Roof_Shallow",
      "rotation": 2
    },
    {
      "x": 3,
      "y": 0,
      "z": 0,
      "name": "Wood_Hardwood_Decorative"
    },
    {
      "x": 3,
      "y": 8,
      "z": 0,
      "name": "Wood_Softwood_Roof_Shallow",
      "filler": 32,
      "rotation": 2
    },
    {
      "x": 3,
      "y": 0,
      "z": 1,
      "name": "Wood_Hardwood_Decorative"
    },
    {
      "x": 3,
      "y": 8,
      "z": 1,
      "name": "Wood_Softwood_Roof_Shallow",
      "filler": 992
    },
    {
      "x": 3,
      "y": 0,
      "z": 2,
      "name": "Wood_Hardwood_Decorative"
    },
    {
      "x": 3,
      "y": 7,
      "z": 2,
      "name": "Wood_Softwood_Stairs",
      "rotation": 8
    },
    {
      "x": 3,
      "y": 8,
      "z": 2,
      "name": "Wood_Softwood_Roof_Shallow"
    },
    {
      "x": 3,
      "y": 0,
      "z": 3,
      "name": "Wood_Hardwood_Decorative"
    },
    {
      "x": 3,
      "y": 1,
      "z": 3,
      "name": "Furniture_Village_Chair",
      "rotation": 3
    },
    {
      "x": 3,
      "y": 2,
      "z": 3,
      "name": "Furniture_Village_Chair",
      "filler": 1024,
      "rotation": 3
    },
    {
      "x": 3,
      "y": 6,
      "z": 3,
      "name": "Wood_Softwood_Stairs",
      "rotation": 8
    },
    {
      "x": 3,
      "y": 7,
      "z": 3,
      "name": "Wood_Softwood_Roof"
    },
    {
      "x": 3,
      "y": 0,
      "z": 4,
      "name": "Wood_Hardwood_Decorative"
    },
    {
      "x": 3,
      "y": 1,
      "z": 4,
      "name": "Furniture_Village_Chair",
      "rotation": 3
    },
    {
      "x": 3,
      "y": 2,
      "z": 4,
      "name": "Furniture_Village_Chair",
      "filler": 1024,
      "rotation": 3
    },
    {
      "x": 3,
      "y": 5,
      "z": 4,
      "name": "Wood_Softwood_Stairs",
      "rotation": 8
    },
    {
      "x": 3,
      "y": 6,
      "z": 4,
      "name": "Wood_Softwood_Roof"
    },
    {
      "x": 3,
      "y": 0,
      "z": 5,
      "name": "Rock_Stone_Cobble"
    },
    {
      "x": 3,
      "y": 1,
      "z": 5,
      "name": "Rock_Stone_Brick"
    },
    {
      "x": 3,
      "y": 2,
      "z": 5,
      "name": "Furniture_Village_Window"
    },
    {
      "x": 3,
      "y": 3,
      "z": 5,
      "name": "Furniture_Village_Window"
    },
    {
      "x": 3,
      "y": 4,
      "z": 5,
      "name": "Wood_Beech_Trunk",
      "support": 15,
      "rotation": 5
    },
    {
      "x": 3,
      "y": 5,
      "z": 5,
      "name": "Wood_Softwood_Roof"
    },
    {
      "x": 3,
      "y": 0,
      "z": 6,
      "name": "Rock_Stone_Cobble_Mossy"
    },
    {
      "x": 3,
      "y": 4,
      "z": 6,
      "name": "Wood_Softwood_Roof_Hollow"
    },
    {
      "x": 4,
      "y": 0,
      "z": -5,
      "name": "Rock_Stone_Cobble"
    },
    {
      "x": 4,
      "y": 4,
      "z": -5,
      "name": "Wood_Softwood_Roof_Hollow",
      "rotation": 2
    },
    {
      "x": 4,
      "y": 0,
      "z": -4,
      "name": "Rock_Stone_Cobble"
    },
    {
      "x": 4,
      "y": 1,
      "z": -4,
      "name": "Rock_Stone_Brick"
    },
    {
      "x": 4,
      "y": 2,
      "z": -4,
      "name": "*Wood_Village_Wall_Full_State_Definitions_Bottom"
    },
    {
      "x": 4,
      "y": 3,
      "z": -4,
      "name": "*Wood_Village_Wall_Full_State_Definitions_Top"
    },
    {
      "x": 4,
      "y": 4,
      "z": -4,
      "name": "Wood_Beech_Trunk",
      "support": 15,
      "rotation": 5
    },
    {
      "x": 4,
      "y": 5,
      "z": -4,
      "name": "Wood_Softwood_Roof",
      "rotation": 2
    },
    {
      "x": 4,
      "y": 0,
      "z": -3,
      "name": "Wood_Hardwood_Decorative"
    },
    {
      "x": 4,
      "y": 5,
      "z": -3,
      "name": "Wood_Hardwood_Stairs",
      "rotation": 10
    },
    {
      "x": 4,
      "y": 6,
      "z": -3,
      "name": "Wood_Softwood_Roof",
      "rotation": 2
    },
    {
      "x": 4,
      "y": 0,
      "z": -2,
      "name": "Wood_Hardwood_Decorative"
    },
    {
      "x": 4,
      "y": 6,
      "z": -2,
      "name": "Wood_Hardwood_Stairs",
      "rotation": 10
    },
    {
      "x": 4,
      "y": 7,
      "z": -2,
      "name": "Wood_Softwood_Roof",
      "rotation": 2
    },
    {
      "x": 4,
      "y": 0,
      "z": -1,
      "name": "Wood_Hardwood_Decorative"
    },
    {
      "x": 4,
      "y": 7,
      "z": -1,
      "name": "Wood_Softwood_Stairs",
      "rotation": 10
    },
    {
      "x": 4,
      "y": 8,
      "z": -1,
      "name": "Wood_Softwood_Roof_Shallow",
      "rotation": 2
    },
    {
      "x": 4,
      "y": 0,
      "z": 0,
      "name": "Wood_Hardwood_Decorative"
    },
    {
      "x": 4,
      "y": 1,
      "z": 0,
      "name": "*Furniture_Village_Door_State_Definitions_OpenDoorIn",
      "filler": 31,
      "rotation": 3
    },
    {
      "x": 4,
      "y": 2,
      "z": 0,
      "name": "*Furniture_Village_Door_State_Definitions_OpenDoorIn",
      "filler": 1055,
      "rotation": 3
    },
    {
      "x": 4,
      "y": 8,
      "z": 0,
      "name": "Wood_Softwood_Roof_Shallow",
      "filler": 32,
      "rotation": 2
    },
    {
      "x": 4,
      "y": 0,
      "z": 1,
      "name": "Wood_Hardwood_Decorative"
    },
    {
      "x": 4,
      "y": 1,
      "z": 1,
      "name": "*Furniture_Village_Door_State_Definitions_OpenDoorOut",
      "filler": 31,
      "rotation": 1
    },
    {
      "x": 4,
      "y": 2,
      "z": 1,
      "name": "*Furniture_Village_Door_State_Definitions_OpenDoorOut",
      "filler": 1055,
      "rotation": 1
    },
    {
      "x": 4,
      "y": 8,
      "z": 1,
      "name": "Wood_Softwood_Roof_Shallow",
      "filler": 992
    },
    {
      "x": 4,
      "y": 0,
      "z": 2,
      "name": "Wood_Hardwood_Decorative"
    },
    {
      "x": 4,
      "y": 7,
      "z": 2,
      "name": "Wood_Softwood_Stairs",
      "rotation": 8
    },
    {
      "x": 4,
      "y": 8,
      "z": 2,
      "name": "Wood_Softwood_Roof_Shallow"
    },
    {
      "x": 4,
      "y": 0,
      "z": 3,
      "name": "Wood_Hardwood_Decorative"
    },
    {
      "x": 4,
      "y": 6,
      "z": 3,
      "name": "Wood_Softwood_Stairs",
      "rotation": 8
    },
    {
      "x": 4,
      "y": 7,
      "z": 3,
      "name": "Wood_Softwood_Roof"
    },
    {
      "x": 4,
      "y": 0,
      "z": 4,
      "name": "Wood_Hardwood_Decorative"
    },
    {
      "x": 4,
      "y": 5,
      "z": 4,
      "name": "Wood_Softwood_Stairs",
      "rotation": 8
    },
    {
      "x": 4,
      "y": 6,
      "z": 4,
      "name": "Wood_Softwood_Roof"
    },
    {
      "x": 4,
      "y": 0,
      "z": 5,
      "name": "Rock_Stone_Cobble"
    },
    {
      "x": 4,
      "y": 1,
      "z": 5,
      "name": "Rock_Stone_Brick"
    },
    {
      "x": 4,
      "y": 2,
      "z": 5,
      "name": "*Wood_Village_Wall_Full_State_Definitions_Bottom"
    },
    {
      "x": 4,
      "y": 3,
      "z": 5,
      "name": "*Wood_Village_Wall_Full_State_Definitions_Top"
    },
    {
      "x": 4,
      "y": 4,
      "z": 5,
      "name": "Wood_Beech_Trunk",
      "support": 15,
      "rotation": 5
    },
    {
      "x": 4,
      "y": 5,
      "z": 5,
      "name": "Wood_Softwood_Roof"
    },
    {
      "x": 4,
      "y": 0,
      "z": 6,
      "name": "Rock_Stone_Cobble_Mossy"
    },
    {
      "x": 4,
      "y": 4,
      "z": 6,
      "name": "Wood_Softwood_Roof_Hollow"
    },
    {
      "x": 5,
      "y": 0,
      "z": -5,
      "name": "Rock_Stone_Cobble_Mossy"
    },
    {
      "x": 5,
      "y": 2,
      "z": -5,
      "name": "Plant_Vine_Wall",
      "support": 15,
      "rotation": 2
    },
    {
      "x": 5,
      "y": 3,
      "z": -5,
      "name": "Wood_Beech_Trunk_Half",
      "rotation": 6
    },
    {
      "x": 5,
      "y": 4,
      "z": -5,
      "name": "Wood_Softwood_Roof_Hollow",
      "rotation": 2
    },
    {
      "x": 5,
      "y": 0,
      "z": -4,
      "name": "Rock_Stone_Cobble"
    },
    {
      "x": 5,
      "y": 1,
      "z": -4,
      "name": "Wood_Beech_Trunk",
      "support": 15
    },
    {
      "x": 5,
      "y": 2,
      "z": -4,
      "name": "Wood_Beech_Trunk",
      "support": 15
    },
    {
      "x": 5,
      "y": 3,
      "z": -4,
      "name": "Wood_Beech_Trunk",
      "support": 15
    },
    {
      "x": 5,
      "y": 4,
      "z": -4,
      "name": "Wood_Beech_Trunk",
      "support": 15
    },
    {
      "x": 5,
      "y": 5,
      "z": -4,
      "name": "Wood_Softwood_Roof",
      "rotation": 2
    },
    {
      "x": 5,
      "y": 0,
      "z": -3,
      "name": "Rock_Stone_Cobble"
    },
    {
      "x": 5,
      "y": 1,
      "z": -3,
      "name": "Rock_Stone_Brick"
    },
    {
      "x": 5,
      "y": 2,
      "z": -3,
      "name": "*Wood_Village_Wall_Full_State_Definitions_Bottom"
    },
    {
      "x": 5,
      "y": 3,
      "z": -3,
      "name": "*Wood_Village_Wall_Full_State_Definitions_Top"
    },
    {
      "x": 5,
      "y": 4,
      "z": -3,
      "name": "Wood_Beech_Trunk",
      "support": 15,
      "rotation": 4
    },
    {
      "x": 5,
      "y": 5,
      "z": -3,
      "name": "Wood_Village_Wall_Full"
    },
    {
      "x": 5,
      "y": 6,
      "z": -3,
      "name": "Wood_Softwood_Roof",
      "rotation": 2
    },
    {
      "x": 5,
      "y": 0,
      "z": -2,
      "name": "Rock_Stone_Cobble"
    },
    {
      "x": 5,
      "y": 1,
      "z": -2,
      "name": "Rock_Stone_Brick"
    },
    {
      "x": 5,
      "y": 2,
      "z": -2,
      "name": "Furniture_Village_Window",
      "rotation": 1
    },
    {
      "x": 5,
      "y": 3,
      "z": -2,
      "name": "Furniture_Village_Window",
      "rotation": 1
    },
    {
      "x": 5,
      "y": 4,
      "z": -2,
      "name": "Wood_Beech_Trunk",
      "support": 15,
      "rotation": 4
    },
    {
      "x": 5,
      "y": 5,
      "z": -2,
      "name": "*Wood_Village_Wall_Full_State_Definitions_Bottom"
    },
    {
      "x": 5,
      "y": 6,
      "z": -2,
      "name": "*Wood_Village_Wall_Full_State_Definitions_Top"
    },
    {
      "x": 5,
      "y": 7,
      "z": -2,
      "name": "Wood_Softwood_Roof",
      "rotation": 2
    },
    {
      "x": 5,
      "y": 0,
      "z": -1,
      "name": "Rock_Stone_Cobble"
    },
    {
      "x": 5,
      "y": 1,
      "z": -1,
      "name": "Wood_Beech_Trunk",
      "support": 15
    },
    {
      "x": 5,
      "y": 2,
      "z": -1,
      "name": "Wood_Beech_Trunk",
      "support": 15
    },
    {
      "x": 5,
      "y": 3,
      "z": -1,
      "name": "Wood_Beech_Trunk",
      "support": 15
    },
    {
      "x": 5,
      "y": 4,
      "z": -1,
      "name": "Wood_Beech_Trunk",
      "support": 15
    },
    {
      "x": 5,
      "y": 5,
      "z": -1,
      "name": "Wood_Beech_Trunk",
      "support": 15
    },
    {
      "x": 5,
      "y": 6,
      "z": -1,
      "name": "Wood_Beech_Trunk",
      "support": 15
    },
    {
      "x": 5,
      "y": 7,
      "z": -1,
      "name": "Wood_Beech_Trunk",
      "support": 15
    },
    {
      "x": 5,
      "y": 8,
      "z": -1,
      "name": "Wood_Softwood_Roof_Shallow",
      "rotation": 2
    },
    {
      "x": 5,
      "y": 0,
      "z": 0,
      "name": "Rock_Stone_Cobble"
    },
    {
      "x": 5,
      "y": 1,
      "z": 0,
      "name": "*Furniture_Village_Door_State_Definitions_OpenDoorIn",
      "rotation": 3
    },
    {
      "x": 5,
      "y": 2,
      "z": 0,
      "name": "*Furniture_Village_Door_State_Definitions_OpenDoorIn",
      "filler": 1024,
      "rotation": 3
    },
    {
      "x": 5,
      "y": 3,
      "z": 0,
      "name": "Wood_Hardwood_Ornate"
    },
    {
      "x": 5,
      "y": 4,
      "z": 0,
      "name": "Wood_Beech_Trunk",
      "support": 15,
      "rotation": 4
    },
    {
      "x": 5,
      "y": 5,
      "z": 0,
      "name": "Furniture_Village_Window",
      "rotation": 1
    },
    {
      "x": 5,
      "y": 6,
      "z": 0,
      "name": "Furniture_Village_Window",
      "rotation": 1
    },
    {
      "x": 5,
      "y": 7,
      "z": 0,
      "name": "Wood_Village_Wall_Full"
    },
    {
      "x": 5,
      "y": 8,
      "z": 0,
      "name": "Wood_Softwood_Roof_Shallow",
      "filler": 32,
      "rotation": 2
    },
    {
      "x": 5,
      "y": 0,
      "z": 1,
      "name": "Rock_Stone_Cobble"
    },
    {
      "x": 5,
      "y": 1,
      "z": 1,
      "name": "*Furniture_Village_Door_State_Definitions_OpenDoorOut",
      "rotation": 1
    },
    {
      "x": 5,
      "y": 2,
      "z": 1,
      "name": "*Furniture_Village_Door_State_Definitions_OpenDoorOut",
      "filler": 1024,
      "rotation": 1
    },
    {
      "x": 5,
      "y": 3,
      "z": 1,
      "name": "Wood_Hardwood_Ornate"
    },
    {
      "x": 5,
      "y": 4,
      "z": 1,
      "name": "Wood_Beech_Trunk",
      "support": 15,
      "rotation": 4
    },
    {
      "x": 5,
      "y": 5,
      "z": 1,
      "name": "Furniture_Village_Window",
      "rotation": 1
    },
    {
      "x": 5,
      "y": 6,
      "z": 1,
      "name": "Furniture_Village_Window",
      "rotation": 1
    },
    {
      "x": 5,
      "y": 7,
      "z": 1,
      "name": "Wood_Village_Wall_Full"
    },
    {
      "x": 5,
      "y": 8,
      "z": 1,
      "name": "Wood_Softwood_Roof_Shallow",
      "filler": 992
    },
    {
      "x": 5,
      "y": 0,
      "z": 2,
      "name": "Rock_Stone_Cobble"
    },
    {
      "x": 5,
      "y": 1,
      "z": 2,
      "name": "Wood_Beech_Trunk",
      "support": 15
    },
    {
      "x": 5,
      "y": 2,
      "z": 2,
      "name": "Wood_Beech_Trunk",
      "support": 15
    },
    {
      "x": 5,
      "y": 3,
      "z": 2,
      "name": "Wood_Beech_Trunk",
      "support": 15
    },
    {
      "x": 5,
      "y": 4,
      "z": 2,
      "name": "Wood_Beech_Trunk",
      "support": 15
    },
    {
      "x": 5,
      "y": 5,
      "z": 2,
      "name": "Wood_Beech_Trunk",
      "support": 15
    },
    {
      "x": 5,
      "y": 6,
      "z": 2,
      "name": "Wood_Beech_Trunk",
      "support": 15
    },
    {
      "x": 5,
      "y": 7,
      "z": 2,
      "name": "Wood_Beech_Trunk",
      "support": 15
    },
    {
      "x": 5,
      "y": 8,
      "z": 2,
      "name": "Wood_Softwood_Roof_Shallow"
    },
    {
      "x": 5,
      "y": 0,
      "z": 3,
      "name": "Rock_Stone_Cobble"
    },
    {
      "x": 5,
      "y": 1,
      "z": 3,
      "name": "Rock_Stone_Brick"
    },
    {
      "x": 5,
      "y": 2,
      "z": 3,
      "name": "Furniture_Village_Window",
      "rotation": 1
    },
    {
      "x": 5,
      "y": 3,
      "z": 3,
      "name": "Furniture_Village_Window",
      "rotation": 1
    },
    {
      "x": 5,
      "y": 4,
      "z": 3,
      "name": "Wood_Beech_Trunk",
      "support": 15,
      "rotation": 4
    },
    {
      "x": 5,
      "y": 5,
      "z": 3,
      "name": "*Wood_Village_Wall_Full_State_Definitions_Bottom"
    },
    {
      "x": 5,
      "y": 6,
      "z": 3,
      "name": "*Wood_Village_Wall_Full_State_Definitions_Top"
    },
    {
      "x": 5,
      "y": 7,
      "z": 3,
      "name": "Wood_Softwood_Roof"
    },
    {
      "x": 5,
      "y": 0,
      "z": 4,
      "name": "Rock_Stone_Cobble"
    },
    {
      "x": 5,
      "y": 1,
      "z": 4,
      "name": "Rock_Stone_Brick"
    },
    {
      "x": 5,
      "y": 2,
      "z": 4,
      "name": "*Wood_Village_Wall_Full_State_Definitions_Bottom"
    },
    {
      "x": 5,
      "y": 3,
      "z": 4,
      "name": "*Wood_Village_Wall_Full_State_Definitions_Top"
    },
    {
      "x": 5,
      "y": 4,
      "z": 4,
      "name": "Wood_Beech_Trunk",
      "support": 15,
      "rotation": 4
    },
    {
      "x": 5,
      "y": 5,
      "z": 4,
      "name": "Wood_Village_Wall_Full"
    },
    {
      "x": 5,
      "y": 6,
      "z": 4,
      "name": "Wood_Softwood_Roof"
    },
    {
      "x": 5,
      "y": 0,
      "z": 5,
      "name": "Rock_Stone_Cobble"
    },
    {
      "x": 5,
      "y": 1,
      "z": 5,
      "name": "Wood_Beech_Trunk",
      "support": 15
    },
    {
      "x": 5,
      "y": 2,
      "z": 5,
      "name": "Wood_Beech_Trunk",
      "support": 15
    },
    {
      "x": 5,
      "y": 3,
      "z": 5,
      "name": "Wood_Beech_Trunk",
      "support": 15
    },
    {
      "x": 5,
      "y": 4,
      "z": 5,
      "name": "Wood_Beech_Trunk",
      "support": 15
    },
    {
      "x": 5,
      "y": 5,
      "z": 5,
      "name": "Wood_Softwood_Roof"
    },
    {
      "x": 5,
      "y": 0,
      "z": 6,
      "name": "Rock_Stone_Cobble"
    },
    {
      "x": 5,
      "y": 4,
      "z": 6,
      "name": "Wood_Softwood_Roof_Hollow"
    },
    {
      "x": 6,
      "y": 0,
      "z": -5,
      "name": "Rock_Stone_Cobble_Mossy"
    },
    {
      "x": 6,
      "y": 4,
      "z": -5,
      "name": "Wood_Softwood_Roof_Hollow",
      "rotation": 2
    },
    {
      "x": 6,
      "y": 0,
      "z": -4,
      "name": "Rock_Stone_Cobble_Mossy"
    },
    {
      "x": 6,
      "y": 4,
      "z": -4,
      "name": "Wood_Beech_Trunk",
      "support": 15,
      "rotation": 5
    },
    {
      "x": 6,
      "y": 5,
      "z": -4,
      "name": "Wood_Softwood_Roof",
      "rotation": 2
    },
    {
      "x": 6,
      "y": 0,
      "z": -3,
      "name": "Rock_Stone_Cobble"
    },
    {
      "x": 6,
      "y": 4,
      "z": -3,
      "name": "Plant_Vine_Wall",
      "support": 15,
      "rotation": 1
    },
    {
      "x": 6,
      "y": 5,
      "z": -3,
      "name": "Wood_Softwood_Stairs",
      "rotation": 10
    },
    {
      "x": 6,
      "y": 6,
      "z": -3,
      "name": "Wood_Softwood_Roof",
      "rotation": 2
    },
    {
      "x": 6,
      "y": 0,
      "z": -2,
      "name": "Rock_Stone_Cobble"
    },
    {
      "x": 6,
      "y": 6,
      "z": -2,
      "name": "Wood_Softwood_Stairs",
      "rotation": 10
    },
    {
      "x": 6,
      "y": 7,
      "z": -2,
      "name": "Wood_Softwood_Roof",
      "rotation": 2
    },
    {
      "x": 6,
      "y": 0,
      "z": -1,
      "name": "Rock_Stone_Cobble"
    },
    {
      "x": 6,
      "y": 2,
      "z": -1,
      "name": "Wood_Torch_Wall",
      "rotation": 1
    },
    {
      "x": 6,
      "y": 4,
      "z": -1,
      "name": "Wood_Beech_Trunk_Half",
      "rotation": 5
    },
    {
      "x": 6,
      "y": 7,
      "z": -1,
      "name": "Wood_Softwood_Stairs",
      "rotation": 10
    },
    {
      "x": 6,
      "y": 8,
      "z": -1,
      "name": "Wood_Softwood_Roof_Shallow",
      "rotation": 2
    },
    {
      "x": 6,
      "y": 0,
      "z": 0,
      "name": "Rock_Stone_Cobble"
    },
    {
      "x": 6,
      "y": 7,
      "z": 0,
      "name": "Wood_Softwood_Planks_Half",
      "rotation": 8
    },
    {
      "x": 6,
      "y": 8,
      "z": 0,
      "name": "Wood_Softwood_Roof_Shallow",
      "filler": 32,
      "rotation": 2
    },
    {
      "x": 6,
      "y": 0,
      "z": 1,
      "name": "Rock_Stone_Cobble"
    },
    {
      "x": 6,
      "y": 7,
      "z": 1,
      "name": "Wood_Softwood_Planks_Half",
      "rotation": 8
    },
    {
      "x": 6,
      "y": 8,
      "z": 1,
      "name": "Wood_Softwood_Roof_Shallow",
      "filler": 992
    },
    {
      "x": 6,
      "y": 0,
      "z": 2,
      "name": "Rock_Stone_Cobble"
    },
    {
      "x": 6,
      "y": 2,
      "z": 2,
      "name": "Wood_Torch_Wall",
      "rotation": 1
    },
    {
      "x": 6,
      "y": 4,
      "z": 2,
      "name": "Wood_Beech_Trunk_Half",
      "rotation": 5
    },
    {
      "x": 6,
      "y": 7,
      "z": 2,
      "name": "Wood_Softwood_Stairs",
      "rotation": 8
    },
    {
      "x": 6,
      "y": 8,
      "z": 2,
      "name": "Wood_Softwood_Roof_Shallow"
    },
    {
      "x": 6,
      "y": 0,
      "z": 3,
      "name": "Rock_Stone_Cobble"
    },
    {
      "x": 6,
      "y": 5,
      "z": 3,
      "name": "Plant_Vine_Wall",
      "support": 15,
      "rotation": 1
    },
    {
      "x": 6,
      "y": 6,
      "z": 3,
      "name": "Wood_Softwood_Stairs",
      "rotation": 8
    },
    {
      "x": 6,
      "y": 7,
      "z": 3,
      "name": "Wood_Softwood_Roof"
    },
    {
      "x": 6,
      "y": 0,
      "z": 4,
      "name": "Rock_Stone_Cobble_Mossy"
    },
    {
      "x": 6,
      "y": 5,
      "z": 4,
      "name": "Wood_Softwood_Stairs",
      "rotation": 8
    },
    {
      "x": 6,
      "y": 6,
      "z": 4,
      "name": "Wood_Softwood_Roof"
    },
    {
      "x": 6,
      "y": 0,
      "z": 5,
      "name": "Rock_Stone_Cobble"
    },
    {
      "x": 6,
      "y": 4,
      "z": 5,
      "name": "Wood_Beech_Trunk",
      "support": 15,
      "rotation": 5
    },
    {
      "x": 6,
      "y": 5,
      "z": 5,
      "name": "Wood_Softwood_Roof"
    },
    {
      "x": 6,
      "y": 0,
      "z": 6,
      "name": "Rock_Stone_Cobble"
    },
    {
      "x": 6,
      "y": 4,
      "z": 6,
      "name": "Wood_Softwood_Roof_Hollow"
    }
  ],
  "fluids": [
    {
      "x": -6,
      "y": 0,
      "z": -5,
      "name": "Empty",
      "level": 0
    },
    {
      "x": -6,
      "y": 1,
      "z": -5,
      "name": "Empty",
      "level": 0
    },
    {
      "x": -6,
      "y": 2,
      "z": -5,
      "name": "Empty",
      "level": 0
    },
    {
      "x": -6,
      "y": 4,
      "z": -5,
      "name": "Empty",
      "level": 0
    },
    {
      "x": -6,
      "y": 0,
      "z": -4,
      "name": "Empty",
      "level": 0
    },
    {
      "x": -6,
      "y": 1,
      "z": -4,
      "name": "Empty",
      "level": 0
    },
    {
      "x": -6,
      "y": 4,
      "z": -4,
      "name": "Empty",
      "level": 0
    },
    {
      "x": -6,
      "y": 5,
      "z": -4,
      "name": "Empty",
      "level": 0
    },
    {
      "x": -6,
      "y": 0,
      "z": -3,
      "name": "Empty",
      "level": 0
    },
    {
      "x": -6,
      "y": 4,
      "z": -3,
      "name": "Empty",
      "level": 0
    },
    {
      "x": -6,
      "y": 5,
      "z": -3,
      "name": "Empty",
      "level": 0
    },
    {
      "x": -6,
      "y": 6,
      "z": -3,
      "name": "Empty",
      "level": 0
    },
    {
      "x": -6,
      "y": 0,
      "z": -2,
      "name": "Empty",
      "level": 0
    },
    {
      "x": -6,
      "y": 6,
      "z": -2,
      "name": "Empty",
      "level": 0
    },
    {
      "x": -6,
      "y": 7,
      "z": -2,
      "name": "Empty",
      "level": 0
    },
    {
      "x": -6,
      "y": 0,
      "z": -1,
      "name": "Empty",
      "level": 0
    },
    {
      "x": -6,
      "y": 4,
      "z": -1,
      "name": "Empty",
      "level": 0
    },
    {
      "x": -6,
      "y": 7,
      "z": -1,
      "name": "Empty",
      "level": 0
    },
    {
      "x": -6,
      "y": 8,
      "z": -1,
      "name": "Empty",
      "level": 0
    },
    {
      "x": -6,
      "y": 0,
      "z": 0,
      "name": "Empty",
      "level": 0
    },
    {
      "x": -6,
      "y": 7,
      "z": 0,
      "name": "Empty",
      "level": 0
    },
    {
      "x": -6,
      "y": 8,
      "z": 0,
      "name": "Empty",
      "level": 0
    },
    {
      "x": -6,
      "y": 0,
      "z": 1,
      "name": "Empty",
      "level": 0
    },
    {
      "x": -6,
      "y": 7,
      "z": 1,
      "name": "Empty",
      "level": 0
    },
    {
      "x": -6,
      "y": 8,
      "z": 1,
      "name": "Empty",
      "level": 0
    },
    {
      "x": -6,
      "y": 0,
      "z": 2,
      "name": "Empty",
      "level": 0
    },
    {
      "x": -6,
      "y": 4,
      "z": 2,
      "name": "Empty",
      "level": 0
    },
    {
      "x": -6,
      "y": 7,
      "z": 2,
      "name": "Empty",
      "level": 0
    },
    {
      "x": -6,
      "y": 8,
      "z": 2,
      "name": "Empty",
      "level": 0
    },
    {
      "x": -6,
      "y": 0,
      "z": 3,
      "name": "Empty",
      "level": 0
    },
    {
      "x": -6,
      "y": 5,
      "z": 3,
      "name": "Empty",
      "level": 0
    },
    {
      "x": -6,
      "y": 6,
      "z": 3,
      "name": "Empty",
      "level": 0
    },
    {
      "x": -6,
      "y": 7,
      "z": 3,
      "name": "Empty",
      "level": 0
    },
    {
      "x": -6,
      "y": 0,
      "z": 4,
      "name": "Empty",
      "level": 0
    },
    {
      "x": -6,
      "y": 2,
      "z": 4,
      "name": "Empty",
      "level": 0
    },
    {
      "x": -6,
      "y": 5,
      "z": 4,
      "name": "Empty",
      "level": 0
    },
    {
      "x": -6,
      "y": 6,
      "z": 4,
      "name": "Empty",
      "level": 0
    },
    {
      "x": -6,
      "y": 0,
      "z": 5,
      "name": "Empty",
      "level": 0
    },
    {
      "x": -6,
      "y": 4,
      "z": 5,
      "name": "Empty",
      "level": 0
    },
    {
      "x": -6,
      "y": 5,
      "z": 5,
      "name": "Empty",
      "level": 0
    },
    {
      "x": -6,
      "y": 0,
      "z": 6,
      "name": "Empty",
      "level": 0
    },
    {
      "x": -6,
      "y": 4,
      "z": 6,
      "name": "Empty",
      "level": 0
    },
    {
      "x": -5,
      "y": 0,
      "z": -5,
      "name": "Empty",
      "level": 0
    },
    {
      "x": -5,
      "y": 1,
      "z": -5,
      "name": "Empty",
      "level": 0
    },
    {
      "x": -5,
      "y": 3,
      "z": -5,
      "name": "Empty",
      "level": 0
    },
    {
      "x": -5,
      "y": 4,
      "z": -5,
      "name": "Empty",
      "level": 0
    },
    {
      "x": -5,
      "y": 0,
      "z": -4,
      "name": "Empty",
      "level": 0
    },
    {
      "x": -5,
      "y": 1,
      "z": -4,
      "name": "Empty",
      "level": 0
    },
    {
      "x": -5,
      "y": 2,
      "z": -4,
      "name": "Empty",
      "level": 0
    },
    {
      "x": -5,
      "y": 3,
      "z": -4,
      "name": "Empty",
      "level": 0
    },
    {
      "x": -5,
      "y": 4,
      "z": -4,
      "name": "Empty",
      "level": 0
    },
    {
      "x": -5,
      "y": 5,
      "z": -4,
      "name": "Empty",
      "level": 0
    },
    {
      "x": -5,
      "y": 0,
      "z": -3,
      "name": "Empty",
      "level": 0
    },
    {
      "x": -5,
      "y": 1,
      "z": -3,
      "name": "Empty",
      "level": 0
    },
    {
      "x": -5,
      "y": 2,
      "z": -3,
      "name": "Empty",
      "level": 0
    },
    {
      "x": -5,
      "y": 3,
      "z": -3,
      "name": "Empty",
      "level": 0
    },
    {
      "x": -5,
      "y": 4,
      "z": -3,
      "name": "Empty",
      "level": 0
    },
    {
      "x": -5,
      "y": 5,
      "z": -3,
      "name": "Empty",
      "level": 0
    },
    {
      "x": -5,
      "y": 6,
      "z": -3,
      "name": "Empty",
      "level": 0
    },
    {
      "x": -5,
      "y": 0,
      "z": -2,
      "name": "Empty",
      "level": 0
    },
    {
      "x": -5,
      "y": 1,
      "z": -2,
      "name": "Empty",
      "level": 0
    },
    {
      "x": -5,
      "y": 2,
      "z": -2,
      "name": "Empty",
      "level": 0
    },
    {
      "x": -5,
      "y": 3,
      "z": -2,
      "name": "Empty",
      "level": 0
    },
    {
      "x": -5,
      "y": 4,
      "z": -2,
      "name": "Empty",
      "level": 0
    },
    {
      "x": -5,
      "y": 5,
      "z": -2,
      "name": "Empty",
      "level": 0
    },
    {
      "x": -5,
      "y": 6,
      "z": -2,
      "name": "Empty",
      "level": 0
    },
    {
      "x": -5,
      "y": 7,
      "z": -2,
      "name": "Empty",
      "level": 0
    },
    {
      "x": -5,
      "y": 0,
      "z": -1,
      "name": "Empty",
      "level": 0
    },
    {
      "x": -5,
      "y": 1,
      "z": -1,
      "name": "Empty",
      "level": 0
    },
    {
      "x": -5,
      "y": 2,
      "z": -1,
      "name": "Empty",
      "level": 0
    },
    {
      "x": -5,
      "y": 3,
      "z": -1,
      "name": "Empty",
      "level": 0
    },
    {
      "x": -5,
      "y": 4,
      "z": -1,
      "name": "Empty",
      "level": 0
    },
    {
      "x": -5,
      "y": 5,
      "z": -1,
      "name": "Empty",
      "level": 0
    },
    {
      "x": -5,
      "y": 6,
      "z": -1,
      "name": "Empty",
      "level": 0
    },
    {
      "x": -5,
      "y": 7,
      "z": -1,
      "name": "Empty",
      "level": 0
    },
    {
      "x": -5,
      "y": 8,
      "z": -1,
      "name": "Empty",
      "level": 0
    },
    {
      "x": -5,
      "y": 0,
      "z": 0,
      "name": "Empty",
      "level": 0
    },
    {
      "x": -5,
      "y": 1,
      "z": 0,
      "name": "Empty",
      "level": 0
    },
    {
      "x": -5,
      "y": 2,
      "z": 0,
      "name": "Empty",
      "level": 0
    },
    {
      "x": -5,
      "y": 3,
      "z": 0,
      "name": "Empty",
      "level": 0
    },
    {
      "x": -5,
      "y": 4,
      "z": 0,
      "name": "Empty",
      "level": 0
    },
    {
      "x": -5,
      "y": 5,
      "z": 0,
      "name": "Empty",
      "level": 0
    },
    {
      "x": -5,
      "y": 6,
      "z": 0,
      "name": "Empty",
      "level": 0
    },
    {
      "x": -5,
      "y": 7,
      "z": 0,
      "name": "Empty",
      "level": 0
    },
    {
      "x": -5,
      "y": 8,
      "z": 0,
      "name": "Empty",
      "level": 0
    },
    {
      "x": -5,
      "y": 0,
      "z": 1,
      "name": "Empty",
      "level": 0
    },
    {
      "x": -5,
      "y": 1,
      "z": 1,
      "name": "Empty",
      "level": 0
    },
    {
      "x": -5,
      "y": 2,
      "z": 1,
      "name": "Empty",
      "level": 0
    },
    {
      "x": -5,
      "y": 3,
      "z": 1,
      "name": "Empty",
      "level": 0
    },
    {
      "x": -5,
      "y": 4,
      "z": 1,
      "name": "Empty",
      "level": 0
    },
    {
      "x": -5,
      "y": 5,
      "z": 1,
      "name": "Empty",
      "level": 0
    },
    {
      "x": -5,
      "y": 6,
      "z": 1,
      "name": "Empty",
      "level": 0
    },
    {
      "x": -5,
      "y": 7,
      "z": 1,
      "name": "Empty",
      "level": 0
    },
    {
      "x": -5,
      "y": 8,
      "z": 1,
      "name": "Empty",
      "level": 0
    },
    {
      "x": -5,
      "y": 0,
      "z": 2,
      "name": "Empty",
      "level": 0
    },
    {
      "x": -5,
      "y": 1,
      "z": 2,
      "name": "Empty",
      "level": 0
    },
    {
      "x": -5,
      "y": 2,
      "z": 2,
      "name": "Empty",
      "level": 0
    },
    {
      "x": -5,
      "y": 3,
      "z": 2,
      "name": "Empty",
      "level": 0
    },
    {
      "x": -5,
      "y": 4,
      "z": 2,
      "name": "Empty",
      "level": 0
    },
    {
      "x": -5,
      "y": 5,
      "z": 2,
      "name": "Empty",
      "level": 0
    },
    {
      "x": -5,
      "y": 6,
      "z": 2,
      "name": "Empty",
      "level": 0
    },
    {
      "x": -5,
      "y": 7,
      "z": 2,
      "name": "Empty",
      "level": 0
    },
    {
      "x": -5,
      "y": 8,
      "z": 2,
      "name": "Empty",
      "level": 0
    },
    {
      "x": -5,
      "y": 0,
      "z": 3,
      "name": "Empty",
      "level": 0
    },
    {
      "x": -5,
      "y": 1,
      "z": 3,
      "name": "Empty",
      "level": 0
    },
    {
      "x": -5,
      "y": 2,
      "z": 3,
      "name": "Empty",
      "level": 0
    },
    {
      "x": -5,
      "y": 3,
      "z": 3,
      "name": "Empty",
      "level": 0
    },
    {
      "x": -5,
      "y": 4,
      "z": 3,
      "name": "Empty",
      "level": 0
    },
    {
      "x": -5,
      "y": 5,
      "z": 3,
      "name": "Empty",
      "level": 0
    },
    {
      "x": -5,
      "y": 6,
      "z": 3,
      "name": "Empty",
      "level": 0
    },
    {
      "x": -5,
      "y": 7,
      "z": 3,
      "name": "Empty",
      "level": 0
    },
    {
      "x": -5,
      "y": 0,
      "z": 4,
      "name": "Empty",
      "level": 0
    },
    {
      "x": -5,
      "y": 1,
      "z": 4,
      "name": "Empty",
      "level": 0
    },
    {
      "x": -5,
      "y": 2,
      "z": 4,
      "name": "Empty",
      "level": 0
    },
    {
      "x": -5,
      "y": 3,
      "z": 4,
      "name": "Empty",
      "level": 0
    },
    {
      "x": -5,
      "y": 4,
      "z": 4,
      "name": "Empty",
      "level": 0
    },
    {
      "x": -5,
      "y": 5,
      "z": 4,
      "name": "Empty",
      "level": 0
    },
    {
      "x": -5,
      "y": 6,
      "z": 4,
      "name": "Empty",
      "level": 0
    },
    {
      "x": -5,
      "y": 0,
      "z": 5,
      "name": "Empty",
      "level": 0
    },
    {
      "x": -5,
      "y": 1,
      "z": 5,
      "name": "Empty",
      "level": 0
    },
    {
      "x": -5,
      "y": 2,
      "z": 5,
      "name": "Empty",
      "level": 0
    },
    {
      "x": -5,
      "y": 3,
      "z": 5,
      "name": "Empty",
      "level": 0
    },
    {
      "x": -5,
      "y": 4,
      "z": 5,
      "name": "Empty",
      "level": 0
    },
    {
      "x": -5,
      "y": 5,
      "z": 5,
      "name": "Empty",
      "level": 0
    },
    {
      "x": -5,
      "y": 0,
      "z": 6,
      "name": "Empty",
      "level": 0
    },
    {
      "x": -5,
      "y": 4,
      "z": 6,
      "name": "Empty",
      "level": 0
    },
    {
      "x": -5,
      "y": 10,
      "z": 6,
      "name": "Empty",
      "level": 0
    },
    {
      "x": -4,
      "y": 0,
      "z": -5,
      "name": "Empty",
      "level": 0
    },
    {
      "x": -4,
      "y": 4,
      "z": -5,
      "name": "Empty",
      "level": 0
    },
    {
      "x": -4,
      "y": 0,
      "z": -4,
      "name": "Empty",
      "level": 0
    },
    {
      "x": -4,
      "y": 1,
      "z": -4,
      "name": "Empty",
      "level": 0
    },
    {
      "x": -4,
      "y": 2,
      "z": -4,
      "name": "Empty",
      "level": 0
    },
    {
      "x": -4,
      "y": 3,
      "z": -4,
      "name": "Empty",
      "level": 0
    },
    {
      "x": -4,
      "y": 4,
      "z": -4,
      "name": "Empty",
      "level": 0
    },
    {
      "x": -4,
      "y": 5,
      "z": -4,
      "name": "Empty",
      "level": 0
    },
    {
      "x": -4,
      "y": 0,
      "z": -3,
      "name": "Empty",
      "level": 0
    },
    {
      "x": -4,
      "y": 1,
      "z": -3,
      "name": "Empty",
      "level": 0
    },
    {
      "x": -4,
      "y": 2,
      "z": -3,
      "name": "Empty",
      "level": 0
    },
    {
      "x": -4,
      "y": 5,
      "z": -3,
      "name": "Empty",
      "level": 0
    },
    {
      "x": -4,
      "y": 6,
      "z": -3,
      "name": "Empty",
      "level": 0
    },
    {
      "x": -4,
      "y": 0,
      "z": -2,
      "name": "Empty",
      "level": 0
    },
    {
      "x": -4,
      "y": 1,
      "z": -2,
      "name": "Empty",
      "level": 0
    },
    {
      "x": -4,
      "y": 2,
      "z": -2,
      "name": "Empty",
      "level": 0
    },
    {
      "x": -4,
      "y": 6,
      "z": -2,
      "name": "Empty",
      "level": 0
    },
    {
      "x": -4,
      "y": 7,
      "z": -2,
      "name": "Empty",
      "level": 0
    },
    {
      "x": -4,
      "y": 0,
      "z": -1,
      "name": "Empty",
      "level": 0
    },
    {
      "x": -4,
      "y": 1,
      "z": -1,
      "name": "Empty",
      "level": 0
    },
    {
      "x": -4,
      "y": 2,
      "z": -1,
      "name": "Empty",
      "level": 0
    },
    {
      "x": -4,
      "y": 7,
      "z": -1,
      "name": "Empty",
      "level": 0
    },
    {
      "x": -4,
      "y": 8,
      "z": -1,
      "name": "Empty",
      "level": 0
    },
    {
      "x": -4,
      "y": 0,
      "z": 0,
      "name": "Empty",
      "level": 0
    },
    {
      "x": -4,
      "y": 1,
      "z": 0,
      "name": "Empty",
      "level": 0
    },
    {
      "x": -4,
      "y": 2,
      "z": 0,
      "name": "Empty",
      "level": 0
    },
    {
      "x": -4,
      "y": 3,
      "z": 0,
      "name": "Empty",
      "level": 0
    },
    {
      "x": -4,
      "y": 8,
      "z": 0,
      "name": "Empty",
      "level": 0
    },
    {
      "x": -4,
      "y": 0,
      "z": 1,
      "name": "Empty",
      "level": 0
    },
    {
      "x": -4,
      "y": 2,
      "z": 1,
      "name": "Empty",
      "level": 0
    },
    {
      "x": -4,
      "y": 3,
      "z": 1,
      "name": "Empty",
      "level": 0
    },
    {
      "x": -4,
      "y": 8,
      "z": 1,
      "name": "Empty",
      "level": 0
    },
    {
      "x": -4,
      "y": 0,
      "z": 2,
      "name": "Empty",
      "level": 0
    },
    {
      "x": -4,
      "y": 7,
      "z": 2,
      "name": "Empty",
      "level": 0
    },
    {
      "x": -4,
      "y": 8,
      "z": 2,
      "name": "Empty",
      "level": 0
    },
    {
      "x": -4,
      "y": 0,
      "z": 3,
      "name": "Empty",
      "level": 0
    },
    {
      "x": -4,
      "y": 1,
      "z": 3,
      "name": "Empty",
      "level": 0
    },
    {
      "x": -4,
      "y": 2,
      "z": 3,
      "name": "Empty",
      "level": 0
    },
    {
      "x": -4,
      "y": 3,
      "z": 3,
      "name": "Empty",
      "level": 0
    },
    {
      "x": -4,
      "y": 6,
      "z": 3,
      "name": "Empty",
      "level": 0
    },
    {
      "x": -4,
      "y": 7,
      "z": 3,
      "name": "Empty",
      "level": 0
    },
    {
      "x": -4,
      "y": 0,
      "z": 4,
      "name": "Empty",
      "level": 0
    },
    {
      "x": -4,
      "y": 1,
      "z": 4,
      "name": "Empty",
      "level": 0
    },
    {
      "x": -4,
      "y": 2,
      "z": 4,
      "name": "Empty",
      "level": 0
    },
    {
      "x": -4,
      "y": 5,
      "z": 4,
      "name": "Empty",
      "level": 0
    },
    {
      "x": -4,
      "y": 6,
      "z": 4,
      "name": "Empty",
      "level": 0
    },
    {
      "x": -4,
      "y": 0,
      "z": 5,
      "name": "Empty",
      "level": 0
    },
    {
      "x": -4,
      "y": 1,
      "z": 5,
      "name": "Empty",
      "level": 0
    },
    {
      "x": -4,
      "y": 2,
      "z": 5,
      "name": "Empty",
      "level": 0
    },
    {
      "x": -4,
      "y": 3,
      "z": 5,
      "name": "Empty",
      "level": 0
    },
    {
      "x": -4,
      "y": 4,
      "z": 5,
      "name": "Empty",
      "level": 0
    },
    {
      "x": -4,
      "y": 5,
      "z": 5,
      "name": "Empty",
      "level": 0
    },
    {
      "x": -4,
      "y": 0,
      "z": 6,
      "name": "Empty",
      "level": 0
    },
    {
      "x": -4,
      "y": 4,
      "z": 6,
      "name": "Empty",
      "level": 0
    },
    {
      "x": -3,
      "y": 0,
      "z": -5,
      "name": "Empty",
      "level": 0
    },
    {
      "x": -3,
      "y": 4,
      "z": -5,
      "name": "Empty",
      "level": 0
    },
    {
      "x": -3,
      "y": 0,
      "z": -4,
      "name": "Empty",
      "level": 0
    },
    {
      "x": -3,
      "y": 1,
      "z": -4,
      "name": "Empty",
      "level": 0
    },
    {
      "x": -3,
      "y": 2,
      "z": -4,
      "name": "Empty",
      "level": 0
    },
    {
      "x": -3,
      "y": 3,
      "z": -4,
      "name": "Empty",
      "level": 0
    },
    {
      "x": -3,
      "y": 4,
      "z": -4,
      "name": "Empty",
      "level": 0
    },
    {
      "x": -3,
      "y": 5,
      "z": -4,
      "name": "Empty",
      "level": 0
    },
    {
      "x": -3,
      "y": 0,
      "z": -3,
      "name": "Empty",
      "level": 0
    },
    {
      "x": -3,
      "y": 5,
      "z": -3,
      "name": "Empty",
      "level": 0
    },
    {
      "x": -3,
      "y": 6,
      "z": -3,
      "name": "Empty",
      "level": 0
    },
    {
      "x": -3,
      "y": 0,
      "z": -2,
      "name": "Empty",
      "level": 0
    },
    {
      "x": -3,
      "y": 1,
      "z": -2,
      "name": "Empty",
      "level": 0
    },
    {
      "x": -3,
      "y": 6,
      "z": -2,
      "name": "Empty",
      "level": 0
    },
    {
      "x": -3,
      "y": 7,
      "z": -2,
      "name": "Empty",
      "level": 0
    },
    {
      "x": -3,
      "y": 0,
      "z": -1,
      "name": "Empty",
      "level": 0
    },
    {
      "x": -3,
      "y": 1,
      "z": -1,
      "name": "Empty",
      "level": 0
    },
    {
      "x": -3,
      "y": 7,
      "z": -1,
      "name": "Empty",
      "level": 0
    },
    {
      "x": -3,
      "y": 8,
      "z": -1,
      "name": "Empty",
      "level": 0
    },
    {
      "x": -3,
      "y": 0,
      "z": 0,
      "name": "Empty",
      "level": 0
    },
    {
      "x": -3,
      "y": 8,
      "z": 0,
      "name": "Empty",
      "level": 0
    },
    {
      "x": -3,
      "y": 0,
      "z": 1,
      "name": "Empty",
      "level": 0
    },
    {
      "x": -3,
      "y": 8,
      "z": 1,
      "name": "Empty",
      "level": 0
    },
    {
      "x": -3,
      "y": 0,
      "z": 2,
      "name": "Empty",
      "level": 0
    },
    {
      "x": -3,
      "y": 7,
      "z": 2,
      "name": "Empty",
      "level": 0
    },
    {
      "x": -3,
      "y": 8,
      "z": 2,
      "name": "Empty",
      "level": 0
    },
    {
      "x": -3,
      "y": 0,
      "z": 3,
      "name": "Empty",
      "level": 0
    },
    {
      "x": -3,
      "y": 6,
      "z": 3,
      "name": "Empty",
      "level": 0
    },
    {
      "x": -3,
      "y": 7,
      "z": 3,
      "name": "Empty",
      "level": 0
    },
    {
      "x": -3,
      "y": 0,
      "z": 4,
      "name": "Empty",
      "level": 0
    },
    {
      "x": -3,
      "y": 5,
      "z": 4,
      "name": "Empty",
      "level": 0
    },
    {
      "x": -3,
      "y": 6,
      "z": 4,
      "name": "Empty",
      "level": 0
    },
    {
      "x": -3,
      "y": 0,
      "z": 5,
      "name": "Empty",
      "level": 0
    },
    {
      "x": -3,
      "y": 1,
      "z": 5,
      "name": "Empty",
      "level": 0
    },
    {
      "x": -3,
      "y": 2,
      "z": 5,
      "name": "Empty",
      "level": 0
    },
    {
      "x": -3,
      "y": 3,
      "z": 5,
      "name": "Empty",
      "level": 0
    },
    {
      "x": -3,
      "y": 4,
      "z": 5,
      "name": "Empty",
      "level": 0
    },
    {
      "x": -3,
      "y": 5,
      "z": 5,
      "name": "Empty",
      "level": 0
    },
    {
      "x": -3,
      "y": 0,
      "z": 6,
      "name": "Empty",
      "level": 0
    },
    {
      "x": -3,
      "y": 4,
      "z": 6,
      "name": "Empty",
      "level": 0
    },
    {
      "x": -2,
      "y": 0,
      "z": -5,
      "name": "Empty",
      "level": 0
    },
    {
      "x": -2,
      "y": 4,
      "z": -5,
      "name": "Empty",
      "level": 0
    },
    {
      "x": -2,
      "y": 0,
      "z": -4,
      "name": "Empty",
      "level": 0
    },
    {
      "x": -2,
      "y": 1,
      "z": -4,
      "name": "Empty",
      "level": 0
    },
    {
      "x": -2,
      "y": 2,
      "z": -4,
      "name": "Empty",
      "level": 0
    },
    {
      "x": -2,
      "y": 3,
      "z": -4,
      "name": "Empty",
      "level": 0
    },
    {
      "x": -2,
      "y": 4,
      "z": -4,
      "name": "Empty",
      "level": 0
    },
    {
      "x": -2,
      "y": 5,
      "z": -4,
      "name": "Empty",
      "level": 0
    },
    {
      "x": -2,
      "y": 0,
      "z": -3,
      "name": "Empty",
      "level": 0
    },
    {
      "x": -2,
      "y": 5,
      "z": -3,
      "name": "Empty",
      "level": 0
    },
    {
      "x": -2,
      "y": 6,
      "z": -3,
      "name": "Empty",
      "level": 0
    },
    {
      "x": -2,
      "y": 0,
      "z": -2,
      "name": "Empty",
      "level": 0
    },
    {
      "x": -2,
      "y": 6,
      "z": -2,
      "name": "Empty",
      "level": 0
    },
    {
      "x": -2,
      "y": 7,
      "z": -2,
      "name": "Empty",
      "level": 0
    },
    {
      "x": -2,
      "y": 0,
      "z": -1,
      "name": "Empty",
      "level": 0
    },
    {
      "x": -2,
      "y": 1,
      "z": -1,
      "name": "Empty",
      "level": 0
    },
    {
      "x": -2,
      "y": 7,
      "z": -1,
      "name": "Empty",
      "level": 0
    },
    {
      "x": -2,
      "y": 8,
      "z": -1,
      "name": "Empty",
      "level": 0
    },
    {
      "x": -2,
      "y": 0,
      "z": 0,
      "name": "Empty",
      "level": 0
    },
    {
      "x": -2,
      "y": 1,
      "z": 0,
      "name": "Empty",
      "level": 0
    },
    {
      "x": -2,
      "y": 2,
      "z": 0,
      "name": "Empty",
      "level": 0
    },
    {
      "x": -2,
      "y": 5,
      "z": 0,
      "name": "Empty",
      "level": 0
    },
    {
      "x": -2,
      "y": 6,
      "z": 0,
      "name": "Empty",
      "level": 0
    },
    {
      "x": -2,
      "y": 7,
      "z": 0,
      "name": "Empty",
      "level": 0
    },
    {
      "x": -2,
      "y": 8,
      "z": 0,
      "name": "Empty",
      "level": 0
    },
    {
      "x": -2,
      "y": 0,
      "z": 1,
      "name": "Empty",
      "level": 0
    },
    {
      "x": -2,
      "y": 1,
      "z": 1,
      "name": "Empty",
      "level": 0
    },
    {
      "x": -2,
      "y": 2,
      "z": 1,
      "name": "Empty",
      "level": 0
    },
    {
      "x": -2,
      "y": 8,
      "z": 1,
      "name": "Empty",
      "level": 0
    },
    {
      "x": -2,
      "y": 0,
      "z": 2,
      "name": "Empty",
      "level": 0
    },
    {
      "x": -2,
      "y": 1,
      "z": 2,
      "name": "Empty",
      "level": 0
    },
    {
      "x": -2,
      "y": 2,
      "z": 2,
      "name": "Empty",
      "level": 0
    },
    {
      "x": -2,
      "y": 7,
      "z": 2,
      "name": "Empty",
      "level": 0
    },
    {
      "x": -2,
      "y": 8,
      "z": 2,
      "name": "Empty",
      "level": 0
    },
    {
      "x": -2,
      "y": 0,
      "z": 3,
      "name": "Empty",
      "level": 0
    },
    {
      "x": -2,
      "y": 1,
      "z": 3,
      "name": "Empty",
      "level": 0
    },
    {
      "x": -2,
      "y": 2,
      "z": 3,
      "name": "Empty",
      "level": 0
    },
    {
      "x": -2,
      "y": 6,
      "z": 3,
      "name": "Empty",
      "level": 0
    },
    {
      "x": -2,
      "y": 7,
      "z": 3,
      "name": "Empty",
      "level": 0
    },
    {
      "x": -2,
      "y": 0,
      "z": 4,
      "name": "Empty",
      "level": 0
    },
    {
      "x": -2,
      "y": 1,
      "z": 4,
      "name": "Empty",
      "level": 0
    },
    {
      "x": -2,
      "y": 2,
      "z": 4,
      "name": "Empty",
      "level": 0
    },
    {
      "x": -2,
      "y": 5,
      "z": 4,
      "name": "Empty",
      "level": 0
    },
    {
      "x": -2,
      "y": 6,
      "z": 4,
      "name": "Empty",
      "level": 0
    },
    {
      "x": -2,
      "y": 0,
      "z": 5,
      "name": "Empty",
      "level": 0
    },
    {
      "x": -2,
      "y": 1,
      "z": 5,
      "name": "Empty",
      "level": 0
    },
    {
      "x": -2,
      "y": 2,
      "z": 5,
      "name": "Empty",
      "level": 0
    },
    {
      "x": -2,
      "y": 3,
      "z": 5,
      "name": "Empty",
      "level": 0
    },
    {
      "x": -2,
      "y": 4,
      "z": 5,
      "name": "Empty",
      "level": 0
    },
    {
      "x": -2,
      "y": 5,
      "z": 5,
      "name": "Empty",
      "level": 0
    },
    {
      "x": -2,
      "y": 0,
      "z": 6,
      "name": "Empty",
      "level": 0
    },
    {
      "x": -2,
      "y": 4,
      "z": 6,
      "name": "Empty",
      "level": 0
    },
    {
      "x": -1,
      "y": 0,
      "z": -5,
      "name": "Empty",
      "level": 0
    },
    {
      "x": -1,
      "y": 3,
      "z": -5,
      "name": "Empty",
      "level": 0
    },
    {
      "x": -1,
      "y": 4,
      "z": -5,
      "name": "Empty",
      "level": 0
    },
    {
      "x": -1,
      "y": 0,
      "z": -4,
      "name": "Empty",
      "level": 0
    },
    {
      "x": -1,
      "y": 1,
      "z": -4,
      "name": "Empty",
      "level": 0
    },
    {
      "x": -1,
      "y": 2,
      "z": -4,
      "name": "Empty",
      "level": 0
    },
    {
      "x": -1,
      "y": 3,
      "z": -4,
      "name": "Empty",
      "level": 0
    },
    {
      "x": -1,
      "y": 4,
      "z": -4,
      "name": "Empty",
      "level": 0
    },
    {
      "x": -1,
      "y": 5,
      "z": -4,
      "name": "Empty",
      "level": 0
    },
    {
      "x": -1,
      "y": 0,
      "z": -3,
