{
  "version": 8,
  "blockIdVersion": 11,
  "anchorX": 0,
  "anchorY": 0,
  "anchorZ": 0,
  "blocks": [
    {
      "x": -5,
      "y": 0,
      "z": -6,
      "name": "Rock_Stone_Cobble_Mossy",
      "rotation": 1
    },
    {
      "x": -5,
      "y": 4,
      "z": -6,
      "name": "Wood_Softwood_Roof_Hollow",
      "rotation": 3
    },
    {
      "x": -5,
      "y": 0,
      "z": -5,
      "name": "Rock_Stone_Cobble_Mossy",
      "rotation": 1
    },
    {
      "x": -5,
      "y": 2,
      "z": -5,
      "name": "Plant_Vine_Wall",
      "rotation": 3
    },
    {
      "x": -5,
      "y": 3,
      "z": -5,
      "name": "Wood_Beech_Trunk_Half",
      "rotation": 7
    },
    {
      "x": -5,
      "y": 4,
      "z": -5,
      "name": "Wood_Softwood_Roof_Hollow",
      "rotation": 3
    },
    {
      "x": -5,
      "y": 0,
      "z": -4,
      "name": "Rock_Stone_Cobble",
      "rotation": 1
    },
    {
      "x": -5,
      "y": 4,
      "z": -4,
      "name": "Wood_Softwood_Roof_Hollow",
      "rotation": 3
    },
    {
      "x": -5,
      "y": 0,
      "z": -3,
      "name": "Rock_Stone_Cobble",
      "rotation": 1
    },
    {
      "x": -5,
      "y": 4,
      "z": -3,
      "name": "Wood_Softwood_Roof_Hollow",
      "rotation": 3
    },
    {
      "x": -5,
      "y": 0,
      "z": -2,
      "name": "Rock_Stone_Cobble",
      "rotation": 1
    },
    {
      "x": -5,
      "y": 4,
      "z": -2,
      "name": "Wood_Softwood_Roof_Hollow",
      "rotation": 3
    },
    {
      "x": -5,
      "y": 0,
      "z": -1,
      "name": "Rock_Stone_Cobble",
      "rotation": 1
    },
    {
      "x": -5,
      "y": 4,
      "z": -1,
      "name": "Wood_Softwood_Roof_Hollow",
      "rotation": 3
    },
    {
      "x": -5,
      "y": 0,
      "z": 0,
      "name": "Rock_Stone_Cobble_Mossy",
      "rotation": 1
    },
    {
      "x": -5,
      "y": 4,
      "z": 0,
      "name": "Wood_Softwood_Roof_Hollow",
      "rotation": 3
    },
    {
      "x": -5,
      "y": 0,
      "z": 1,
      "name": "Rock_Stone_Cobble_Mossy",
      "rotation": 1
    },
    {
      "x": -5,
      "y": 3,
      "z": 1,
      "name": "Plant_Vine_Wall",
      "rotation": 3
    },
    {
      "x": -5,
      "y": 4,
      "z": 1,
      "name": "Wood_Softwood_Roof_Hollow",
      "rotation": 3
    },
    {
      "x": -5,
      "y": 0,
      "z": 2,
      "name": "Rock_Stone_Cobble",
      "rotation": 1
    },
    {
      "x": -5,
      "y": 4,
      "z": 2,
      "name": "Wood_Softwood_Roof_Hollow",
      "rotation": 3
    },
    {
      "x": -5,
      "y": 0,
      "z": 3,
      "name": "Rock_Stone_Cobble",
      "rotation": 1
    },
    {
      "x": -5,
      "y": 4,
      "z": 3,
      "name": "Wood_Softwood_Roof_Hollow",
      "rotation": 3
    },
    {
      "x": -5,
      "y": 0,
      "z": 4,
      "name": "Rock_Stone_Cobble",
      "rotation": 1
    },
    {
      "x": -5,
      "y": 4,
      "z": 4,
      "name": "Wood_Softwood_Roof_Hollow",
      "rotation": 3
    },
    {
      "x": -5,
      "y": 0,
      "z": 5,
      "name": "Rock_Stone_Cobble",
      "rotation": 1
    },
    {
      "x": -5,
      "y": 1,
      "z": 5,
      "name": "Rock_Sandstone_Red_Brick_Smooth",
      "rotation": 1
    },
    {
      "x": -5,
      "y": 3,
      "z": 5,
      "name": "Wood_Beech_Trunk_Half",
      "rotation": 7
    },
    {
      "x": -5,
      "y": 4,
      "z": 5,
      "name": "Wood_Softwood_Roof_Hollow",
      "rotation": 3
    },
    {
      "x": -5,
      "y": 0,
      "z": 6,
      "name": "Rock_Stone_Cobble",
      "rotation": 1
    },
    {
      "x": -5,
      "y": 1,
      "z": 6,
      "name": "Mixology_Crate",
      "rotation": 1
    },
    {
      "x": -5,
      "y": 2,
      "z": 6,
      "name": "Mixology_Crate",
      "rotation": 1
    },
    {
      "x": -5,
      "y": 4,
      "z": 6,
      "name": "Wood_Softwood_Roof_Hollow",
      "rotation": 3
    },
    {
      "x": -4,
      "y": 0,
      "z": -6,
      "name": "Rock_Stone_Cobble_Mossy",
      "rotation": 1
    },
    {
      "x": -4,
      "y": 4,
      "z": -6,
      "name": "Wood_Beech_Trunk",
      "rotation": 6
    },
    {
      "x": -4,
      "y": 5,
      "z": -6,
      "name": "Wood_Softwood_Roof",
      "rotation": 3
    },
    {
      "x": -4,
      "y": 0,
      "z": -5,
      "name": "Rock_Stone_Cobble",
      "rotation": 1
    },
    {
      "x": -4,
      "y": 1,
      "z": -5,
      "name": "Wood_Beech_Trunk",
      "rotation": 1
    },
    {
      "x": -4,
      "y": 2,
      "z": -5,
      "name": "Wood_Beech_Trunk",
      "rotation": 1
    },
    {
      "x": -4,
      "y": 3,
      "z": -5,
      "name": "Wood_Beech_Trunk",
      "rotation": 1
    },
    {
      "x": -4,
      "y": 4,
      "z": -5,
      "name": "Wood_Beech_Trunk",
      "rotation": 1
    },
    {
      "x": -4,
      "y": 5,
      "z": -5,
      "name": "Wood_Softwood_Roof",
      "rotation": 3
    },
    {
      "x": -4,
      "y": 0,
      "z": -4,
      "name": "Rock_Stone_Cobble",
      "rotation": 1
    },
    {
      "x": -4,
      "y": 1,
      "z": -4,
      "name": "Rock_Stone_Brick",
      "rotation": 1
    },
    {
      "x": -4,
      "y": 2,
      "z": -4,
      "name": "*Wood_Village_Wall_Full_State_Definitions_Bottom",
      "rotation": 1
    },
    {
      "x": -4,
      "y": 3,
      "z": -4,
      "name": "*Wood_Village_Wall_Full_State_Definitions_Top",
      "rotation": 1
    },
    {
      "x": -4,
      "y": 4,
      "z": -4,
      "name": "Wood_Beech_Trunk",
      "rotation": 6
    },
    {
      "x": -4,
      "y": 5,
      "z": -4,
      "name": "Wood_Softwood_Roof",
      "rotation": 3
    },
    {
      "x": -4,
      "y": 0,
      "z": -3,
      "name": "Rock_Stone_Cobble",
      "rotation": 1
    },
    {
      "x": -4,
      "y": 1,
      "z": -3,
      "name": "Rock_Stone_Brick",
      "rotation": 1
    },
    {
      "x": -4,
      "y": 2,
      "z": -3,
      "name": "Furniture_Village_Window",
      "rotation": 1
    },
    {
      "x": -4,
      "y": 3,
      "z": -3,
      "name": "Furniture_Village_Window",
      "rotation": 1
    },
    {
      "x": -4,
      "y": 4,
      "z": -3,
      "name": "Wood_Beech_Trunk",
      "rotation": 6
    },
    {
      "x": -4,
      "y": 5,
      "z": -3,
      "name": "Wood_Softwood_Roof",
      "rotation": 3
    },
    {
      "x": -4,
      "y": 0,
      "z": -2,
      "name": "Rock_Stone_Cobble",
      "rotation": 1
    },
    {
      "x": -4,
      "y": 1,
      "z": -2,
      "name": "Rock_Stone_Brick",
      "rotation": 1
    },
    {
      "x": -4,
      "y": 2,
      "z": -2,
      "name": "Furniture_Village_Window",
      "rotation": 1
    },
    {
      "x": -4,
      "y": 3,
      "z": -2,
      "name": "Furniture_Village_Window",
      "rotation": 1
    },
    {
      "x": -4,
      "y": 4,
      "z": -2,
      "name": "Wood_Beech_Trunk",
      "rotation": 6
    },
    {
      "x": -4,
      "y": 5,
      "z": -2,
      "name": "Wood_Softwood_Roof",
      "rotation": 3
    },
    {
      "x": -4,
      "y": 0,
      "z": -1,
      "name": "Rock_Stone_Cobble",
      "rotation": 1
    },
    {
      "x": -4,
      "y": 1,
      "z": -1,
      "name": "Rock_Stone_Brick",
      "rotation": 1
    },
    {
      "x": -4,
      "y": 2,
      "z": -1,
      "name": "*Wood_Village_Wall_Full_State_Definitions_Bottom",
      "rotation": 1
    },
    {
      "x": -4,
      "y": 3,
      "z": -1,
      "name": "*Wood_Village_Wall_Full_State_Definitions_Top",
      "rotation": 1
    },
    {
      "x": -4,
      "y": 4,
      "z": -1,
      "name": "Wood_Beech_Trunk",
      "rotation": 6
    },
    {
      "x": -4,
      "y": 5,
      "z": -1,
      "name": "Wood_Softwood_Roof",
      "rotation": 3
    },
    {
      "x": -4,
      "y": 0,
      "z": 0,
      "name": "Rock_Stone_Cobble",
      "rotation": 1
    },
    {
      "x": -4,
      "y": 1,
      "z": 0,
      "name": "Wood_Beech_Trunk",
      "rotation": 1
    },
    {
      "x": -4,
      "y": 2,
      "z": 0,
      "name": "Wood_Beech_Trunk",
      "rotation": 1
    },
    {
      "x": -4,
      "y": 3,
      "z": 0,
      "name": "Wood_Beech_Trunk",
      "rotation": 1
    },
    {
      "x": -4,
      "y": 4,
      "z": 0,
      "name": "Wood_Beech_Trunk",
      "rotation": 1
    },
    {
      "x": -4,
      "y": 5,
      "z": 0,
      "name": "Wood_Softwood_Roof",
      "rotation": 3
    },
    {
      "x": -4,
      "y": 0,
      "z": 1,
      "name": "Rock_Stone_Cobble",
      "rotation": 1
    },
    {
      "x": -4,
      "y": 1,
      "z": 1,
      "name": "Rock_Stone_Brick",
      "rotation": 1
    },
    {
      "x": -4,
      "y": 2,
      "z": 1,
      "name": "*Wood_Village_Wall_Full_State_Definitions_Bottom",
      "rotation": 1
    },
    {
      "x": -4,
      "y": 3,
      "z": 1,
      "name": "*Wood_Village_Wall_Full_State_Definitions_Top",
      "rotation": 1
    },
    {
      "x": -4,
      "y": 4,
      "z": 1,
      "name": "Wood_Beech_Trunk",
      "rotation": 6
    },
    {
      "x": -4,
      "y": 5,
      "z": 1,
      "name": "Wood_Softwood_Roof",
      "rotation": 3
    },
    {
      "x": -4,
      "y": 0,
      "z": 2,
      "name": "Rock_Stone_Cobble",
      "rotation": 1
    },
    {
      "x": -4,
      "y": 1,
      "z": 2,
      "name": "Rock_Stone_Brick",
      "rotation": 1
    },
    {
      "x": -4,
      "y": 2,
      "z": 2,
      "name": "Furniture_Village_Window",
      "rotation": 1
    },
    {
      "x": -4,
      "y": 3,
      "z": 2,
      "name": "Furniture_Village_Window",
      "rotation": 1
    },
    {
      "x": -4,
      "y": 4,
      "z": 2,
      "name": "Wood_Beech_Trunk",
      "rotation": 6
    },
    {
      "x": -4,
      "y": 5,
      "z": 2,
      "name": "Wood_Softwood_Roof",
      "rotation": 3
    },
    {
      "x": -4,
      "y": 0,
      "z": 3,
      "name": "Rock_Stone_Cobble",
      "rotation": 1
    },
    {
      "x": -4,
      "y": 1,
      "z": 3,
      "name": "Rock_Stone_Brick",
      "rotation": 1
    },
    {
      "x": -4,
      "y": 2,
      "z": 3,
      "name": "Furniture_Village_Window",
      "rotation": 1
    },
    {
      "x": -4,
      "y": 3,
      "z": 3,
      "name": "Furniture_Village_Window",
      "rotation": 1
    },
    {
      "x": -4,
      "y": 4,
      "z": 3,
      "name": "Wood_Beech_Trunk",
      "rotation": 6
    },
    {
      "x": -4,
      "y": 5,
      "z": 3,
      "name": "Wood_Softwood_Roof",
      "rotation": 3
    },
    {
      "x": -4,
      "y": 0,
      "z": 4,
      "name": "Rock_Stone_Cobble",
      "rotation": 1
    },
    {
      "x": -4,
      "y": 1,
      "z": 4,
      "name": "Rock_Stone_Brick",
      "rotation": 1
    },
    {
      "x": -4,
      "y": 2,
      "z": 4,
      "name": "*Wood_Village_Wall_Full_State_Definitions_Bottom",
      "rotation": 1
    },
    {
      "x": -4,
      "y": 3,
      "z": 4,
      "name": "*Wood_Village_Wall_Full_State_Definitions_Top",
      "rotation": 1
    },
    {
      "x": -4,
      "y": 4,
      "z": 4,
      "name": "Wood_Beech_Trunk",
      "rotation": 6
    },
    {
      "x": -4,
      "y": 5,
      "z": 4,
      "name": "Wood_Softwood_Roof",
      "rotation": 3
    },
    {
      "x": -4,
      "y": 0,
      "z": 5,
      "name": "Rock_Stone_Cobble",
      "rotation": 1
    },
    {
      "x": -4,
      "y": 1,
      "z": 5,
      "name": "Wood_Beech_Trunk",
      "rotation": 1
    },
    {
      "x": -4,
      "y": 2,
      "z": 5,
      "name": "Wood_Beech_Trunk",
      "rotation": 1
    },
    {
      "x": -4,
      "y": 3,
      "z": 5,
      "name": "Wood_Beech_Trunk",
      "rotation": 1
    },
    {
      "x": -4,
      "y": 4,
      "z": 5,
      "name": "Wood_Beech_Trunk",
      "rotation": 1
    },
    {
      "x": -4,
      "y": 5,
      "z": 5,
      "name": "Wood_Softwood_Roof",
      "rotation": 3
    },
    {
      "x": -4,
      "y": 0,
      "z": 6,
      "name": "Rock_Stone_Cobble",
      "rotation": 1
    },
    {
      "x": -4,
      "y": 1,
      "z": 6,
      "name": "Mixology_Crate",
      "rotation": 1
    },
    {
      "x": -4,
      "y": 4,
      "z": 6,
      "name": "Wood_Beech_Trunk",
      "rotation": 6
    },
    {
      "x": -4,
      "y": 5,
      "z": 6,
      "name": "Wood_Softwood_Roof",
      "rotation": 3
    },
    {
      "x": -3,
      "y": 0,
      "z": -6,
      "name": "Rock_Stone_Cobble",
      "rotation": 1
    },
    {
      "x": -3,
      "y": 4,
      "z": -6,
      "name": "Plant_Vine_Wall",
      "rotation": 2
    },
    {
      "x": -3,
      "y": 5,
      "z": -6,
      "name": "Wood_Softwood_Stairs",
      "rotation": 11
    },
    {
      "x": -3,
      "y": 6,
      "z": -6,
      "name": "Wood_Softwood_Roof",
      "rotation": 3
    },
    {
      "x": -3,
      "y": 0,
      "z": -5,
      "name": "Rock_Stone_Cobble",
      "rotation": 1
    },
    {
      "x": -3,
      "y": 1,
      "z": -5,
      "name": "Rock_Stone_Brick",
      "rotation": 1
    },
    {
      "x": -3,
      "y": 2,
      "z": -5,
      "name": "*Wood_Village_Wall_Full_State_Definitions_Bottom",
      "rotation": 1
    },
    {
      "x": -3,
      "y": 3,
      "z": -5,
      "name": "*Wood_Village_Wall_Full_State_Definitions_Top",
      "rotation": 1
    },
    {
      "x": -3,
      "y": 4,
      "z": -5,
      "name": "Wood_Beech_Trunk",
      "rotation": 5
    },
    {
      "x": -3,
      "y": 5,
      "z": -5,
      "name": "Wood_Village_Wall_Full",
      "rotation": 1
    },
    {
      "x": -3,
      "y": 6,
      "z": -5,
      "name": "Wood_Softwood_Roof",
      "rotation": 3
    },
    {
      "x": -3,
      "y": 0,
      "z": -4,
      "name": "Wood_Hardwood_Decorative",
      "rotation": 1
    },
    {
      "x": -3,
      "y": 5,
      "z": -4,
      "name": "Wood_Hardwood_Stairs",
      "rotation": 11
    },
    {
      "x": -3,
      "y": 6,
      "z": -4,
      "name": "Wood_Softwood_Roof",
      "rotation": 3
    },
    {
      "x": -3,
      "y": 0,
      "z": -3,
      "name": "Wood_Hardwood_Decorative",
      "rotation": 1
    },
    {
      "x": -3,
      "y": 1,
      "z": -3,
      "name": "Furniture_Village_Stool",
      "components": {
        "Components": {}
      }
    },
    {
      "x": -3,
      "y": 5,
      "z": -3,
      "name": "Wood_Softwood_Stairs",
      "rotation": 11
    },
    {
      "x": -3,
      "y": 6,
      "z": -3,
      "name": "Wood_Softwood_Roof",
      "rotation": 3
    },
    {
      "x": -3,
      "y": 0,
      "z": -2,
      "name": "Wood_Hardwood_Decorative",
      "rotation": 1
    },
    {
      "x": -3,
      "y": 1,
      "z": -2,
      "name": "Furniture_Village_Table",
      "filler": 992,
      "rotation": 1
    },
    {
      "x": -3,
      "y": 5,
      "z": -2,
      "name": "Wood_Softwood_Stairs",
      "rotation": 11
    },
    {
      "x": -3,
      "y": 6,
      "z": -2,
      "name": "Wood_Softwood_Roof",
      "rotation": 3
    },
    {
      "x": -3,
      "y": 0,
      "z": -1,
      "name": "Wood_Hardwood_Decorative",
      "rotation": 1
    },
    {
      "x": -3,
      "y": 1,
      "z": -1,
      "name": "Furniture_Village_Table",
      "rotation": 1
    },
    {
      "x": -3,
      "y": 2,
      "z": -1,
      "name": "Apple_Martini",
      "rotation": 1
    },
    {
      "x": -3,
      "y": 5,
      "z": -1,
      "name": "Wood_Softwood_Stairs",
      "rotation": 11
    },
    {
      "x": -3,
      "y": 6,
      "z": -1,
      "name": "Wood_Softwood_Roof",
      "rotation": 3
    },
    {
      "x": -3,
      "y": 0,
      "z": 0,
      "name": "Wood_Hardwood_Decorative",
      "rotation": 1
    },
    {
      "x": -3,
      "y": 1,
      "z": 0,
      "name": "Furniture_Village_Stool",
      "rotation": 2
    },
    {
      "x": -3,
      "y": 5,
      "z": 0,
      "name": "Wood_Softwood_Stairs",
      "rotation": 11
    },
    {
      "x": -3,
      "y": 6,
      "z": 0,
      "name": "Wood_Softwood_Roof",
      "rotation": 3
    },
    {
      "x": -3,
      "y": 0,
      "z": 1,
      "name": "Wood_Hardwood_Decorative",
      "rotation": 1
    },
    {
      "x": -3,
      "y": 5,
      "z": 1,
      "name": "Wood_Softwood_Stairs",
      "rotation": 11
    },
    {
      "x": -3,
      "y": 6,
      "z": 1,
      "name": "Wood_Softwood_Roof",
      "rotation": 3
    },
    {
      "x": -3,
      "y": 0,
      "z": 2,
      "name": "Wood_Hardwood_Decorative",
      "rotation": 1
    },
    {
      "x": -3,
      "y": 5,
      "z": 2,
      "name": "Wood_Softwood_Stairs",
      "rotation": 11
    },
    {
      "x": -3,
      "y": 6,
      "z": 2,
      "name": "Wood_Softwood_Roof",
      "rotation": 3
    },
    {
      "x": -3,
      "y": 0,
      "z": 3,
      "name": "Wood_Hardwood_Decorative",
      "rotation": 1
    },
    {
      "x": -3,
      "y": 5,
      "z": 3,
      "name": "Wood_Softwood_Stairs",
      "rotation": 11
    },
    {
      "x": -3,
      "y": 6,
      "z": 3,
      "name": "Wood_Softwood_Roof",
      "rotation": 3
    },
    {
      "x": -3,
      "y": 0,
      "z": 4,
      "name": "Wood_Hardwood_Planks",
      "rotation": 1
    },
    {
      "x": -3,
      "y": 1,
      "z": 4,
      "name": "Furniture_Tavern_Wardrobe",
      "rotation": 2
    },
    {
      "x": -3,
      "y": 2,
      "z": 4,
      "name": "Furniture_Tavern_Wardrobe",
      "filler": 1024,
      "rotation": 2
    },
    {
      "x": -3,
      "y": 5,
      "z": 4,
      "name": "Wood_Softwood_Stairs",
      "rotation": 11
    },
    {
      "x": -3,
      "y": 6,
      "z": 4,
      "name": "Wood_Softwood_Roof",
      "rotation": 3
    },
    {
      "x": -3,
      "y": 0,
      "z": 5,
      "name": "Rock_Stone_Cobble",
      "rotation": 1
    },
    {
      "x": -3,
      "y": 1,
      "z": 5,
      "name": "Rock_Stone_Brick",
      "rotation": 1
    },
    {
      "x": -3,
      "y": 2,
      "z": 5,
      "name": "Rock_Stone_Brick",
      "rotation": 1
    },
    {
      "x": -3,
      "y": 3,
      "z": 5,
      "name": "Wood_Hardwood_Ornate",
      "rotation": 1
    },
    {
      "x": -3,
      "y": 4,
      "z": 5,
      "name": "Wood_Beech_Trunk",
      "rotation": 5
    },
    {
      "x": -3,
      "y": 5,
      "z": 5,
      "name": "Wood_Village_Wall_Full",
      "rotation": 1
    },
    {
      "x": -3,
      "y": 6,
      "z": 5,
      "name": "Wood_Softwood_Roof",
      "rotation": 3
    },
    {
      "x": -3,
      "y": 0,
      "z": 6,
      "name": "Rock_Stone_Cobble",
      "rotation": 1
    },
    {
      "x": -3,
      "y": 4,
      "z": 6,
      "name": "Plant_Vine_Wall"
    },
    {
      "x": -3,
      "y": 5,
      "z": 6,
      "name": "Wood_Softwood_Stairs",
      "rotation": 11
    },
    {
      "x": -3,
      "y": 6,
      "z": 6,
      "name": "Wood_Softwood_Roof",
      "rotation": 3
    },
    {
      "x": -2,
      "y": 0,
      "z": -6,
      "name": "Rock_Stone_Cobble",
      "rotation": 1
    },
    {
      "x": -2,
      "y": 6,
      "z": -6,
      "name": "Wood_Softwood_Stairs",
      "rotation": 11
    },
    {
      "x": -2,
      "y": 7,
      "z": -6,
      "name": "Wood_Softwood_Roof",
      "rotation": 3
    },
    {
      "x": -2,
      "y": 0,
      "z": -5,
      "name": "Rock_Stone_Cobble",
      "rotation": 1
    },
    {
      "x": -2,
      "y": 1,
      "z": -5,
      "name": "Rock_Stone_Brick",
      "rotation": 1
    },
    {
      "x": -2,
      "y": 2,
      "z": -5,
      "name": "Furniture_Village_Window",
      "rotation": 2
    },
    {
      "x": -2,
      "y": 3,
      "z": -5,
      "name": "Furniture_Village_Window",
      "rotation": 2
    },
    {
      "x": -2,
      "y": 4,
      "z": -5,
      "name": "Wood_Beech_Trunk",
      "rotation": 5
    },
    {
      "x": -2,
      "y": 5,
      "z": -5,
      "name": "*Wood_Village_Wall_Full_State_Definitions_Bottom",
      "rotation": 1
    },
    {
      "x": -2,
      "y": 6,
      "z": -5,
      "name": "*Wood_Village_Wall_Full_State_Definitions_Top",
      "rotation": 1
    },
    {
      "x": -2,
      "y": 7,
      "z": -5,
      "name": "Wood_Softwood_Roof",
      "rotation": 3
    },
    {
      "x": -2,
      "y": 0,
      "z": -4,
      "name": "Wood_Hardwood_Decorative",
      "rotation": 1
    },
    {
      "x": -2,
      "y": 6,
      "z": -4,
      "name": "Wood_Hardwood_Stairs",
      "rotation": 11
    },
    {
      "x": -2,
      "y": 7,
      "z": -4,
      "name": "Wood_Softwood_Roof",
      "rotation": 3
    },
    {
      "x": -2,
      "y": 0,
      "z": -3,
      "name": "Wood_Hardwood_Decorative",
      "rotation": 1
    },
    {
      "x": -2,
      "y": 1,
      "z": -3,
      "name": "Furniture_Village_Stool"
    },
    {
      "x": -2,
      "y": 6,
      "z": -3,
      "name": "Wood_Hardwood_Stairs",
      "rotation": 11
    },
    {
      "x": -2,
      "y": 7,
      "z": -3,
      "name": "Wood_Softwood_Roof",
      "rotation": 3
    },
    {
      "x": -2,
      "y": 0,
      "z": -2,
      "name": "Wood_Hardwood_Decorative",
      "rotation": 1
    },
    {
      "x": -2,
      "y": 1,
      "z": -2,
      "name": "Furniture_Village_Table",
      "filler": 993,
      "rotation": 1
    },
    {
      "x": -2,
      "y": 2,
      "z": -2,
      "name": "Deco_Mug",
      "rotation": 1
    },
    {
      "x": -2,
      "y": 6,
      "z": -2,
      "name": "Wood_Hardwood_Stairs",
      "rotation": 11
    },
    {
      "x": -2,
      "y": 7,
      "z": -2,
      "name": "Wood_Softwood_Roof",
      "rotation": 3
    },
    {
      "x": -2,
      "y": 0,
      "z": -1,
      "name": "Wood_Hardwood_Decorative",
      "rotation": 1
    },
    {
      "x": -2,
      "y": 1,
      "z": -1,
      "name": "Furniture_Village_Table",
      "filler": 1,
      "rotation": 1
    },
    {
      "x": -2,
      "y": 6,
      "z": -1,
      "name": "Wood_Hardwood_Stairs",
      "rotation": 11
    },
    {
      "x": -2,
      "y": 7,
      "z": -1,
      "name": "Wood_Softwood_Roof",
      "rotation": 3
    },
    {
      "x": -2,
      "y": 0,
      "z": 0,
      "name": "Wood_Hardwood_Decorative",
      "rotation": 1
    },
    {
      "x": -2,
      "y": 1,
      "z": 0,
      "name": "Furniture_Village_Stool",
      "rotation": 2
    },
    {
      "x": -2,
      "y": 6,
      "z": 0,
      "name": "Wood_Hardwood_Stairs",
      "rotation": 11
    },
    {
      "x": -2,
      "y": 7,
      "z": 0,
      "name": "Wood_Softwood_Roof",
      "rotation": 3
    },
    {
      "x": -2,
      "y": 0,
      "z": 1,
      "name": "Wood_Hardwood_Decorative",
      "rotation": 1
    },
    {
      "x": -2,
      "y": 6,
      "z": 1,
      "name": "Wood_Hardwood_Stairs",
      "rotation": 11
    },
    {
      "x": -2,
      "y": 7,
      "z": 1,
      "name": "Wood_Softwood_Roof",
      "rotation": 3
    },
    {
      "x": -2,
      "y": 0,
      "z": 2,
      "name": "Wood_Hardwood_Decorative",
      "rotation": 1
    },
    {
      "x": -2,
      "y": 6,
      "z": 2,
      "name": "Wood_Hardwood_Stairs",
      "rotation": 11
    },
    {
      "x": -2,
      "y": 7,
      "z": 2,
      "name": "Wood_Softwood_Roof",
      "rotation": 3
    },
    {
      "x": -2,
      "y": 0,
      "z": 3,
      "name": "Wood_Hardwood_Decorative",
      "rotation": 1
    },
    {
      "x": -2,
      "y": 1,
      "z": 3,
      "name": "*Wood_Hardwood_Fence_Gate_State_Definitions_OpenDoorIn",
      "filler": 31,
      "rotation": 3
    },
    {
      "x": -2,
      "y": 6,
      "z": 3,
      "name": "Wood_Hardwood_Stairs",
      "rotation": 11
    },
    {
      "x": -2,
      "y": 7,
      "z": 3,
      "name": "Wood_Softwood_Roof",
      "rotation": 3
    },
    {
      "x": -2,
      "y": 0,
      "z": 4,
      "name": "Wood_Hardwood_Planks",
      "rotation": 1
    },
    {
      "x": -2,
      "y": 1,
      "z": 4,
      "name": "Furniture_Tavern_Wardrobe",
      "filler": 1,
      "rotation": 2
    },
    {
      "x": -2,
      "y": 2,
      "z": 4,
      "name": "Furniture_Tavern_Wardrobe",
      "filler": 1025,
      "rotation": 2
    },
    {
      "x": -2,
      "y": 6,
      "z": 4,
      "name": "Wood_Hardwood_Stairs",
      "rotation": 11
    },
    {
      "x": -2,
      "y": 7,
      "z": 4,
      "name": "Wood_Softwood_Roof",
      "rotation": 3
    },
    {
      "x": -2,
      "y": 0,
      "z": 5,
      "name": "Rock_Stone_Cobble",
      "rotation": 1
    },
    {
      "x": -2,
      "y": 1,
      "z": 5,
      "name": "Rock_Stone_Brick",
      "rotation": 1
    },
    {
      "x": -2,
      "y": 2,
      "z": 5,
      "name": "Rock_Stone_Brick",
      "rotation": 1
    },
    {
      "x": -2,
      "y": 3,
      "z": 5,
      "name": "Furniture_Village_Window",
      "rotation": 2
    },
    {
      "x": -2,
      "y": 4,
      "z": 5,
      "name": "Wood_Beech_Trunk",
      "rotation": 5
    },
    {
      "x": -2,
      "y": 5,
      "z": 5,
      "name": "*Wood_Village_Wall_Full_State_Definitions_Bottom",
      "rotation": 1
    },
    {
      "x": -2,
      "y": 6,
      "z": 5,
      "name": "*Wood_Village_Wall_Full_State_Definitions_Top",
      "rotation": 1
    },
    {
      "x": -2,
      "y": 7,
      "z": 5,
      "name": "Wood_Softwood_Roof",
      "rotation": 3
    },
    {
      "x": -2,
      "y": 0,
      "z": 6,
      "name": "Rock_Stone_Cobble",
      "rotation": 1
    },
    {
      "x": -2,
      "y": 6,
      "z": 6,
      "name": "Wood_Softwood_Stairs",
      "rotation": 11
    },
    {
      "x": -2,
      "y": 7,
      "z": 6,
      "name": "Wood_Softwood_Roof",
      "rotation": 3
    },
    {
      "x": -1,
      "y": 0,
      "z": -6,
      "name": "Rock_Stone_Cobble",
      "rotation": 1
    },
    {
      "x": -1,
      "y": 2,
      "z": -6,
      "name": "Wood_Torch_Wall",
      "rotation": 2
    },
    {
      "x": -1,
      "y": 4,
      "z": -6,
      "name": "Wood_Beech_Trunk_Half",
      "rotation": 6
    },
    {
      "x": -1,
      "y": 7,
      "z": -6,
      "name": "Wood_Softwood_Stairs",
      "rotation": 11
    },
    {
      "x": -1,
      "y": 8,
      "z": -6,
      "name": "Wood_Softwood_Roof_Shallow",
      "rotation": 3
    },
    {
      "x": -1,
      "y": 0,
      "z": -5,
      "name": "Rock_Stone_Cobble",
      "rotation": 1
    },
    {
      "x": -1,
      "y": 1,
      "z": -5,
      "name": "Wood_Beech_Trunk",
      "rotation": 1
    },
    {
      "x": -1,
      "y": 2,
      "z": -5,
      "name": "Wood_Beech_Trunk",
      "rotation": 1
    },
    {
      "x": -1,
      "y": 3,
      "z": -5,
      "name": "Wood_Beech_Trunk",
      "rotation": 1
    },
    {
      "x": -1,
      "y": 4,
      "z": -5,
      "name": "Wood_Beech_Trunk",
      "rotation": 1
    },
    {
      "x": -1,
      "y": 5,
      "z": -5,
      "name": "Wood_Beech_Trunk",
      "rotation": 1
    },
    {
      "x": -1,
      "y": 6,
      "z": -5,
      "name": "Wood_Beech_Trunk",
      "rotation": 1
    },
    {
      "x": -1,
      "y": 7,
      "z": -5,
      "name": "Wood_Beech_Trunk",
      "rotation": 1
    },
    {
      "x": -1,
      "y": 8,
      "z": -5,
      "name": "Wood_Softwood_Roof_Shallow",
      "rotation": 3
    },
    {
      "x": -1,
      "y": 0,
      "z": -4,
      "name": "Wood_Hardwood_Decorative",
      "rotation": 1
    },
    {
      "x": -1,
      "y": 7,
      "z": -4,
      "name": "Wood_Softwood_Stairs",
      "rotation": 11
    },
    {
      "x": -1,
      "y": 8,
      "z": -4,
      "name": "Wood_Softwood_Roof_Shallow",
      "rotation": 3
    },
    {
      "x": -1,
      "y": 0,
      "z": -3,
      "name": "Wood_Hardwood_Decorative",
      "rotation": 1
    },
    {
      "x": -1,
      "y": 7,
      "z": -3,
      "name": "Wood_Softwood_Stairs",
      "rotation": 11
    },
    {
      "x": -1,
      "y": 8,
      "z": -3,
      "name": "Wood_Softwood_Roof_Shallow",
      "rotation": 3
    },
    {
      "x": -1,
      "y": 0,
      "z": -2,
      "name": "Wood_Hardwood_Decorative",
      "rotation": 1
    },
    {
      "x": -1,
      "y": 7,
      "z": -2,
      "name": "Wood_Softwood_Stairs",
      "rotation": 11
    },
    {
      "x": -1,
      "y": 8,
      "z": -2,
      "name": "Wood_Softwood_Roof_Shallow",
      "rotation": 3
    },
    {
      "x": -1,
      "y": 0,
      "z": -1,
      "name": "Wood_Hardwood_Decorative",
      "rotation": 1
    },
    {
      "x": -1,
      "y": 7,
      "z": -1,
      "name": "Wood_Softwood_Stairs",
      "rotation": 11
    },
    {
      "x": -1,
      "y": 8,
      "z": -1,
      "name": "Wood_Softwood_Roof_Shallow",
      "rotation": 3
    },
    {
      "x": -1,
      "y": 0,
      "z": 0,
      "name": "Wood_Hardwood_Decorative",
      "rotation": 1
    },
    {
      "x": -1,
      "y": 7,
      "z": 0,
      "name": "Wood_Hardwood_Stairs",
      "rotation": 11
    },
    {
      "x": -1,
      "y": 8,
      "z": 0,
      "name": "Wood_Softwood_Roof_Shallow",
      "rotation": 3
    },
    {
      "x": -1,
      "y": 0,
      "z": 1,
      "name": "Wood_Hardwood_Decorative",
      "rotation": 1
    },
    {
      "x": -1,
      "y": 7,
      "z": 1,
      "name": "Wood_Hardwood_Stairs",
      "rotation": 11
    },
    {
      "x": -1,
      "y": 8,
      "z": 1,
      "name": "Wood_Softwood_Roof_Shallow",
      "rotation": 3
    },
    {
      "x": -1,
      "y": 0,
      "z": 2,
      "name": "Wood_Hardwood_Decorative",
      "rotation": 1
    },
    {
      "x": -1,
      "y": 1,
      "z": 2,
      "name": "Wood_Hardwood_Ornate",
      "rotation": 1
    },
    {
      "x": -1,
      "y": 7,
      "z": 2,
      "name": "Wood_Hardwood_Stairs",
      "rotation": 11
    },
    {
      "x": -1,
      "y": 8,
      "z": 2,
      "name": "Wood_Softwood_Roof_Shallow",
      "rotation": 3
    },
    {
      "x": -1,
      "y": 0,
      "z": 3,
      "name": "Wood_Hardwood_Decorative",
      "rotation": 1
    },
    {
      "x": -1,
      "y": 1,
      "z": 3,
      "name": "*Wood_Hardwood_Fence_Gate_State_Definitions_OpenDoorIn",
      "rotation": 3
    },
    {
      "x": -1,
      "y": 7,
      "z": 3,
      "name": "Wood_Hardwood_Stairs",
      "rotation": 11
    },
    {
      "x": -1,
      "y": 8,
      "z": 3,
      "name": "Wood_Softwood_Roof_Shallow",
      "rotation": 3
    },
    {
      "x": -1,
      "y": 0,
      "z": 4,
      "name": "Wood_Hardwood_Planks",
      "rotation": 1
    },
    {
      "x": -1,
      "y": 1,
      "z": 4,
      "name": "Wood_Hardwood_Planks",
      "rotation": 1
    },
    {
      "x": -1,
      "y": 2,
      "z": 4,
      "name": "Apple_Martini",
      "rotation": 1
    },
    {
      "x": -1,
      "y": 7,
      "z": 4,
      "name": "Wood_Hardwood_Stairs",
      "rotation": 11
    },
    {
      "x": -1,
      "y": 8,
      "z": 4,
      "name": "Wood_Softwood_Roof_Shallow",
      "rotation": 3
    },
    {
      "x": -1,
      "y": 0,
      "z": 5,
      "name": "Rock_Stone_Cobble",
      "rotation": 1
    },
    {
      "x": -1,
      "y": 1,
      "z": 5,
      "name": "Wood_Beech_Trunk",
      "rotation": 1
    },
    {
      "x": -1,
      "y": 2,
      "z": 5,
      "name": "Wood_Beech_Trunk",
      "rotation": 1
    },
    {
      "x": -1,
      "y": 3,
      "z": 5,
      "name": "Wood_Beech_Trunk",
      "rotation": 1
    },
    {
      "x": -1,
      "y": 4,
      "z": 5,
      "name": "Wood_Beech_Trunk",
      "rotation": 1
    },
    {
      "x": -1,
      "y": 5,
      "z": 5,
      "name": "Wood_Beech_Trunk",
      "rotation": 1
    },
    {
      "x": -1,
      "y": 6,
      "z": 5,
      "name": "Wood_Beech_Trunk",
      "rotation": 1
    },
    {
      "x": -1,
      "y": 7,
      "z": 5,
      "name": "Wood_Beech_Trunk",
      "rotation": 1
    },
    {
      "x": -1,
      "y": 8,
      "z": 5,
      "name": "Wood_Softwood_Roof_Shallow",
      "rotation": 3
    },
    {
      "x": -1,
      "y": 0,
      "z": 6,
      "name": "Rock_Stone_Cobble",
      "rotation": 1
    },
    {
      "x": -1,
      "y": 4,
      "z": 6,
      "name": "Wood_Beech_Trunk_Half",
      "rotation": 4
    },
    {
      "x": -1,
      "y": 7,
      "z": 6,
      "name": "Wood_Softwood_Stairs",
      "rotation": 11
    },
    {
      "x": -1,
      "y": 8,
      "z": 6,
      "name": "Wood_Softwood_Roof_Shallow",
      "rotation": 3
    },
    {
      "x": 0,
      "y": 0,
      "z": -6,
      "name": "Rock_Stone_Cobble",
      "rotation": 1
    },
    {
      "x": 0,
      "y": 7,
      "z": -6,
      "name": "Wood_Softwood_Planks_Half",
      "rotation": 9
    },
    {
      "x": 0,
      "y": 8,
      "z": -6,
      "name": "Wood_Softwood_Roof_Shallow",
      "filler": 1,
      "rotation": 3
    },
    {
      "x": 0,
      "y": 0,
      "z": -5,
      "name": "Rock_Stone_Cobble",
      "rotation": 1
    },
    {
      "x": 0,
      "y": 1,
      "z": -5,
      "name": "*Furniture_Village_Door_State_Definitions_OpenDoorIn"
    },
    {
      "x": 0,
      "y": 2,
      "z": -5,
      "name": "*Furniture_Village_Door_State_Definitions_OpenDoorIn",
      "filler": 1024
    },
    {
      "x": 0,
      "y": 3,
      "z": -5,
      "name": "Wood_Hardwood_Ornate",
      "rotation": 1
    },
    {
      "x": 0,
      "y": 4,
      "z": -5,
      "name": "Wood_Beech_Trunk",
      "rotation": 5
    },
    {
      "x": 0,
      "y": 5,
      "z": -5,
      "name": "Furniture_Village_Window",
      "rotation": 2
    },
    {
      "x": 0,
      "y": 6,
      "z": -5,
      "name": "Furniture_Village_Window",
      "rotation": 2
    },
    {
      "x": 0,
      "y": 7,
      "z": -5,
      "name": "Wood_Village_Wall_Full",
      "rotation": 1
    },
    {
      "x": 0,
      "y": 8,
      "z": -5,
      "name": "Wood_Softwood_Roof_Shallow",
      "filler": 1,
      "rotation": 3
    },
    {
      "x": 0,
      "y": 0,
      "z": -4,
      "name": "Wood_Hardwood_Decorative",
      "rotation": 1
    },
    {
      "x": 0,
      "y": 1,
      "z": -4,
      "name": "*Furniture_Village_Door_State_Definitions_OpenDoorIn",
      "filler": 32
    },
    {
      "x": 0,
      "y": 2,
      "z": -4,
      "name": "*Furniture_Village_Door_State_Definitions_OpenDoorIn",
      "filler": 1056
    },
    {
      "x": 0,
      "y": 8,
      "z": -4,
      "name": "Wood_Softwood_Roof_Shallow",
      "filler": 1,
      "rotation": 3
    },
    {
      "x": 0,
      "y": 0,
      "z": -3,
      "name": "Wood_Hardwood_Decorative",
      "rotation": 1
    },
    {
      "x": 0,
      "y": 8,
      "z": -3,
      "name": "Wood_Softwood_Roof_Shallow",
      "filler": 1,
      "rotation": 3
    },
    {
      "x": 0,
      "y": 0,
      "z": -2,
      "name": "Wood_Hardwood_Decorative",
      "rotation": 1
    },
    {
      "x": 0,
      "y": 4,
      "z": -2,
      "name": "Deco_Lantern_Ceiling",
      "rotation": 1
    },
    {
      "x": 0,
      "y": 5,
      "z": -2,
      "name": "Deco_Rope",
      "rotation": 1
    },
    {
      "x": 0,
      "y": 6,
      "z": -2,
      "name": "Deco_Rope",
      "rotation": 1
    },
    {
      "x": 0,
      "y": 7,
      "z": -2,
      "name": "Deco_Rope",
      "rotation": 1
    },
    {
      "x": 0,
      "y": 8,
      "z": -2,
      "name": "Wood_Softwood_Roof_Shallow",
      "filler": 1,
      "rotation": 3
    },
    {
      "x": 0,
      "y": 0,
      "z": -1,
      "name": "Wood_Hardwood_Decorative",
      "rotation": 1
    },
    {
      "x": 0,
      "y": 8,
      "z": -1,
      "name": "Wood_Softwood_Roof_Shallow",
      "filler": 1,
      "rotation": 3
    },
    {
      "x": 0,
      "y": 0,
      "z": 0,
      "name": "Wood_Hardwood_Decorative",
      "rotation": 1
    },
    {
      "x": 0,
      "y": 8,
      "z": 0,
      "name": "Wood_Softwood_Roof_Shallow",
      "filler": 1,
      "rotation": 3
    },
    {
      "x": 0,
      "y": 0,
      "z": 1,
      "name": "Wood_Hardwood_Decorative",
      "rotation": 1
    },
    {
      "x": 0,
      "y": 8,
      "z": 1,
      "name": "Wood_Softwood_Roof_Shallow",
      "filler": 1,
      "rotation": 3
    },
    {
      "x": 0,
      "y": 0,
      "z": 2,
      "name": "Wood_Hardwood_Decorative",
      "rotation": 1
    },
    {
      "x": 0,
      "y": 1,
      "z": 2,
      "name": "Bench_Mixology_Bar",
      "filler": 31
    },
    {
      "x": 0,
      "y": 2,
      "z": 2,
      "name": "Bench_Mixology_Bar",
      "filler": 1055
    },
    {
      "x": 0,
      "y": 5,
      "z": 2,
      "name": "Deco_Lantern_Ceiling",
      "rotation": 1
    },
    {
      "x": 0,
      "y": 6,
      "z": 2,
      "name": "Deco_Rope",
      "rotation": 1
    },
    {
      "x": 0,
      "y": 7,
      "z": 2,
      "name": "Deco_Rope",
      "rotation": 1
    },
    {
      "x": 0,
      "y": 8,
      "z": 2,
      "name": "Wood_Softwood_Roof_Shallow",
      "filler": 1,
      "rotation": 3
    },
    {
      "x": 0,
      "y": 0,
      "z": 3,
      "name": "Wood_Hardwood_Decorative",
      "rotation": 1
    },
    {
      "x": 0,
      "y": 8,
      "z": 3,
      "name": "Wood_Softwood_Roof_Shallow",
      "filler": 1,
      "rotation": 3
    },
    {
      "x": 0,
      "y": 0,
      "z": 4,
      "name": "Wood_Hardwood_Planks",
      "rotation": 1
    },
    {
      "x": 0,
      "y": 1,
      "z": 4,
      "name": "Furniture_Village_Shelf_Full",
      "rotation": 2
    },
    {
      "x": 0,
      "y": 2,
      "z": 4,
      "name": "Furniture_Lumberjack_Shelf",
      "rotation": 2
    },
    {
      "x": 0,
      "y": 3,
      "z": 4,
      "name": "Berry_Punch",
      "rotation": 1
    },
    {
      "x": 0,
      "y": 8,
      "z": 4,
      "name": "Wood_Softwood_Roof_Shallow",
      "filler": 1,
      "rotation": 3
    },
    {
      "x": 0,
      "y": 0,
      "z": 5,
      "name": "Rock_Stone_Cobble",
      "rotation": 1
    },
    {
      "x": 0,
      "y": 1,
      "z": 5,
      "name": "Rock_Stone_Brick",
      "rotation": 1
    },
    {
      "x": 0,
      "y": 2,
      "z": 5,
      "name": "Rock_Stone_Brick",
      "rotation": 1
    },
    {
      "x": 0,
      "y": 3,
      "z": 5,
      "name": "Wood_Hardwood_Ornate",
      "rotation": 1
    },
    {
      "x": 0,
      "y": 4,
      "z": 5,
      "name": "Wood_Beech_Trunk",
      "rotation": 5
    },
    {
      "x": 0,
      "y": 5,
      "z": 5,
      "name": "Furniture_Village_Window",
      "rotation": 2
    },
    {
      "x": 0,
      "y": 6,
      "z": 5,
      "name": "Furniture_Village_Window",
      "rotation": 2
    },
    {
      "x": 0,
      "y": 7,
      "z": 5,
      "name": "Wood_Village_Wall_Full",
      "rotation": 1
    },
    {
      "x": 0,
      "y": 8,
      "z": 5,
      "name": "Wood_Softwood_Roof_Shallow",
      "filler": 1,
      "rotation": 3
    },
    {
      "x": 0,
      "y": 0,
      "z": 6,
      "name": "Rock_Stone_Cobble_Mossy",
      "rotation": 1
    },
    {
      "x": 0,
      "y": 7,
      "z": 6,
      "name": "Wood_Softwood_Planks_Half",
      "rotation": 9
    },
    {
      "x": 0,
      "y": 8,
      "z": 6,
      "name": "Wood_Softwood_Roof_Shallow",
      "filler": 1,
      "rotation": 3
    },
    {
      "x": 1,
      "y": 0,
      "z": -6,
      "name": "Rock_Stone_Cobble",
      "rotation": 1
    },
    {
      "x": 1,
      "y": 7,
      "z": -6,
      "name": "Wood_Softwood_Planks_Half",
      "rotation": 9
    },
    {
      "x": 1,
      "y": 8,
      "z": -6,
      "name": "Wood_Softwood_Roof_Shallow",
      "filler": 31,
      "rotation": 1
    },
    {
      "x": 1,
      "y": 0,
      "z": -5,
      "name": "Rock_Stone_Cobble",
      "rotation": 1
    },
    {
      "x": 1,
      "y": 1,
      "z": -5,
      "name": "*Furniture_Village_Door_State_Definitions_OpenDoorOut",
      "rotation": 2
    },
    {
      "x": 1,
      "y": 2,
      "z": -5,
      "name": "*Furniture_Village_Door_State_Definitions_OpenDoorOut",
      "filler": 1024,
      "rotation": 2
    },
    {
      "x": 1,
      "y": 3,
      "z": -5,
      "name": "Wood_Hardwood_Ornate",
      "rotation": 1
    },
    {
      "x": 1,
      "y": 4,
      "z": -5,
      "name": "Wood_Beech_Trunk",
      "rotation": 5
    },
    {
      "x": 1,
      "y": 5,
      "z": -5,
      "name": "Furniture_Village_Window",
      "rotation": 2
    },
    {
      "x": 1,
      "y": 6,
      "z": -5,
      "name": "Furniture_Village_Window",
      "rotation": 2
    },
    {
      "x": 1,
      "y": 7,
      "z": -5,
      "name": "Wood_Village_Wall_Full",
      "rotation": 1
    },
    {
      "x": 1,
      "y": 8,
      "z": -5,
      "name": "Wood_Softwood_Roof_Shallow",
      "filler": 31,
      "rotation": 1
    },
    {
      "x": 1,
      "y": 0,
      "z": -4,
      "name": "Wood_Hardwood_Decorative",
      "rotation": 1
    },
    {
      "x": 1,
      "y": 1,
      "z": -4,
      "name": "*Furniture_Village_Door_State_Definitions_OpenDoorOut",
      "filler": 32,
      "rotation": 2
    },
    {
      "x": 1,
      "y": 2,
      "z": -4,
      "name": "*Furniture_Village_Door_State_Definitions_OpenDoorOut",
      "filler": 1056,
      "rotation": 2
    },
    {
      "x": 1,
      "y": 8,
      "z": -4,
      "name": "Wood_Softwood_Roof_Shallow",
      "filler": 31,
      "rotation": 1
    },
    {
      "x": 1,
      "y": 0,
      "z": -3,
      "name": "Wood_Hardwood_Decorative",
      "rotation": 1
    },
    {
      "x": 1,
      "y": 8,
      "z": -3,
      "name": "Wood_Softwood_Roof_Shallow",
      "filler": 31,
      "rotation": 1
    },
    {
      "x": 1,
      "y": 0,
      "z": -2,
      "name": "Wood_Hardwood_Decorative",
      "rotation": 1
    },
    {
      "x": 1,
      "y": 8,
      "z": -2,
      "name": "Wood_Softwood_Roof_Shallow",
      "filler": 31,
      "rotation": 1
    },
    {
      "x": 1,
      "y": 0,
      "z": -1,
      "name": "Wood_Hardwood_Decorative",
      "rotation": 1
    },
    {
      "x": 1,
      "y": 8,
      "z": -1,
      "name": "Wood_Softwood_Roof_Shallow",
      "filler": 31,
      "rotation": 1
    },
    {
      "x": 1,
      "y": 0,
      "z": 0,
      "name": "Wood_Hardwood_Decorative",
      "rotation": 1
    },
    {
      "x": 1,
      "y": 5,
      "z": 0,
      "name": "Deco_Lantern_Ceiling",
      "rotation": 1
    },
    {
      "x": 1,
      "y": 6,
      "z": 0,
      "name": "Deco_Rope",
      "rotation": 1
    },
    {
      "x": 1,
      "y": 7,
      "z": 0,
      "name": "Deco_Rope",
      "rotation": 1
    },
    {
      "x": 1,
      "y": 8,
      "z": 0,
      "name": "Wood_Softwood_Roof_Shallow",
      "filler": 31,
      "rotation": 1
    },
    {
      "x": 1,
      "y": 0,
      "z": 1,
      "name": "Wood_Hardwood_Decorative",
      "rotation": 1
    },
    {
      "x": 1,
      "y": 8,
      "z": 1,
      "name": "Wood_Softwood_Roof_Shallow",
      "filler": 31,
      "rotation": 1
    },
    {
      "x": 1,
      "y": 0,
      "z": 2,
      "name": "Wood_Hardwood_Decorative",
      "rotation": 1
    },
    {
      "x": 1,
      "y": 1,
      "z": 2,
      "name": "Bench_Mixology_Bar",
      "components": {
        "Components": {
          "BenchBlock": {
            "TierLevel": 1,
            "UpgradeItems": []
          }
        }
      }
    },
    {
      "x": 1,
      "y": 2,
      "z": 2,
      "name": "Bench_Mixology_Bar",
      "filler": 1024
    },
    {
      "x": 1,
      "y": 8,
      "z": 2,
      "name": "Wood_Softwood_Roof_Shallow",
      "filler": 31,
      "rotation": 1
    },
    {
      "x": 1,
      "y": 0,
      "z": 3,
      "name": "Wood_Hardwood_Decorative",
      "rotation": 1
    },
    {
      "x": 1,
      "y": 8,
      "z": 3,
      "name": "Wood_Softwood_Roof_Shallow",
      "filler": 31,
      "rotation": 1
    },
    {
      "x": 1,
      "y": 0,
      "z": 4,
      "name": "Wood_Hardwood_Planks",
      "rotation": 1
    },
    {
      "x": 1,
      "y": 2,
      "z": 4,
      "name": "Furniture_Lumberjack_Shelf",
      "rotation": 2
    },
    {
      "x": 1,
      "y": 3,
      "z": 4,
      "name": "Corn_Cooler",
      "rotation": 1
    },
    {
      "x": 1,
      "y": 8,
      "z": 4,
      "name": "Wood_Softwood_Roof_Shallow",
      "filler": 31,
      "rotation": 1
    },
    {
      "x": 1,
      "y": 0,
      "z": 5,
      "name": "Rock_Stone_Cobble",
      "rotation": 1
    },
    {
      "x": 1,
      "y": 1,
      "z": 5,
      "name": "Rock_Stone_Brick",
      "rotation": 1
    },
    {
      "x": 1,
      "y": 2,
      "z": 5,
      "name": "Rock_Stone_Brick",
      "rotation": 1
    },
    {
      "x": 1,
      "y": 3,
      "z": 5,
      "name": "Wood_Hardwood_Ornate",
      "rotation": 1
    },
    {
      "x": 1,
      "y": 4,
      "z": 5,
      "name": "Wood_Beech_Trunk",
      "rotation": 5
    },
    {
      "x": 1,
      "y": 5,
      "z": 5,
      "name": "Furniture_Village_Window",
      "rotation": 2
    },
    {
      "x": 1,
      "y": 6,
      "z": 5,
      "name": "Furniture_Village_Window",
      "rotation": 2
    },
    {
      "x": 1,
      "y": 7,
      "z": 5,
      "name": "Wood_Village_Wall_Full",
      "rotation": 1
    },
    {
      "x": 1,
      "y": 8,
      "z": 5,
      "name": "Wood_Softwood_Roof_Shallow",
      "filler": 31,
      "rotation": 1
    },
    {
      "x": 1,
      "y": 0,
      "z": 6,
      "name": "Rock_Stone_Cobble_Mossy",
      "rotation": 1
    },
    {
      "x": 1,
      "y": 7,
      "z": 6,
      "name": "Wood_Softwood_Planks_Half",
      "rotation": 9
    },
    {
      "x": 1,
      "y": 8,
      "z": 6,
      "name": "Wood_Softwood_Roof_Shallow",
      "filler": 31,
      "rotation": 1
    },
    {
      "x": 2,
      "y": 0,
      "z": -6,
      "name": "Rock_Stone_Cobble",
      "rotation": 1
    },
    {
      "x": 2,
      "y": 2,
      "z": -6,
      "name": "Wood_Torch_Wall",
      "rotation": 2
    },
    {
      "x": 2,
      "y": 4,
      "z": -6,
      "name": "Wood_Beech_Trunk_Half",
      "rotation": 6
    },
    {
      "x": 2,
      "y": 7,
      "z": -6,
      "name": "Wood_Softwood_Stairs",
      "rotation": 9
    },
    {
      "x": 2,
      "y": 8,
      "z": -6,
      "name": "Wood_Softwood_Roof_Shallow",
      "rotation": 1
    },
    {
      "x": 2,
      "y": 0,
      "z": -5,
      "name": "Rock_Stone_Cobble",
      "rotation": 1
    },
    {
      "x": 2,
      "y": 1,
      "z": -5,
      "name": "Wood_Beech_Trunk",
      "rotation": 1
    },
    {
      "x": 2,
      "y": 2,
      "z": -5,
      "name": "Wood_Beech_Trunk",
      "rotation": 1
    },
    {
      "x": 2,
      "y": 3,
      "z": -5,
      "name": "Wood_Beech_Trunk",
      "rotation": 1
    },
    {
      "x": 2,
      "y": 4,
      "z": -5,
      "name": "Wood_Beech_Trunk",
      "rotation": 1
    },
    {
      "x": 2,
      "y": 5,
      "z": -5,
      "name": "Wood_Beech_Trunk",
      "rotation": 1
    },
    {
      "x": 2,
      "y": 6,
      "z": -5,
      "name": "Wood_Beech_Trunk",
      "rotation": 1
    },
    {
      "x": 2,
      "y": 7,
      "z": -5,
      "name": "Wood_Beech_Trunk",
      "rotation": 1
    },
    {
      "x": 2,
      "y": 8,
      "z": -5,
      "name": "Wood_Softwood_Roof_Shallow",
      "rotation": 1
    },
    {
      "x": 2,
      "y": 0,
      "z": -4,
      "name": "Wood_Hardwood_Decorative",
      "rotation": 1
    },
    {
      "x": 2,
      "y": 7,
      "z": -4,
      "name": "Wood_Softwood_Stairs",
      "rotation": 9
    },
    {
      "x": 2,
      "y": 8,
      "z": -4,
      "name": "Wood_Softwood_Roof_Shallow",
      "rotation": 1
    },
    {
      "x": 2,
      "y": 0,
      "z": -3,
      "name": "Wood_Hardwood_Decorative",
      "rotation": 1
    },
    {
      "x": 2,
      "y": 7,
      "z": -3,
      "name": "Wood_Softwood_Stairs",
      "rotation": 9
    },
    {
      "x": 2,
      "y": 8,
      "z": -3,
      "name": "Wood_Softwood_Roof_Shallow",
      "rotation": 1
    },
    {
      "x": 2,
      "y": 0,
      "z": -2,
      "name": "Wood_Hardwood_Decorative",
      "rotation": 1
    },
    {
      "x": 2,
      "y": 1,
      "z": -2,
      "name": "Furniture_Village_Shelf_Full",
      "rotation": 3
    },
    {
      "x": 2,
      "y": 7,
      "z": -2,
      "name": "Wood_Softwood_Stairs",
      "rotation": 9
    },
    {
      "x": 2,
      "y": 8,
      "z": -2,
      "name": "Wood_Softwood_Roof_Shallow",
      "rotation": 1
    },
    {
      "x": 2,
      "y": 0,
      "z": -1,
      "name": "Wood_Hardwood_Decorative",
      "rotation": 1
    },
    {
      "x": 2,
      "y": 7,
      "z": -1,
      "name": "Wood_Softwood_Stairs",
      "rotation": 9
    },
    {
      "x": 2,
      "y": 8,
      "z": -1,
      "name": "Wood_Softwood_Roof_Shallow",
      "rotation": 1
    },
    {
      "x": 2,
      "y": 0,
      "z": 0,
      "name": "Wood_Hardwood_Decorative",
      "rotation": 1
    },
    {
      "x": 2,
      "y": 7,
      "z": 0,
      "name": "Wood_Softwood_Stairs",
      "rotation": 9
    },
    {
      "x": 2,
      "y": 8,
      "z": 0,
      "name": "Wood_Softwood_Roof_Shallow",
      "rotation": 1
    },
    {
      "x": 2,
      "y": 0,
      "z": 1,
      "name": "Wood_Hardwood_Decorative",
      "rotation": 1
    },
    {
      "x": 2,
      "y": 7,
      "z": 1,
      "name": "Wood_Softwood_Stairs",
      "rotation": 9
    },
    {
      "x": 2,
      "y": 8,
      "z": 1,
      "name": "Wood_Softwood_Roof_Shallow",
      "rotation": 1
    },
    {
      "x": 2,
      "y": 0,
      "z": 2,
      "name": "Wood_Hardwood_Decorative",
      "rotation": 1
    },
    {
      "x": 2,
      "y": 1,
      "z": 2,
      "name": "Wood_Hardwood_Ornate",
      "rotation": 1
    },
    {
      "x": 2,
      "y": 2,
      "z": 2,
      "name": "Aetherhaven_Shop_Spot",
      "components": {
        "Components": {
          "AetherhavenShopSpotBlock": {
            "SpotId": "5558e95d-dfe3-45cd-b56a-2231ce97ea1f",
            "TownId": "cfd57632-98c0-4631-a474-e7db2e4777fb",
            "PlotId": "3b154a9e-71f8-4dc1-8ddb-28de3c6c6173",
            "PlayerControlled": false,
            "LootTableId": "mixologist_drinks",
            "Configured": true
          },
          "PlacedByInteraction": {
            "WhoPlacedUuid": {
              "$binary": "7RgS5j+2Q7iGDrSXx3YJoA==",
              "$type": "04"
            }
          }
        }
      },
      "rotation": 2
    },
    {
      "x": 2,
      "y": 7,
      "z": 2,
      "name": "Wood_Softwood_Stairs",
      "rotation": 9
    },
    {
      "x": 2,
      "y": 8,
      "z": 2,
      "name": "Wood_Softwood_Roof_Shallow",
      "rotation": 1
    },
    {
      "x": 2,
      "y": 0,
      "z": 3,
      "name": "Wood_Hardwood_Decorative",
      "rotation": 1
    },
    {
      "x": 2,
      "y": 7,
      "z": 3,
      "name": "Wood_Softwood_Stairs",
      "rotation": 9
    },
    {
      "x": 2,
      "y": 8,
      "z": 3,
      "name": "Wood_Softwood_Roof_Shallow",
      "rotation": 1
    },
    {
      "x": 2,
      "y": 0,
      "z": 4,
      "name": "Wood_Hardwood_Planks",
      "rotation": 1
    },
    {
      "x": 2,
      "y": 7,
      "z": 4,
      "name": "Wood_Softwood_Stairs",
      "rotation": 9
    },
    {
      "x": 2,
      "y": 8,
      "z": 4,
      "name": "Wood_Softwood_Roof_Shallow",
      "rotation": 1
    },
    {
      "x": 2,
      "y": 0,
      "z": 5,
      "name": "Rock_Stone_Cobble",
      "rotation": 1
    },
    {
      "x": 2,
      "y": 1,
      "z": 5,
      "name": "Wood_Beech_Trunk",
      "rotation": 1
    },
    {
      "x": 2,
      "y": 2,
      "z": 5,
      "name": "Wood_Beech_Trunk",
      "rotation": 1
    },
    {
      "x": 2,
      "y": 3,
      "z": 5,
      "name": "Wood_Beech_Trunk",
      "rotation": 1
    },
    {
      "x": 2,
      "y": 4,
      "z": 5,
      "name": "Wood_Beech_Trunk",
      "rotation": 1
    },
    {
      "x": 2,
      "y": 5,
      "z": 5,
      "name": "Wood_Beech_Trunk",
      "rotation": 1
    },
    {
      "x": 2,
      "y": 6,
      "z": 5,
      "name": "Wood_Beech_Trunk",
      "rotation": 1
    },
    {
      "x": 2,
      "y": 7,
      "z": 5,
      "name": "Wood_Beech_Trunk",
      "rotation": 1
    },
    {
      "x": 2,
      "y": 8,
      "z": 5,
      "name": "Wood_Softwood_Roof_Shallow",
      "rotation": 1
    },
    {
      "x": 2,
      "y": 0,
      "z": 6,
      "name": "Rock_Stone_Cobble",
      "rotation": 1
    },
    {
      "x": 2,
      "y": 4,
      "z": 6,
      "name": "Wood_Beech_Trunk_Half",
      "rotation": 4
    },
    {
      "x": 2,
      "y": 7,
      "z": 6,
      "name": "Wood_Softwood_Stairs",
      "rotation": 9
    },
    {
      "x": 2,
      "y": 8,
      "z": 6,
      "name": "Wood_Softwood_Roof_Shallow",
      "rotation": 1
    },
    {
      "x": 3,
      "y": 0,
      "z": -6,
      "name": "Rock_Stone_Cobble",
      "rotation": 1
    },
    {
      "x": 3,
      "y": 5,
      "z": -6,
      "name": "Plant_Vine_Wall",
      "rotation": 2
    },
    {
      "x": 3,
      "y": 6,
      "z": -6,
      "name": "Wood_Softwood_Stairs",
      "rotation": 9
    },
    {
      "x": 3,
      "y": 7,
      "z": -6,
      "name": "Wood_Softwood_Roof",
      "rotation": 1
    },
    {
      "x": 3,
      "y": 0,
      "z": -5,
      "name": "Rock_Stone_Cobble",
      "rotation": 1
    },
    {
      "x": 3,
      "y": 1,
      "z": -5,
      "name": "Rock_Stone_Brick",
      "rotation": 1
    },
    {
      "x": 3,
      "y": 2,
      "z": -5,
      "name": "Furniture_Village_Window",
      "rotation": 2
    },
    {
      "x": 3,
      "y": 3,
      "z": -5,
      "name": "Furniture_Village_Window",
      "rotation": 2
    },
    {
      "x": 3,
      "y": 4,
      "z": -5,
      "name": "Wood_Beech_Trunk",
      "rotation": 5
    },
    {
      "x": 3,
      "y": 5,
      "z": -5,
      "name": "*Wood_Village_Wall_Full_State_Definitions_Bottom",
      "rotation": 1
    },
    {
      "x": 3,
      "y": 6,
      "z": -5,
      "name": "*Wood_Village_Wall_Full_State_Definitions_Top",
      "rotation": 1
    },
    {
      "x": 3,
      "y": 7,
      "z": -5,
      "name": "Wood_Softwood_Roof",
      "rotation": 1
    },
    {
      "x": 3,
      "y": 0,
      "z": -4,
      "name": "Wood_Hardwood_Decorative",
      "rotation": 1
    },
    {
      "x": 3,
      "y": 6,
      "z": -4,
      "name": "Wood_Softwood_Stairs",
      "rotation": 9
    },
    {
      "x": 3,
      "y": 7,
      "z": -4,
      "name": "Wood_Softwood_Roof",
      "rotation": 1
    },
    {
      "x": 3,
      "y": 0,
      "z": -3,
      "name": "Wood_Hardwood_Decorative",
      "rotation": 1
    },
    {
      "x": 3,
      "y": 1,
      "z": -3,
      "name": "Furniture_Village_Chair",
      "components": {
        "Components": {}
      }
    },
    {
      "x": 3,
      "y": 2,
      "z": -3,
      "name": "Furniture_Village_Chair",
      "filler": 1024
    },
    {
      "x": 3,
      "y": 6,
      "z": -3,
      "name": "Wood_Softwood_Stairs",
      "rotation": 9
    },
    {
      "x": 3,
      "y": 7,
      "z": -3,
      "name": "Wood_Softwood_Roof",
      "rotation": 1
    },
    {
      "x": 3,
      "y": 0,
      "z": -2,
      "name": "Wood_Hardwood_Decorative",
      "rotation": 1
    },
    {
      "x": 3,
      "y": 1,
      "z": -2,
      "name": "Furniture_Village_Platform",
      "rotation": 1
    },
    {
      "x": 3,
      "y": 6,
      "z": -2,
      "name": "Wood_Softwood_Stairs",
      "rotation": 9
    },
    {
      "x": 3,
      "y": 7,
      "z": -2,
      "name": "Wood_Softwood_Roof",
      "rotation": 1
    },
    {
      "x": 3,
      "y": 0,
      "z": -1,
      "name": "Wood_Hardwood_Decorative",
      "rotation": 1
    },
    {
      "x": 3,
      "y": 1,
      "z": -1,
      "name": "Furniture_Village_Chair",
      "rotation": 2
    },
    {
      "x": 3,
      "y": 2,
      "z": -1,
      "name": "Furniture_Village_Chair",
      "filler": 1024,
      "rotation": 2
    },
    {
      "x": 3,
      "y": 6,
      "z": -1,
      "name": "Wood_Softwood_Stairs",
      "rotation": 9
    },
    {
      "x": 3,
      "y": 7,
      "z": -1,
      "name": "Wood_Softwood_Roof",
      "rotation": 1
    },
    {
      "x": 3,
      "y": 0,
      "z": 0,
      "name": "Wood_Hardwood_Decorative",
      "rotation": 1
    },
    {
      "x": 3,
      "y": 6,
      "z": 0,
      "name": "Wood_Softwood_Stairs",
      "rotation": 9
    },
    {
      "x": 3,
      "y": 7,
      "z": 0,
      "name": "Wood_Softwood_Roof",
      "rotation": 1
    },
    {
      "x": 3,
      "y": 0,
      "z": 1,
      "name": "Wood_Hardwood_Decorative",
      "rotation": 1
    },
    {
      "x": 3,
      "y": 6,
      "z": 1,
      "name": "Wood_Softwood_Stairs",
      "rotation": 9
    },
    {
      "x": 3,
      "y": 7,
      "z": 1,
      "name": "Wood_Softwood_Roof",
      "rotation": 1
    },
    {
      "x": 3,
      "y": 0,
      "z": 2,
      "name": "Wood_Hardwood_Decorative",
      "rotation": 1
    },
    {
      "x": 3,
      "y": 1,
      "z": 2,
      "name": "Wood_Hardwood_Ornate",
      "rotation": 1
    },
    {
      "x": 3,
      "y": 2,
      "z": 2,
      "name": "Aetherhaven_Shop_Spot",
      "components": {
        "Components": {
          "AetherhavenShopSpotBlock": {
            "SpotId": "d3b3b711-66c5-4720-8887-647c826343f5",
            "TownId": "cfd57632-98c0-4631-a474-e7db2e4777fb",
            "PlotId": "3b154a9e-71f8-4dc1-8ddb-28de3c6c6173",
            "PlayerControlled": false,
            "LootTableId": "mixologist_drinks",
            "Configured": true
          },
          "PlacedByInteraction": {
            "WhoPlacedUuid": {
              "$binary": "7RgS5j+2Q7iGDrSXx3YJoA==",
              "$type": "04"
            }
          }
        }
      },
      "rotation": 2
    },
    {
      "x": 3,
      "y": 6,
      "z": 2,
      "name": "Wood_Softwood_Stairs",
      "rotation": 9
    },
    {
      "x": 3,
      "y": 7,
      "z": 2,
      "name": "Wood_Softwood_Roof",
      "rotation": 1
    },
    {
      "x": 3,
      "y": 0,
      "z": 3,
      "name": "Wood_Hardwood_Decorative",
      "rotation": 1
    },
    {
      "x": 3,
      "y": 6,
      "z": 3,
      "name": "Wood_Softwood_Stairs",
      "rotation": 9
    },
    {
      "x": 3,
      "y": 7,
      "z": 3,
      "name": "Wood_Softwood_Roof",
      "rotation": 1
    },
    {
      "x": 3,
      "y": 0,
      "z": 4,
      "name": "Wood_Hardwood_Planks",
      "rotation": 1
    },
    {
      "x": 3,
      "y": 1,
      "z": 4,
      "name": "Aetherhaven_Management_Block",
      "components": {
        "Components": {
          "AetherhavenManagementBlock": {
            "PlotId": "3b154a9e-71f8-4dc1-8ddb-28de3c6c6173",
            "TownId": "cfd57632-98c0-4631-a474-e7db2e4777fb"
          }
        }
      },
      "rotation": 2
    },
    {
      "x": 3,
      "y": 2,
      "z": 4,
      "name": "Furniture_Lumberjack_Shelf",
      "rotation": 2
    },
    {
      "x": 3,
      "y": 3,
      "z": 4,
      "name": "Autumn_Sip",
      "rotation": 1
    },
    {
      "x": 3,
      "y": 6,
      "z": 4,
      "name": "Wood_Softwood_Stairs",
      "rotation": 9
    },
    {
      "x": 3,
      "y": 7,
      "z": 4,
      "name": "Wood_Softwood_Roof",
      "rotation": 1
    },
    {
      "x": 3,
      "y": 0,
      "z": 5,
      "name": "Rock_Stone_Cobble",
      "rotation": 1
    },
    {
      "x": 3,
      "y": 1,
      "z": 5,
      "name": "Rock_Stone_Brick",
      "rotation": 1
    },
    {
      "x": 3,
      "y": 2,
      "z": 5,
      "name": "Rock_Stone_Brick",
      "rotation": 1
    },
    {
      "x": 3,
      "y": 3,
      "z": 5,
      "name": "Furniture_Village_Window",
      "rotation": 2
    },
    {
      "x": 3,
      "y": 4,
      "z": 5,
      "name": "Wood_Beech_Trunk",
      "rotation": 5
    },
    {
      "x": 3,
      "y": 5,
      "z": 5,
      "name": "*Wood_Village_Wall_Full_State_Definitions_Bottom",
      "rotation": 1
    },
    {
      "x": 3,
      "y": 6,
      "z": 5,
      "name": "*Wood_Village_Wall_Full_State_Definitions_Top",
      "rotation": 1
    },
    {
      "x": 3,
      "y": 7,
      "z": 5,
      "name": "Wood_Softwood_Roof",
      "rotation": 1
    },
    {
      "x": 3,
      "y": 0,
      "z": 6,
      "name": "Rock_Stone_Cobble",
      "rotation": 1
    },
    {
      "x": 3,
      "y": 5,
      "z": 6,
      "name": "Plant_Vine_Wall"
    },
    {
      "x": 3,
      "y": 6,
      "z": 6,
      "name": "Wood_Softwood_Stairs",
      "rotation": 9
    },
    {
      "x": 3,
      "y": 7,
      "z": 6,
      "name": "Wood_Softwood_Roof",
      "rotation": 1
    },
    {
      "x": 4,
      "y": 0,
      "z": -6,
      "name": "Rock_Stone_Cobble_Mossy",
      "rotation": 1
    },
    {
      "x": 4,
      "y": 5,
      "z": -6,
      "name": "Wood_Softwood_Stairs",
      "rotation": 9
    },
    {
      "x": 4,
      "y": 6,
      "z": -6,
      "name": "Wood_Softwood_Roof",
      "rotation": 1
    },
    {
      "x": 4,
      "y": 0,
      "z": -5,
      "name": "Rock_Stone_Cobble",
      "rotation": 1
    },
    {
      "x": 4,
      "y": 1,
      "z": -5,
      "name": "Rock_Stone_Brick",
      "rotation": 1
    },
    {
      "x": 4,
      "y": 2,
      "z": -5,
      "name": "*Wood_Village_Wall_Full_State_Definitions_Bottom",
      "rotation": 1
    },
    {
      "x": 4,
      "y": 3,
      "z": -5,
      "name": "*Wood_Village_Wall_Full_State_Definitions_Top",
      "rotation": 1
    },
    {
      "x": 4,
      "y": 4,
      "z": -5,
      "name": "Wood_Beech_Trunk",
      "rotation": 5
    },
    {
      "x": 4,
      "y": 5,
      "z": -5,
      "name": "Wood_Village_Wall_Full",
      "rotation": 1
    },
    {
      "x": 4,
      "y": 6,
      "z": -5,
      "name": "Wood_Softwood_Roof",
      "rotation": 1
    },
    {
      "x": 4,
      "y": 0,
      "z": -4,
      "name": "Wood_Hardwood_Decorative",
      "rotation": 1
    },
    {
      "x": 4,
      "y": 5,
      "z": -4,
      "name": "Wood_Softwood_Stairs",
      "rotation": 9
    },
    {
      "x": 4,
      "y": 6,
      "z": -4,
      "name": "Wood_Softwood_Roof",
      "rotation": 1
    },
    {
      "x": 4,
      "y": 0,
      "z": -3,
      "name": "Wood_Hardwood_Decorative",
      "rotation": 1
    },
    {
      "x": 4,
      "y": 1,
      "z": -3,
      "name": "Furniture_Village_Chair"
    },
    {
      "x": 4,
      "y": 2,
      "z": -3,
      "name": "Furniture_Village_Chair",
      "filler": 1024
    },
    {
      "x": 4,
      "y": 5,
      "z": -3,
      "name": "Wood_Softwood_Stairs",
      "rotation": 9
    },
    {
      "x": 4,
      "y": 6,
      "z": -3,
      "name": "Wood_Softwood_Roof",
      "rotation": 1
    },
    {
      "x": 4,
      "y": 0,
      "z": -2,
      "name": "Wood_Hardwood_Decorative",
      "rotation": 1
    },
    {
      "x": 4,
      "y": 1,
      "z": -2,
      "name": "Furniture_Village_Platform",
      "rotation": 1
    },
    {
      "x": 4,
      "y": 2,
      "z": -2,
      "name": "Autumn_Sip",
      "rotation": 1
    },
    {
      "x": 4,
      "y": 5,
      "z": -2,
      "name": "Wood_Softwood_Stairs",
      "rotation": 9
    },
    {
      "x": 4,
      "y": 6,
      "z": -2,
      "name": "Wood_Softwood_Roof",
      "rotation": 1
    },
    {
      "x": 4,
      "y": 0,
      "z": -1,
      "name": "Wood_Hardwood_Decorative",
      "rotation": 1
    },
    {
      "x": 4,
      "y": 1,
      "z": -1,
      "name": "Furniture_Village_Chair",
      "rotation": 2
    },
    {
      "x": 4,
      "y": 2,
      "z": -1,
      "name": "Furniture_Village_Chair",
      "filler": 1024,
      "rotation": 2
    },
    {
      "x": 4,
      "y": 5,
      "z": -1,
      "name": "Wood_Softwood_Stairs",
      "rotation": 9
    },
    {
      "x": 4,
      "y": 6,
      "z": -1,
      "name": "Wood_Softwood_Roof",
      "rotation": 1
    },
    {
      "x": 4,
      "y": 0,
      "z": 0,
      "name": "Wood_Hardwood_Decorative",
      "rotation": 1
    },
    {
      "x": 4,
      "y": 5,
      "z": 0,
      "name": "Wood_Softwood_Stairs",
      "rotation": 9
    },
    {
      "x": 4,
      "y": 6,
      "z": 0,
      "name": "Wood_Softwood_Roof",
      "rotation": 1
    },
    {
      "x": 4,
      "y": 0,
      "z": 1,
      "name": "Wood_Hardwood_Decorative",
      "rotation": 1
    },
    {
      "x": 4,
      "y": 5,
      "z": 1,
      "name": "Wood_Softwood_Stairs",
      "rotation": 9
    },
    {
      "x": 4,
      "y": 6,
      "z": 1,
      "name": "Wood_Softwood_Roof",
      "rotation": 1
    },
    {
      "x": 4,
      "y": 0,
      "z": 2,
      "name": "Wood_Hardwood_Decorative",
      "rotation": 1
    },
    {
      "x": 4,
      "y": 1,
      "z": 2,
      "name": "Wood_Hardwood_Ornate",
      "rotation": 1
    },
    {
      "x": 4,
      "y": 2,
      "z": 2,
      "name": "Aetherhaven_Shop_Spot",
      "components": {
        "Components": {
          "AetherhavenShopSpotBlock": {
            "SpotId": "e4c3322a-3cd9-421c-bd2d-bbaba5a7c396",
            "TownId": "cfd57632-98c0-4631-a474-e7db2e4777fb",
            "PlotId": "3b154a9e-71f8-4dc1-8ddb-28de3c6c6173",
            "PlayerControlled": false,
            "LootTableId": "mixologist_drinks",
            "Configured": true
          },
          "PlacedByInteraction": {
            "WhoPlacedUuid": {
              "$binary": "7RgS5j+2Q7iGDrSXx3YJoA==",
              "$type": "04"
            }
          }
        }
      },
      "rotation": 2
    },
    {
      "x": 4,
      "y": 5,
      "z": 2,
      "name": "Wood_Softwood_Stairs",
      "rotation": 9
    },
    {
      "x": 4,
      "y": 6,
      "z": 2,
      "name": "Wood_Softwood_Roof",
      "rotation": 1
    },
    {
      "x": 4,
      "y": 0,
      "z": 3,
      "name": "Wood_Hardwood_Decorative",
      "rotation": 1
    },
    {
      "x": 4,
      "y": 5,
      "z": 3,
      "name": "Wood_Softwood_Stairs",
      "rotation": 9
    },
    {
      "x": 4,
      "y": 6,
      "z": 3,
      "name": "Wood_Softwood_Roof",
      "rotation": 1
    },
    {
      "x": 4,
      "y": 0,
      "z": 4,
      "name": "Wood_Hardwood_Planks",
      "rotation": 1
    },
    {
      "x": 4,
      "y": 1,
      "z": 4,
      "name": "Furniture_Village_Shelf_Full",
      "rotation": 2
    },
    {
      "x": 4,
      "y": 2,
      "z": 4,
      "name": "Furniture_Lumberjack_Shelf",
      "rotation": 2
    },
    {
      "x": 4,
      "y": 5,
      "z": 4,
      "name": "Wood_Softwood_Stairs",
      "rotation": 9
    },
    {
      "x": 4,
      "y": 6,
      "z": 4,
      "name": "Wood_Softwood_Roof",
      "rotation": 1
    },
    {
      "x": 4,
      "y": 0,
      "z": 5,
      "name": "Rock_Stone_Cobble",
      "rotation": 1
    },
    {
      "x": 4,
      "y": 1,
      "z": 5,
      "name": "Rock_Stone_Brick",
      "rotation": 1
    },
    {
      "x": 4,
      "y": 2,
      "z": 5,
      "name": "Rock_Stone_Brick",
      "rotation": 1
    },
    {
      "x": 4,
      "y": 3,
      "z": 5,
      "name": "Wood_Hardwood_Ornate",
      "rotation": 1
    },
    {
      "x": 4,
      "y": 4,
      "z": 5,
      "name": "Wood_Beech_Trunk",
      "rotation": 5
    },
    {
      "x": 4,
      "y": 5,
      "z": 5,
      "name": "Wood_Village_Wall_Full",
      "rotation": 1
    },
    {
      "x": 4,
      "y": 6,
      "z": 5,
      "name": "Wood_Softwood_Roof",
      "rotation": 1
    },
    {
      "x": 4,
      "y": 0,
      "z": 6,
      "name": "Rock_Stone_Cobble_Mossy",
      "rotation": 1
    },
    {
      "x": 4,
      "y": 2,
      "z": 6,
      "name": "Plant_Vine_Wall"
    },
    {
      "x": 4,
      "y": 5,
      "z": 6,
      "name": "Wood_Softwood_Stairs",
      "rotation": 9
    },
    {
      "x": 4,
      "y": 6,
      "z": 6,
      "name": "Wood_Softwood_Roof",
      "rotation": 1
    },
    {
      "x": 5,
      "y": 0,
      "z": -6,
      "name": "Rock_Stone_Cobble",
      "rotation": 1
    },
    {
      "x": 5,
      "y": 4,
      "z": -6,
      "name": "Wood_Beech_Trunk",
      "rotation": 6
    },
    {
      "x": 5,
      "y": 5,
      "z": -6,
      "name": "Wood_Softwood_Roof",
      "rotation": 1
    },
    {
      "x": 5,
      "y": 0,
      "z": -5,
      "name": "Rock_Stone_Cobble",
      "rotation": 1
    },
    {
      "x": 5,
      "y": 1,
      "z": -5,
      "name": "Wood_Beech_Trunk",
      "rotation": 1
    },
    {
      "x": 5,
      "y": 2,
      "z": -5,
      "name": "Wood_Beech_Trunk",
      "rotation": 1
    },
    {
      "x": 5,
      "y": 3,
      "z": -5,
      "name": "Wood_Beech_Trunk",
      "rotation": 1
    },
    {
      "x": 5,
      "y": 4,
      "z": -5,
      "name": "Wood_Beech_Trunk",
      "rotation": 1
    },
    {
      "x": 5,
      "y": 5,
      "z": -5,
      "name": "Wood_Softwood_Roof",
      "rotation": 1
    },
    {
      "x": 5,
      "y": 0,
      "z": -4,
      "name": "Rock_Stone_Cobble",
      "rotation": 1
    },
    {
      "x": 5,
      "y": 1,
      "z": -4,
      "name": "Rock_Stone_Brick",
      "rotation": 1
    },
    {
      "x": 5,
      "y": 2,
      "z": -4,
      "name": "*Wood_Village_Wall_Full_State_Definitions_Bottom",
      "rotation": 1
    },
    {
      "x": 5,
      "y": 3,
      "z": -4,
      "name": "*Wood_Village_Wall_Full_State_Definitions_Top",
      "rotation": 1
    },
    {
      "x": 5,
      "y": 4,
      "z": -4,
      "name": "Wood_Beech_Trunk",
      "rotation": 6
    },
    {
      "x": 5,
      "y": 5,
      "z": -4,
      "name": "Wood_Softwood_Roof",
      "rotation": 1
    },
    {
      "x": 5,
      "y": 0,
      "z": -3,
      "name": "Rock_Stone_Cobble",
      "rotation": 1
    },
    {
      "x": 5,
      "y": 1,
      "z": -3,
      "name": "Rock_Stone_Brick",
      "rotation": 1
    },
    {
      "x": 5,
      "y": 2,
      "z": -3,
      "name": "Furniture_Village_Window",
      "rotation": 1
    },
    {
      "x": 5,
      "y": 3,
      "z": -3,
      "name": "Furniture_Village_Window",
      "rotation": 1
    },
    {
      "x": 5,
      "y": 4,
      "z": -3,
      "name": "Wood_Beech_Trunk",
      "rotation": 6
    },
    {
      "x": 5,
      "y": 5,
      "z": -3,
      "name": "Wood_Softwood_Roof",
      "rotation": 1
    },
    {
      "x": 5,
      "y": 0,
      "z": -2,
      "name": "Rock_Stone_Cobble",
      "rotation": 1
    },
    {
      "x": 5,
      "y": 1,
      "z": -2,
      "name": "Rock_Stone_Brick",
      "rotation": 1
    },
    {
      "x": 5,
      "y": 2,
      "z": -2,
      "name": "Furniture_Village_Window",
      "rotation": 1
    },
    {
      "x": 5,
      "y": 3,
      "z": -2,
      "name": "Furniture_Village_Window",
      "rotation": 1
    },
    {
      "x": 5,
      "y": 4,
      "z": -2,
      "name": "Wood_Beech_Trunk",
      "rotation": 6
    },
    {
      "x": 5,
      "y": 5,
      "z": -2,
      "name": "Wood_Softwood_Roof",
      "rotation": 1
    },
    {
      "x": 5,
      "y": 0,
      "z": -1,
      "name": "Rock_Stone_Cobble",
      "rotation": 1
    },
    {
      "x": 5,
      "y": 1,
      "z": -1,
      "name": "Rock_Stone_Brick",
      "rotation": 1
    },
    {
      "x": 5,
      "y": 2,
      "z": -1,
      "name": "*Wood_Village_Wall_Full_State_Definitions_Bottom",
      "rotation": 1
    },
    {
      "x": 5,
      "y": 3,
      "z": -1,
      "name": "*Wood_Village_Wall_Full_State_Definitions_Top",
      "rotation": 1
    },
    {
      "x": 5,
      "y": 4,
      "z": -1,
      "name": "Wood_Beech_Trunk",
      "rotation": 6
    },
    {
      "x": 5,
      "y": 5,
      "z": -1,
      "name": "Wood_Softwood_Roof",
      "rotation": 1
    },
    {
      "x": 5,
      "y": 0,
      "z": 0,
      "name": "Rock_Stone_Cobble",
      "rotation": 1
    },
    {
      "x": 5,
      "y": 1,
      "z": 0,
      "name": "Wood_Beech_Trunk",
      "rotation": 1
    },
    {
      "x": 5,
      "y": 2,
      "z": 0,
      "name": "Wood_Beech_Trunk",
      "rotation": 1
    },
    {
      "x": 5,
      "y": 3,
      "z": 0,
      "name": "Wood_Beech_Trunk",
      "rotation": 1
    },
    {
      "x": 5,
      "y": 4,
      "z": 0,
      "name": "Wood_Beech_Trunk",
      "rotation": 1
    },
    {
      "x": 5,
      "y": 5,
      "z": 0,
      "name": "Wood_Softwood_Roof",
      "rotation": 1
    },
    {
      "x": 5,
      "y": 0,
      "z": 1,
      "name": "Rock_Stone_Cobble",
      "rotation": 1
    },
    {
      "x": 5,
      "y": 1,
      "z": 1,
      "name": "Rock_Stone_Brick",
      "rotation": 1
    },
    {
      "x": 5,
      "y": 2,
      "z": 1,
      "name": "*Wood_Village_Wall_Full_State_Definitions_Bottom",
      "rotation": 1
    },
    {
      "x": 5,
      "y": 3,
      "z": 1,
      "name": "*Wood_Village_Wall_Full_State_Definitions_Top",
      "rotation": 1
    },
    {
      "x": 5,
      "y": 4,
      "z": 1,
      "name": "Wood_Beech_Trunk",
      "rotation": 6
    },
    {
      "x": 5,
      "y": 5,
      "z": 1,
      "name": "Wood_Softwood_Roof",
      "rotation": 1
    },
    {
      "x": 5,
      "y": 0,
      "z": 2,
      "name": "Rock_Stone_Cobble",
      "rotation": 1
    },
    {
      "x": 5,
      "y": 1,
      "z": 2,
      "name": "Rock_Stone_Brick",
      "rotation": 1
    },
    {
      "x": 5,
      "y": 2,
      "z": 2,
      "name": "Furniture_Village_Window",
      "rotation": 1
    },
    {
      "x": 5,
      "y": 3,
      "z": 2,
      "name": "Furniture_Village_Window",
      "rotation": 1
    },
    {
      "x": 5,
      "y": 4,
      "z": 2,
      "name": "Wood_Beech_Trunk",
      "rotation": 6
    },
    {
      "x": 5,
      "y": 5,
      "z": 2,
      "name": "Wood_Softwood_Roof",
      "rotation": 1
    },
    {
      "x": 5,
      "y": 0,
      "z": 3,
      "name": "Rock_Stone_Cobble",
      "rotation": 1
    },
    {
      "x": 5,
      "y": 1,
      "z": 3,
      "name": "Rock_Stone_Brick",
      "rotation": 1
    },
    {
      "x": 5,
      "y": 2,
      "z": 3,
      "name": "Furniture_Village_Window",
      "rotation": 1
    },
    {
      "x": 5,
      "y": 3,
      "z": 3,
      "name": "Furniture_Village_Window",
      "rotation": 1
    },
    {
      "x": 5,
      "y": 4,
      "z": 3,
      "name": "Wood_Beech_Trunk",
      "rotation": 6
    },
    {
      "x": 5,
      "y": 5,
      "z": 3,
      "name": "Wood_Softwood_Roof",
      "rotation": 1
    },
    {
      "x": 5,
      "y": 0,
      "z": 4,
      "name": "Rock_Stone_Cobble",
      "rotation": 1
    },
    {
      "x": 5,
      "y": 1,
      "z": 4,
      "name": "Rock_Stone_Brick",
      "rotation": 1
    },
    {
      "x": 5,
      "y": 2,
      "z": 4,
      "name": "*Wood_Village_Wall_Full_State_Definitions_Bottom",
      "rotation": 1
    },
    {
      "x": 5,
      "y": 3,
      "z": 4,
      "name": "*Wood_Village_Wall_Full_State_Definitions_Top",
      "rotation": 1
    },
    {
      "x": 5,
      "y": 4,
      "z": 4,
      "name": "Wood_Beech_Trunk",
      "rotation": 6
    },
    {
      "x": 5,
      "y": 5,
      "z": 4,
      "name": "Wood_Softwood_Roof",
      "rotation": 1
    },
    {
      "x": 5,
      "y": 0,
      "z": 5,
      "name": "Rock_Stone_Cobble",
      "rotation": 1
    },
    {
      "x": 5,
      "y": 1,
      "z": 5,
      "name": "Wood_Beech_Trunk",
      "rotation": 1
    },
    {
      "x": 5,
      "y": 2,
      "z": 5,
      "name": "Wood_Beech_Trunk",
      "rotation": 1
    },
    {
      "x": 5,
      "y": 3,
      "z": 5,
      "name": "Wood_Beech_Trunk",
      "rotation": 1
    },
    {
      "x": 5,
      "y": 4,
      "z": 5,
      "name": "Wood_Beech_Trunk",
      "rotation": 1
    },
    {
      "x": 5,
      "y": 5,
      "z": 5,
      "name": "Wood_Softwood_Roof",
      "rotation": 1
    },
    {
      "x": 5,
      "y": 0,
      "z": 6,
      "name": "Rock_Stone_Cobble",
      "rotation": 1
    },
    {
      "x": 5,
      "y": 4,
      "z": 6,
      "name": "Wood_Beech_Trunk",
      "rotation": 6
    },
    {
      "x": 5,
      "y": 5,
      "z": 6,
      "name": "Wood_Softwood_Roof",
      "rotation": 1
    },
    {
      "x": 6,
      "y": 0,
      "z": -6,
      "name": "Rock_Stone_Cobble"
    },
    {
      "x": 6,
      "y": 4,
      "z": -6,
      "name": "Wood_Softwood_Roof_Hollow",
      "rotation": 1
    },
    {
      "x": 6,
      "y": 0,
      "z": -5,
      "name": "Rock_Stone_Cobble",
      "rotation": 1
    },
    {
      "x": 6,
      "y": 4,
      "z": -5,
      "name": "Wood_Softwood_Roof_Hollow",
      "rotation": 1
    },
    {
      "x": 6,
      "y": 0,
      "z": -4,
      "name": "Rock_Stone_Cobble_Mossy",
      "rotation": 1
    },
    {
      "x": 6,
      "y": 4,
      "z": -4,
      "name": "Wood_Softwood_Roof_Hollow",
      "rotation": 1
    },
    {
      "x": 6,
      "y": 0,
      "z": -3,
      "name": "Rock_Stone_Cobble_Mossy",
      "rotation": 1
    },
    {
      "x": 6,
      "y": 4,
      "z": -3,
      "name": "Wood_Softwood_Roof_Hollow",
      "rotation": 1
    },
    {
      "x": 6,
      "y": 0,
      "z": -2,
      "name": "Rock_Stone_Cobble",
      "rotation": 1
    },
    {
      "x": 6,
      "y": 4,
      "z": -2,
      "name": "Wood_Softwood_Roof_Hollow",
      "rotation": 1
    },
    {
      "x": 6,
      "y": 0,
      "z": -1,
      "name": "Rock_Stone_Cobble",
      "rotation": 1
    },
    {
      "x": 6,
      "y": 2,
      "z": -1,
      "name": "Plant_Vine_Wall",
      "rotation": 1
    },
    {
      "x": 6,
      "y": 4,
      "z": -1,
      "name": "Wood_Softwood_Roof_Hollow",
      "rotation": 1
    },
    {
      "x": 6,
      "y": 0,
      "z": 0,
      "name": "Rock_Stone_Cobble",
      "rotation": 1
    },
    {
      "x": 6,
      "y": 4,
      "z": 0,
      "name": "Wood_Softwood_Roof_Hollow",
      "rotation": 1
    },
    {
      "x": 6,
      "y": 0,
      "z": 1,
      "name": "Rock_Stone_Cobble_Mossy",
      "rotation": 1
    },
    {
      "x": 6,
      "y": 4,
      "z": 1,
      "name": "Wood_Softwood_Roof_Hollow",
      "rotation": 1
    },
    {
      "x": 6,
      "y": 0,
      "z": 2,
      "name": "Rock_Stone_Cobble",
      "rotation": 1
    },
    {
      "x": 6,
      "y": 4,
      "z": 2,
      "name": "Wood_Softwood_Roof_Hollow",
      "rotation": 1
    },
    {
      "x": 6,
      "y": 0,
      "z": 3,
      "name": "Rock_Stone_Cobble",
      "rotation": 1
    },
    {
      "x": 6,
      "y": 4,
      "z": 3,
      "name": "Wood_Softwood_Roof_Hollow",
      "rotation": 1
    },
    {
      "x": 6,
      "y": 0,
      "z": 4,
      "name": "Rock_Stone_Cobble",
      "rotation": 1
    },
    {
      "x": 6,
      "y": 4,
      "z": 4,
      "name": "Wood_Softwood_Roof_Hollow",
      "rotation": 1
    },
    {
      "x": 6,
      "y": 0,
      "z": 5,
      "name": "Rock_Stone_Cobble",
      "rotation": 1
    },
    {
      "x": 6,
      "y": 4,
      "z": 5,
      "name": "Wood_Softwood_Roof_Hollow",
      "rotation": 1
    },
    {
      "x": 6,
      "y": 0,
      "z": 6,
      "name": "Rock_Stone_Cobble",
      "rotation": 1
    },
    {
      "x": 6,
      "y": 4,
      "z": 6,
      "name": "Wood_Softwood_Roof_Hollow",
      "rotation": 1
    }
  ],
  "fluids": [
    {
      "x": -5,
      "y": 0,
      "z": -6,
      "name": "Empty",
      "level": 0
    },
    {
      "x": -5,
      "y": 4,
      "z": -6,
      "name": "Empty",
      "level": 0
    },
    {
      "x": -5,
      "y": 0,
      "z": -5,
      "name": "Empty",
      "level": 0
    },
    {
      "x": -5,
      "y": 2,
      "z": -5,
      "name": "Empty",
      "level": 0
    },
    {
      "x": -5,
      "y": 3,
      "z": -5,
      "name": "Empty",
      "level": 0
    },
    {
      "x": -5,
      "y": 4,
      "z": -5,
      "name": "Empty",
      "level": 0
    },
    {
      "x": -5,
      "y": 0,
      "z": -4,
      "name": "Empty",
      "level": 0
    },
    {
      "x": -5,
      "y": 4,
      "z": -4,
      "name": "Empty",
      "level": 0
    },
    {
      "x": -5,
      "y": 0,
      "z": -3,
      "name": "Empty",
      "level": 0
    },
    {
      "x": -5,
      "y": 4,
      "z": -3,
      "name": "Empty",
      "level": 0
    },
    {
      "x": -5,
      "y": 0,
      "z": -2,
      "name": "Empty",
      "level": 0
    },
    {
      "x": -5,
      "y": 4,
      "z": -2,
      "name": "Empty",
      "level": 0
    },
    {
      "x": -5,
      "y": 0,
      "z": -1,
      "name": "Empty",
      "level": 0
    },
    {
      "x": -5,
      "y": 4,
      "z": -1,
      "name": "Empty",
      "level": 0
    },
    {
      "x": -5,
      "y": 0,
      "z": 0,
      "name": "Empty",
      "level": 0
    },
    {
      "x": -5,
      "y": 4,
      "z": 0,
      "name": "Empty",
      "level": 0
    },
    {
      "x": -5,
      "y": 0,
      "z": 1,
      "name": "Empty",
      "level": 0
    },
    {
      "x": -5,
      "y": 3,
      "z": 1,
      "name": "Empty",
      "level": 0
    },
    {
      "x": -5,
      "y": 4,
      "z": 1,
      "name": "Empty",
      "level": 0
    },
    {
      "x": -5,
      "y": 0,
      "z": 2,
      "name": "Empty",
      "level": 0
    },
    {
      "x": -5,
      "y": 4,
      "z": 2,
      "name": "Empty",
      "level": 0
    },
    {
      "x": -5,
      "y": 0,
      "z": 3,
      "name": "Empty",
      "level": 0
    },
    {
      "x": -5,
      "y": 4,
      "z": 3,
      "name": "Empty",
      "level": 0
    },
    {
      "x": -5,
      "y": 0,
      "z": 4,
      "name": "Empty",
      "level": 0
    },
    {
      "x": -5,
      "y": 4,
      "z": 4,
      "name": "Empty",
      "level": 0
    },
    {
      "x": -5,
      "y": 0,
      "z": 5,
      "name": "Empty",
      "level": 0
    },
    {
      "x": -5,
      "y": 1,
      "z": 5,
      "name": "Empty",
      "level": 0
    },
    {
      "x": -5,
      "y": 3,
      "z": 5,
      "name": "Empty",
      "level": 0
    },
    {
      "x": -5,
      "y": 4,
      "z": 5,
      "name": "Empty",
      "level": 0
    },
    {
      "x": -5,
      "y": 0,
      "z": 6,
      "name": "Empty",
      "level": 0
    },
    {
      "x": -5,
      "y": 1,
      "z": 6,
      "name": "Empty",
      "level": 0
    },
    {
      "x": -5,
      "y": 2,
      "z": 6,
      "name": "Empty",
      "level": 0
    },
    {
      "x": -5,
      "y": 4,
      "z": 6,
      "name": "Empty",
      "level": 0
    },
    {
      "x": -4,
      "y": 0,
      "z": -6,
      "name": "Empty",
      "level": 0
    },
    {
      "x": -4,
      "y": 4,
      "z": -6,
      "name": "Empty",
      "level": 0
    },
    {
      "x": -4,
      "y": 5,
      "z": -6,
      "name": "Empty",
      "level": 0
    },
    {
      "x": -4,
      "y": 0,
      "z": -5,
      "name": "Empty",
      "level": 0
    },
    {
      "x": -4,
      "y": 1,
      "z": -5,
      "name": "Empty",
      "level": 0
    },
    {
      "x": -4,
      "y": 2,
      "z": -5,
      "name": "Empty",
      "level": 0
    },
    {
      "x": -4,
      "y": 3,
      "z": -5,
      "name": "Empty",
      "level": 0
    },
    {
      "x": -4,
      "y": 4,
      "z": -5,
      "name": "Empty",
      "level": 0
    },
    {
      "x": -4,
      "y": 5,
      "z": -5,
      "name": "Empty",
      "level": 0
    },
    {
      "x": -4,
      "y": 0,
      "z": -4,
      "name": "Empty",
      "level": 0
    },
    {
      "x": -4,
      "y": 1,
      "z": -4,
      "name": "Empty",
      "level": 0
    },
    {
      "x": -4,
      "y": 2,
      "z": -4,
      "name": "Empty",
      "level": 0
    },
    {
      "x": -4,
      "y": 3,
      "z": -4,
      "name": "Empty",
      "level": 0
    },
    {
      "x": -4,
      "y": 4,
      "z": -4,
      "name": "Empty",
      "level": 0
    },
    {
      "x": -4,
      "y": 5,
      "z": -4,
      "name": "Empty",
      "level": 0
    },
    {
      "x": -4,
      "y": 0,
      "z": -3,
      "name": "Empty",
      "level": 0
    },
    {
      "x": -4,
      "y": 1,
      "z": -3,
      "name": "Empty",
      "level": 0
    },
    {
      "x": -4,
      "y": 2,
      "z": -3,
      "name": "Empty",
      "level": 0
    },
    {
      "x": -4,
      "y": 3,
      "z": -3,
      "name": "Empty",
      "level": 0
    },
    {
      "x": -4,
      "y": 4,
      "z": -3,
      "name": "Empty",
      "level": 0
    },
    {
      "x": -4,
      "y": 5,
      "z": -3,
      "name": "Empty",
      "level": 0
    },
    {
      "x": -4,
      "y": 0,
      "z": -2,
      "name": "Empty",
      "level": 0
    },
    {
      "x": -4,
      "y": 1,
      "z": -2,
      "name": "Empty",
      "level": 0
    },
    {
      "x": -4,
      "y": 2,
      "z": -2,
      "name": "Empty",
      "level": 0
    },
    {
      "x": -4,
      "y": 3,
      "z": -2,
      "name": "Empty",
      "level": 0
    },
    {
      "x": -4,
      "y": 4,
      "z": -2,
      "name": "Empty",
      "level": 0
    },
    {
      "x": -4,
      "y": 5,
      "z": -2,
      "name": "Empty",
      "level": 0
    },
    {
      "x": -4,
      "y": 0,
      "z": -1,
      "name": "Empty",
      "level": 0
    },
    {
      "x": -4,
      "y": 1,
      "z": -1,
      "name": "Empty",
      "level": 0
    },
    {
      "x": -4,
      "y": 2,
      "z": -1,
      "name": "Empty",
      "level": 0
    },
    {
      "x": -4,
      "y": 3,
      "z": -1,
      "name": "Empty",
      "level": 0
    },
    {
      "x": -4,
      "y": 4,
      "z": -1,
      "name": "Empty",
      "level": 0
    },
    {
      "x": -4,
      "y": 5,
      "z": -1,
      "name": "Empty",
      "level": 0
    },
    {
      "x": -4,
      "y": 0,
      "z": 0,
      "name": "Empty",
      "level": 0
    },
    {
      "x": -4,
      "y": 1,
      "z": 0,
      "name": "Empty",
      "level": 0
    },
    {
      "x": -4,
      "y": 2,
      "z": 0,
      "name": "Empty",
      "level": 0
    },
    {
      "x": -4,
      "y": 3,
      "z": 0,
      "name": "Empty",
      "level": 0
    },
    {
      "x": -4,
      "y": 4,
      "z": 0,
      "name": "Empty",
      "level": 0
    },
    {
      "x": -4,
      "y": 5,
      "z": 0,
      "name": "Empty",
      "level": 0
    },
    {
      "x": -4,
      "y": 0,
      "z": 1,
      "name": "Empty",
      "level": 0
    },
    {
      "x": -4,
      "y": 1,
      "z": 1,
      "name": "Empty",
      "level": 0
    },
    {
      "x": -4,
      "y": 2,
      "z": 1,
      "name": "Empty",
      "level": 0
    },
    {
      "x": -4,
      "y": 3,
      "z": 1,
      "name": "Empty",
      "level": 0
    },
    {
      "x": -4,
      "y": 4,
      "z": 1,
      "name": "Empty",
      "level": 0
    },
    {
      "x": -4,
      "y": 5,
      "z": 1,
      "name": "Empty",
      "level": 0
    },
    {
      "x": -4,
      "y": 0,
      "z": 2,
      "name": "Empty",
      "level": 0
    },
    {
      "x": -4,
      "y": 1,
      "z": 2,
      "name": "Empty",
      "level": 0
    },
    {
      "x": -4,
      "y": 2,
      "z": 2,
      "name": "Empty",
      "level": 0
    },
    {
      "x": -4,
      "y": 3,
      "z": 2,
      "name": "Empty",
      "level": 0
    },
    {
      "x": -4,
      "y": 4,
      "z": 2,
      "name": "Empty",
      "level": 0
    },
    {
      "x": -4,
      "y": 5,
      "z": 2,
      "name": "Empty",
      "level": 0
    },
    {
      "x": -4,
      "y": 0,
      "z": 3,
      "name": "Empty",
      "level": 0
    },
    {
      "x": -4,
      "y": 1,
      "z": 3,
      "name": "Empty",
      "level": 0
    },
    {
      "x": -4,
      "y": 2,
      "z": 3,
      "name": "Empty",
      "level": 0
    },
    {
      "x": -4,
      "y": 3,
      "z": 3,
      "name": "Empty",
      "level": 0
    },
    {
      "x": -4,
      "y": 4,
      "z": 3,
      "name": "Empty",
      "level": 0
    },
    {
      "x": -4,
      "y": 5,
      "z": 3,
      "name": "Empty",
      "level": 0
    },
    {
      "x": -4,
      "y": 0,
      "z": 4,
      "name": "Empty",
      "level": 0
    },
    {
      "x": -4,
      "y": 1,
      "z": 4,
      "name": "Empty",
      "level": 0
    },
    {
      "x": -4,
      "y": 2,
      "z": 4,
      "name": "Empty",
      "level": 0
    },
    {
      "x": -4,
      "y": 3,
      "z": 4,
      "name": "Empty",
      "level": 0
    },
    {
      "x": -4,
      "y": 4,
      "z": 4,
      "name": "Empty",
      "level": 0
    },
    {
      "x": -4,
      "y": 5,
      "z": 4,
      "name": "Empty",
      "level": 0
    },
    {
      "x": -4,
      "y": 0,
      "z": 5,
      "name": "Empty",
      "level": 0
    },
    {
      "x": -4,
      "y": 1,
      "z": 5,
      "name": "Empty",
      "level": 0
    },
    {
      "x": -4,
      "y": 2,
      "z": 5,
      "name": "Empty",
      "level": 0
    },
    {
      "x": -4,
      "y": 3,
      "z": 5,
      "name": "Empty",
      "level": 0
    },
    {
      "x": -4,
      "y": 4,
      "z": 5,
      "name": "Empty",
      "level": 0
    },
    {
      "x": -4,
      "y": 5,
      "z": 5,
      "name": "Empty",
      "level": 0
    },
    {
      "x": -4,
      "y": 0,
      "z": 6,
      "name": "Empty",
      "level": 0
    },
    {
      "x": -4,
      "y": 1,
      "z": 6,
      "name": "Empty",
      "level": 0
    },
    {
      "x": -4,
      "y": 4,
      "z": 6,
      "name": "Empty",
      "level": 0
    },
    {
      "x": -4,
      "y": 5,
      "z": 6,
      "name": "Empty",
      "level": 0
    },
    {
      "x": -3,
      "y": 0,
      "z": -6,
      "name": "Empty",
      "level": 0
    },
    {
      "x": -3,
      "y": 4,
      "z": -6,
      "name": "Empty",
      "level": 0
    },
    {
      "x": -3,
      "y": 5,
      "z": -6,
      "name": "Empty",
      "level": 0
    },
    {
      "x": -3,
      "y": 6,
      "z": -6,
      "name": "Empty",
      "level": 0
    },
    {
      "x": -3,
      "y": 0,
      "z": -5,
      "name": "Empty",
      "level": 0
    },
    {
      "x": -3,
      "y": 1,
      "z": -5,
      "name": "Empty",
      "level": 0
    },
    {
      "x": -3,
      "y": 2,
      "z": -5,
      "name": "Empty",
      "level": 0
    },
    {
      "x": -3,
      "y": 3,
      "z": -5,
      "name": "Empty",
      "level": 0
    },
    {
      "x": -3,
      "y": 4,
      "z": -5,
      "name": "Empty",
      "level": 0
    },
    {
      "x": -3,
      "y": 5,
      "z": -5,
      "name": "Empty",
      "level": 0
    },
    {
      "x": -3,
      "y": 6,
      "z": -5,
      "name": "Empty",
      "level": 0
    },
    {
      "x": -3,
      "y": 0,
      "z": -4,
      "name": "Empty",
      "level": 0
    },
    {
      "x": -3,
      "y": 5,
      "z": -4,
      "name": "Empty",
      "level": 0
    },
    {
      "x": -3,
      "y": 6,
      "z": -4,
      "name": "Empty",
      "level": 0
    },
    {
      "x": -3,
      "y": 0,
      "z": -3,
      "name": "Empty",
      "level": 0
    },
    {
      "x": -3,
      "y": 1,
      "z": -3,
      "name": "Empty",
      "level": 0
    },
    {
      "x": -3,
      "y": 5,
      "z": -3,
      "name": "Empty",
      "level": 0
    },
    {
      "x": -3,
      "y": 6,
      "z": -3,
      "name": "Empty",
      "level": 0
    },
    {
      "x": -3,
      "y": 0,
      "z": -2,
      "name": "Empty",
      "level": 0
    },
    {
      "x": -3,
      "y": 1,
      "z": -2,
      "name": "Empty",
      "level": 0
    },
    {
      "x": -3,
      "y": 5,
      "z": -2,
      "name": "Empty",
      "level": 0
    },
    {
      "x": -3,
      "y": 6,
      "z": -2,
      "name": "Empty",
      "level": 0
    },
    {
      "x": -3,
      "y": 0,
      "z": -1,
      "name": "Empty",
      "level": 0
    },
    {
      "x": -3,
      "y": 1,
      "z": -1,
      "name": "Empty",
      "level": 0
    },
    {
      "x": -3,
      "y": 2,
      "z": -1,
      "name": "Empty",
      "level": 0
    },
    {
      "x": -3,
      "y": 5,
      "z": -1,
      "name": "Empty",
      "level": 0
    },
    {
      "x": -3,
      "y": 6,
      "z": -1,
      "name": "Empty",
      "level": 0
    },
    {
      "x": -3,
      "y": 0,
      "z": 0,
      "name": "Empty",
      "level": 0
    },
    {
      "x": -3,
      "y": 1,
      "z": 0,
      "name": "Empty",
      "level": 0
    },
    {
      "x": -3,
      "y": 5,
      "z": 0,
      "name": "Empty",
      "level": 0
    },
    {
      "x": -3,
      "y": 6,
      "z": 0,
      "name": "Empty",
      "level": 0
    },
    {
      "x": -3,
      "y": 0,
      "z": 1,
      "name": "Empty",
      "level": 0
    },
    {
      "x": -3,
      "y": 5,
      "z": 1,
      "name": "Empty",
      "level": 0
    },
    {
      "x": -3,
      "y": 6,
      "z": 1,
      "name": "Empty",
      "level": 0
    },
    {
      "x": -3,
      "y": 0,
      "z": 2,
      "name": "Empty",
      "level": 0
    },
    {
      "x": -3,
      "y": 5,
      "z": 2,
      "name": "Empty",
      "level": 0
    },
    {
      "x": -3,
      "y": 6,
      "z": 2,
      "name": "Empty",
      "level": 0
    },
    {
      "x": -3,
      "y": 0,
      "z": 3,
      "name": "Empty",
      "level": 0
    },
    {
      "x": -3,
      "y": 5,
      "z": 3,
      "name": "Empty",
      "level": 0
    },
    {
      "x": -3,
      "y": 6,
      "z": 3,
      "name": "Empty",
      "level": 0
    },
    {
      "x": -3,
      "y": 0,
      "z": 4,
      "name": "Empty",
      "level": 0
    },
    {
      "x": -3,
      "y": 1,
      "z": 4,
      "name": "Empty",
      "level": 0
    },
    {
      "x": -3,
      "y": 2,
      "z": 4,
      "name": "Empty",
      "level": 0
    },
    {
      "x": -3,
      "y": 5,
      "z": 4,
      "name": "Empty",
      "level": 0
    },
    {
      "x": -3,
      "y": 6,
      "z": 4,
      "name": "Empty",
      "level": 0
    },
    {
      "x": -3,
      "y": 0,
      "z": 5,
      "name": "Empty",
      "level": 0
    },
    {
      "x": -3,
      "y": 1,
      "z": 5,
      "name": "Empty",
      "level": 0
    },
    {
      "x": -3,
      "y": 2,
      "z": 5,
      "name": "Empty",
      "level": 0
    },
    {
      "x": -3,
      "y": 3,
      "z": 5,
      "name": "Empty",
      "level": 0
    },
    {
      "x": -3,
      "y": 4,
      "z": 5,
      "name": "Empty",
      "level": 0
    },
    {
      "x": -3,
      "y": 5,
      "z": 5,
      "name": "Empty",
      "level": 0
    },
    {
      "x": -3,
      "y": 6,
      "z": 5,
      "name": "Empty",
      "level": 0
    },
    {
      "x": -3,
      "y": 0,
      "z": 6,
      "name": "Empty",
      "level": 0
    },
    {
      "x": -3,
      "y": 4,
      "z": 6,
      "name": "Empty",
      "level": 0
    },
    {
      "x": -3,
      "y": 5,
      "z": 6,
      "name": "Empty",
      "level": 0
    },
    {
      "x": -3,
      "y": 6,
      "z": 6,
      "name": "Empty",
      "level": 0
    },
    {
      "x": -2,
      "y": 0,
      "z": -6,
      "name": "Empty",
      "level": 0
    },
    {
      "x": -2,
      "y": 6,
      "z": -6,
      "name": "Empty",
      "level": 0
    },
    {
      "x": -2,
      "y": 7,
      "z": -6,
      "name": "Empty",
      "level": 0
    },
    {
      "x": -2,
      "y": 0,
      "z": -5,
      "name": "Empty",
      "level": 0
    },
    {
      "x": -2,
      "y": 1,
      "z": -5,
      "name": "Empty",
      "level": 0
    },
    {
      "x": -2,
      "y": 2,
      "z": -5,
      "name": "Empty",
      "level": 0
    },
    {
      "x": -2,
      "y": 3,
      "z": -5,
      "name": "Empty",
      "level": 0
    },
    {
      "x": -2,
      "y": 4,
      "z": -5,
      "name": "Empty",
      "level": 0
    },
    {
      "x": -2,
      "y": 5,
      "z": -5,
      "name": "Empty",
      "level": 0
    },
    {
      "x": -2,
      "y": 6,
      "z": -5,
      "name": "Empty",
      "level": 0
    },
    {
      "x": -2,
      "y": 7,
      "z": -5,
      "name": "Empty",
      "level": 0
    },
    {
      "x": -2,
      "y": 0,
      "z": -4,
      "name": "Empty",
      "level": 0
    },
    {
      "x": -2,
      "y": 6,
      "z": -4,
      "name": "Empty",
      "level": 0
    },
    {
      "x": -2,
      "y": 7,
      "z": -4,
      "name": "Empty",
      "level": 0
    },
    {
      "x": -2,
      "y": 0,
      "z": -3,
      "name": "Empty",
      "level": 0
    },
    {
      "x": -2,
      "y": 1,
      "z": -3,
      "name": "Empty",
      "level": 0
    },
    {
      "x": -2,
      "y": 6,
      "z": -3,
      "name": "Empty",
      "level": 0
    },
    {
      "x": -2,
      "y": 7,
      "z": -3,
      "name": "Empty",
      "level": 0
    },
    {
      "x": -2,
      "y": 0,
      "z": -2,
      "name": "Empty",
      "level": 0
    },
    {
      "x": -2,
      "y": 1,
      "z": -2,
      "name": "Empty",
      "level": 0
    },
    {
      "x": -2,
      "y": 2,
      "z": -2,
      "name": "Empty",
      "level": 0
    },
    {
      "x": -2,
      "y": 6,
      "z": -2,
      "name": "Empty",
      "level": 0
    },
    {
      "x": -2,
      "y": 7,
      "z": -2,
      "name": "Empty",
      "level": 0
    },
    {
      "x": -2,
      "y": 0,
      "z": -1,
      "name": "Empty",
      "level": 0
    },
    {
      "x": -2,
      "y": 1,
      "z": -1,
      "name": "Empty",
      "level": 0
    },
    {
      "x": -2,
      "y": 6,
      "z": -1,
      "name": "Empty",
      "level": 0
    },
    {
      "x": -2,
      "y": 7,
      "z": -1,
      "name": "Empty",
      "level": 0
    },
    {
      "x": -2,
      "y": 0,
      "z": 0,
      "name": "Empty",
      "level": 0
    },
    {
      "x": -2,
      "y": 1,
      "z": 0,
      "name": "Empty",
      "level": 0
    },
    {
      "x": -2,
      "y": 6,
      "z": 0,
      "name": "Empty",
      "level": 0
    },
    {
      "x": -2,
      "y": 7,
      "z": 0,
      "name": "Empty",
      "level": 0
    },
    {
      "x": -2,
      "y": 0,
      "z": 1,
      "name": "Empty",
      "level": 0
    },
    {
      "x": -2,
      "y": 6,
      "z": 1,
      "name": "Empty",
      "level": 0
    },
    {
      "x": -2,
      "y": 7,
      "z": 1,
      "name": "Empty",
      "level": 0
    },
    {
      "x": -2,
      "y": 0,
      "z": 2,
      "name": "Empty",
      "level": 0
    },
    {
      "x": -2,
      "y": 6,
      "z": 2,
      "name": "Empty",
      "level": 0
    },
    {
      "x": -2,
      "y": 7,
      "z": 2,
      "name": "Empty",
      "level": 0
    },
    {
      "x": -2,
      "y": 0,
      "z": 3,
      "name": "Empty",
      "level": 0
    },
    {
      "x": -2,
      "y": 1,
      "z": 3,
      "name": "Empty",
      "level": 0
    },
    {
      "x": -2,
      "y": 6,
      "z": 3,
      "name": "Empty",
      "level": 0
    },
    {
      "x": -2,
      "y": 7,
      "z": 3,
      "name": "Empty",
      "level": 0
    },
    {
      "x": -2,
      "y": 0,
      "z": 4,
      "name": "Empty",
      "level": 0
    },
    {
      "x": -2,
      "y": 1,
      "z": 4,
      "name": "Empty",
      "level": 0
    },
    {
      "x": -2,
      "y": 2,
      "z": 4,
      "name": "Empty",
      "level": 0
    },
    {
      "x": -2,
      "y": 6,
      "z": 4,
      "name": "Empty",
      "level": 0
    },
    {
      "x": -2,
      "y": 7,
      "z": 4,
      "name": "Empty",
      "level": 0
    },
    {
      "x": -2,
      "y": 0,
      "z": 5,
      "name": "Empty",
      "level": 0
    },
    {
      "x": -2,
      "y": 1,
      "z": 5,
      "name": "Empty",
      "level": 0
    },
    {
      "x": -2,
      "y": 2,
      "z": 5,
      "name": "Empty",
      "level": 0
    },
    {
      "x": -2,
      "y": 3,
      "z": 5,
      "name": "Empty",
      "level": 0
    },
    {
      "x": -2,
      "y": 4,
      "z": 5,
      "name": "Empty",
      "level": 0
    },
    {
      "x": -2,
      "y": 5,
      "z": 5,
      "name": "Empty",
      "level": 0
    },
    {
      "x": -2,
      "y": 6,
      "z": 5,
      "name": "Empty",
      "level": 0
    },
    {
      "x": -2,
      "y": 7,
      "z": 5,
      "name": "Empty",
      "level": 0
    },
    {
      "x": -2,
      "y": 0,
